2020-03-20 14:01:10,130:Survey Assist:File doesn't appear to be a valid GSI file.  Missing Key ID: +00000000000STN01
Traceback (most recent call last):
  File "C:\Users\rjwal_000\PycharmProjects\Survey Assist\GSI.py", line 105, in format_gsi
    field_name = GSI.GSI_WORD_ID_DICT[two_digit_id]
KeyError: '*1'
2020-03-20 14:02:32,338:Survey Assist:File doesn't appear to be a valid GSI file.  Missing Key ID: +00000000000STN01
Traceback (most recent call last):
  File "C:\Users\rjwal_000\PycharmProjects\Survey Assist\GSI.py", line 105, in format_gsi
    field_name = GSI.GSI_WORD_ID_DICT[two_digit_id]
KeyError: '*1'
2020-03-20 14:02:58,052:Survey Assist:Database in use.  Unable to delete until it is closed
Traceback (most recent call last):
  File "C:\Users\rjwal_000\PycharmProjects\Survey Assist\GSIDatabase.py", line 24, in create_db
    os.remove(GSIDatabase.DATABASE_PATH)
PermissionError: [WinError 32] The process cannot access the file because it is being used by another process: 'GSI Files\\GSI_database.db'
2020-03-20 14:04:50,368:Survey Assist:File doesn't appear to be a valid GSI file.  Missing Key ID: +00000000000STN01
Traceback (most recent call last):
  File "C:\Users\rjwal_000\PycharmProjects\Survey Assist\GSI.py", line 105, in format_gsi
    field_name = GSI.GSI_WORD_ID_DICT[two_digit_id]
KeyError: '*1'
