2020-03-20 14:01:10,130:Survey Assist:File doesn't appear to be a valid GSI file.  Missing Key ID: +00000000000STN01
Traceback (most recent call last):
  File "C:\Users\rjwal_000\PycharmProjects\Survey Assist\GSI.py", line 105, in format_gsi
    field_name = GSI.GSI_WORD_ID_DICT[two_digit_id]
KeyError: '*1'
2020-03-20 14:02:32,338:Survey Assist:File doesn't appear to be a valid GSI file.  Missing Key ID: +00000000000STN01
Traceback (most recent call last):
  File "C:\Users\rjwal_000\PycharmProjects\Survey Assist\GSI.py", line 105, in format_gsi
    field_name = GSI.GSI_WORD_ID_DICT[two_digit_id]
KeyError: '*1'
2020-03-20 14:02:58,052:Survey Assist:Database in use.  Unable to delete until it is closed
Traceback (most recent call last):
  File "C:\Users\rjwal_000\PycharmProjects\Survey Assist\GSIDatabase.py", line 24, in create_db
    os.remove(GSIDatabase.DATABASE_PATH)
PermissionError: [WinError 32] The process cannot access the file because it is being used by another process: 'GSI Files\\GSI_database.db'
2020-03-20 14:04:50,368:Survey Assist:File doesn't appear to be a valid GSI file.  Missing Key ID: +00000000000STN01
Traceback (most recent call last):
  File "C:\Users\rjwal_000\PycharmProjects\Survey Assist\GSI.py", line 105, in format_gsi
    field_name = GSI.GSI_WORD_ID_DICT[two_digit_id]
KeyError: '*1'
2020-03-20 20:16:41,672:Survey Assist:File doesn't appear to be a valid GSI file.  Missing Key ID: +00000000000STN01
Traceback (most recent call last):
  File "C:\Users\rjwal_000\PycharmProjects\Survey Assist\GSI.py", line 105, in format_gsi
    field_name = GSI.GSI_WORD_ID_DICT[two_digit_id]
KeyError: '*1'
2020-03-20 20:16:46,457:Survey Assist:Database in use.  Unable to delete until it is closed
Traceback (most recent call last):
  File "C:\Users\rjwal_000\PycharmProjects\Survey Assist\GSIDatabase.py", line 24, in create_db
    os.remove(GSIDatabase.DATABASE_PATH)
PermissionError: [WinError 32] The process cannot access the file because it is being used by another process: 'GSI Files\\GSI_database.db'
2020-03-20 20:19:38,515:Survey Assist:Database in use.  Unable to delete until it is closed
Traceback (most recent call last):
  File "C:\Users\rjwal_000\PycharmProjects\Survey Assist\GSIDatabase.py", line 24, in create_db
    os.remove(GSIDatabase.DATABASE_PATH)
PermissionError: [WinError 32] The process cannot access the file because it is being used by another process: 'GSI Files\\GSI_database.db'
2020-03-21 15:26:54,959:Survey Assist:File doesn't appear to be a valid GSI file.  Missing Key ID: +00000000000STN03
Traceback (most recent call last):
  File "C:\Users\rjwal_000\PycharmProjects\Survey Assist\GSI.py", line 105, in format_gsi
    field_name = GSI.GSI_WORD_ID_DICT[two_digit_id]
KeyError: '*1'
2020-03-21 15:27:36,207:Survey Assist:File doesn't appear to be a valid GSI file.  Missing Key ID: +00000000000STN03
Traceback (most recent call last):
  File "C:\Users\rjwal_000\PycharmProjects\Survey Assist\GSI.py", line 105, in format_gsi
    field_name = GSI.GSI_WORD_ID_DICT[two_digit_id]
KeyError: '*1'
2020-03-21 15:28:05,637:Survey Assist:File doesn't appear to be a valid GSI file.  Missing Key ID: +00000000000STN03
Traceback (most recent call last):
  File "C:\Users\rjwal_000\PycharmProjects\Survey Assist\GSI.py", line 105, in format_gsi
    field_name = GSI.GSI_WORD_ID_DICT[two_digit_id]
KeyError: '*1'
2020-03-21 15:29:24,045:Survey Assist:File doesn't appear to be a valid GSI file.  Missing Key ID: +00000000000STN03
Traceback (most recent call last):
  File "C:\Users\rjwal_000\PycharmProjects\Survey Assist\GSI.py", line 105, in format_gsi
    field_name = GSI.GSI_WORD_ID_DICT[two_digit_id]
KeyError: '*1'
2020-03-21 15:37:32,597:Survey Assist:File doesn't appear to be a valid GSI file.  Missing Key ID: +00000000000STN03
Traceback (most recent call last):
  File "C:/Users/rjwal_000/PycharmProjects/Survey Assist/main.py", line 1301, in select_and_combine_gsi_files
    sorted_filecontents = self.sort_alphabetically()
  File "C:/Users/rjwal_000/PycharmProjects/Survey Assist/main.py", line 1346, in sort_alphabetically
    txt_lines_temp_combined_gsi = f_temp_combined_gsi.readline()
io.UnsupportedOperation: not readable

During handling of the above exception, another exception occurred:

Traceback (most recent call last):
  File "C:\Users\rjwal_000\PycharmProjects\Survey Assist\GSI.py", line 105, in format_gsi
    field_name = GSI.GSI_WORD_ID_DICT[two_digit_id]
KeyError: '*1'
2020-03-21 15:39:30,208:Survey Assist:File doesn't appear to be a valid GSI file.  Missing Key ID: +00000000000STN03
Traceback (most recent call last):
  File "C:\Users\rjwal_000\PycharmProjects\Survey Assist\GSI.py", line 105, in format_gsi
    field_name = GSI.GSI_WORD_ID_DICT[two_digit_id]
KeyError: '*1'
2020-03-21 15:39:39,399:Survey Assist:File doesn't appear to be a valid GSI file.  Missing Key ID: +00000000000STN03
Traceback (most recent call last):
  File "C:\Users\rjwal_000\PycharmProjects\Survey Assist\GSI.py", line 105, in format_gsi
    field_name = GSI.GSI_WORD_ID_DICT[two_digit_id]
KeyError: '*1'
2020-03-21 15:43:12,199:Survey Assist:File doesn't appear to be a valid GSI file.  Missing Key ID: +00000000000STN03
Traceback (most recent call last):
  File "C:\Users\rjwal_000\PycharmProjects\Survey Assist\GSI.py", line 105, in format_gsi
    field_name = GSI.GSI_WORD_ID_DICT[two_digit_id]
KeyError: '*1'
2020-03-21 15:43:40,576:Survey Assist:File doesn't appear to be a valid GSI file.  Missing Key ID: +00000000000STN03
Traceback (most recent call last):
  File "C:\Users\rjwal_000\PycharmProjects\Survey Assist\GSI.py", line 105, in format_gsi
    field_name = GSI.GSI_WORD_ID_DICT[two_digit_id]
KeyError: '*1'
2020-03-21 15:57:47,318:Survey Assist:File doesn't appear to be a valid GSI file.  Missing Key ID: 7..10+200000
Traceback (most recent call last):
  File "C:\Users\rjwal_000\PycharmProjects\Survey Assist\GSI.py", line 105, in format_gsi
    field_name = GSI.GSI_WORD_ID_DICT[two_digit_id]
KeyError: '.+'
2020-03-21 16:04:40,224:Survey Assist:Database in use.  Unable to delete until it is closed
Traceback (most recent call last):
  File "C:\Users\rjwal_000\PycharmProjects\Survey Assist\GSIDatabase.py", line 24, in create_db
    os.remove(GSIDatabase.DATABASE_PATH)
PermissionError: [WinError 32] The process cannot access the file because it is being used by another process: 'GSI Files\\GSI_database.db'
2020-03-21 16:05:16,571:Survey Assist:Database in use.  Unable to delete until it is closed
Traceback (most recent call last):
  File "C:\Users\rjwal_000\PycharmProjects\Survey Assist\GSIDatabase.py", line 24, in create_db
    os.remove(GSIDatabase.DATABASE_PATH)
PermissionError: [WinError 32] The process cannot access the file because it is being used by another process: 'GSI Files\\GSI_database.db'
2020-03-21 16:06:19,258:Survey Assist:Database in use.  Unable to delete until it is closed
Traceback (most recent call last):
  File "C:\Users\rjwal_000\PycharmProjects\Survey Assist\GSIDatabase.py", line 24, in create_db
    os.remove(GSIDatabase.DATABASE_PATH)
PermissionError: [WinError 32] The process cannot access the file because it is being used by another process: 'GSI Files\\GSI_database.db'
2020-03-21 16:26:27,981:Survey Assist:Database in use.  Unable to delete until it is closed
Traceback (most recent call last):
  File "C:\Users\rjwal_000\PycharmProjects\Survey Assist\GSIDatabase.py", line 24, in create_db
    os.remove(GSIDatabase.DATABASE_PATH)
PermissionError: [WinError 32] The process cannot access the file because it is being used by another process: 'GSI Files\\GSI_database.db'
2020-03-21 16:34:00,368:Survey Assist:Database in use.  Unable to delete until it is closed
Traceback (most recent call last):
  File "C:\Users\rjwal_000\PycharmProjects\Survey Assist\GSIDatabase.py", line 24, in create_db
    os.remove(GSIDatabase.DATABASE_PATH)
PermissionError: [WinError 32] The process cannot access the file because it is being used by another process: 'GSI Files\\GSI_database.db'
2020-03-21 16:34:12,848:Survey Assist:Database in use.  Unable to delete until it is closed
Traceback (most recent call last):
  File "C:\Users\rjwal_000\PycharmProjects\Survey Assist\GSIDatabase.py", line 24, in create_db
    os.remove(GSIDatabase.DATABASE_PATH)
PermissionError: [WinError 32] The process cannot access the file because it is being used by another process: 'GSI Files\\GSI_database.db'
2020-03-21 16:34:37,791:Survey Assist:Database in use.  Unable to delete until it is closed
Traceback (most recent call last):
  File "C:\Users\rjwal_000\PycharmProjects\Survey Assist\GSIDatabase.py", line 24, in create_db
    os.remove(GSIDatabase.DATABASE_PATH)
PermissionError: [WinError 32] The process cannot access the file because it is being used by another process: 'GSI Files\\GSI_database.db'
2020-03-21 16:34:54,162:Survey Assist:Database in use.  Unable to delete until it is closed
Traceback (most recent call last):
  File "C:\Users\rjwal_000\PycharmProjects\Survey Assist\GSIDatabase.py", line 24, in create_db
    os.remove(GSIDatabase.DATABASE_PATH)
PermissionError: [WinError 32] The process cannot access the file because it is being used by another process: 'GSI Files\\GSI_database.db'
2020-03-21 16:35:02,365:Survey Assist:Database in use.  Unable to delete until it is closed
Traceback (most recent call last):
  File "C:\Users\rjwal_000\PycharmProjects\Survey Assist\GSIDatabase.py", line 24, in create_db
    os.remove(GSIDatabase.DATABASE_PATH)
PermissionError: [WinError 32] The process cannot access the file because it is being used by another process: 'GSI Files\\GSI_database.db'
2020-03-21 16:35:16,305:Survey Assist:Database in use.  Unable to delete until it is closed
Traceback (most recent call last):
  File "C:\Users\rjwal_000\PycharmProjects\Survey Assist\GSIDatabase.py", line 24, in create_db
    os.remove(GSIDatabase.DATABASE_PATH)
PermissionError: [WinError 32] The process cannot access the file because it is being used by another process: 'GSI Files\\GSI_database.db'
2020-03-21 16:35:28,104:Survey Assist:Database in use.  Unable to delete until it is closed
Traceback (most recent call last):
  File "C:\Users\rjwal_000\PycharmProjects\Survey Assist\GSIDatabase.py", line 24, in create_db
    os.remove(GSIDatabase.DATABASE_PATH)
PermissionError: [WinError 32] The process cannot access the file because it is being used by another process: 'GSI Files\\GSI_database.db'
2020-03-21 16:36:35,859:Survey Assist:Database in use.  Unable to delete until it is closed
Traceback (most recent call last):
  File "C:\Users\rjwal_000\PycharmProjects\Survey Assist\GSIDatabase.py", line 24, in create_db
    os.remove(GSIDatabase.DATABASE_PATH)
PermissionError: [WinError 32] The process cannot access the file because it is being used by another process: 'GSI Files\\GSI_database.db'
2020-03-21 16:37:19,852:Survey Assist:Database in use.  Unable to delete until it is closed
Traceback (most recent call last):
  File "C:\Users\rjwal_000\PycharmProjects\Survey Assist\GSIDatabase.py", line 24, in create_db
    os.remove(GSIDatabase.DATABASE_PATH)
PermissionError: [WinError 32] The process cannot access the file because it is being used by another process: 'GSI Files\\GSI_database.db'
2020-03-21 16:42:50,646:Survey Assist:Database in use.  Unable to delete until it is closed
Traceback (most recent call last):
  File "C:\Users\rjwal_000\PycharmProjects\Survey Assist\GSIDatabase.py", line 24, in create_db
    os.remove(GSIDatabase.DATABASE_PATH)
PermissionError: [WinError 32] The process cannot access the file because it is being used by another process: 'GSI Files\\GSI_database.db'
2020-03-21 16:48:49,555:Survey Assist:Database in use.  Unable to delete until it is closed
Traceback (most recent call last):
  File "C:\Users\rjwal_000\PycharmProjects\Survey Assist\GSIDatabase.py", line 24, in create_db
    os.remove(GSIDatabase.DATABASE_PATH)
PermissionError: [WinError 32] The process cannot access the file because it is being used by another process: 'GSI Files\\GSI_database.db'
2020-03-21 16:49:00,383:Survey Assist:Database in use.  Unable to delete until it is closed
Traceback (most recent call last):
  File "C:\Users\rjwal_000\PycharmProjects\Survey Assist\GSIDatabase.py", line 24, in create_db
    os.remove(GSIDatabase.DATABASE_PATH)
PermissionError: [WinError 32] The process cannot access the file because it is being used by another process: 'GSI Files\\GSI_database.db'
2020-03-21 16:49:05,829:Survey Assist:Database in use.  Unable to delete until it is closed
Traceback (most recent call last):
  File "C:\Users\rjwal_000\PycharmProjects\Survey Assist\GSIDatabase.py", line 24, in create_db
    os.remove(GSIDatabase.DATABASE_PATH)
PermissionError: [WinError 32] The process cannot access the file because it is being used by another process: 'GSI Files\\GSI_database.db'
2020-03-21 16:49:38,523:Survey Assist:Database in use.  Unable to delete until it is closed
Traceback (most recent call last):
  File "C:\Users\rjwal_000\PycharmProjects\Survey Assist\GSIDatabase.py", line 24, in create_db
    os.remove(GSIDatabase.DATABASE_PATH)
PermissionError: [WinError 32] The process cannot access the file because it is being used by another process: 'GSI Files\\GSI_database.db'
2020-03-21 16:51:41,569:Survey Assist:Database in use.  Unable to delete until it is closed
Traceback (most recent call last):
  File "C:\Users\rjwal_000\PycharmProjects\Survey Assist\GSIDatabase.py", line 24, in create_db
    os.remove(GSIDatabase.DATABASE_PATH)
PermissionError: [WinError 32] The process cannot access the file because it is being used by another process: 'GSI Files\\GSI_database.db'
2020-03-21 16:52:24,509:Survey Assist:Database in use.  Unable to delete until it is closed
Traceback (most recent call last):
  File "C:\Users\rjwal_000\PycharmProjects\Survey Assist\GSIDatabase.py", line 24, in create_db
    os.remove(GSIDatabase.DATABASE_PATH)
PermissionError: [WinError 32] The process cannot access the file because it is being used by another process: 'GSI Files\\GSI_database.db'
2020-03-21 16:52:43,872:Survey Assist:Database in use.  Unable to delete until it is closed
Traceback (most recent call last):
  File "C:\Users\rjwal_000\PycharmProjects\Survey Assist\GSIDatabase.py", line 24, in create_db
    os.remove(GSIDatabase.DATABASE_PATH)
PermissionError: [WinError 32] The process cannot access the file because it is being used by another process: 'GSI Files\\GSI_database.db'
2020-03-21 16:53:11,384:Survey Assist:Database in use.  Unable to delete until it is closed
Traceback (most recent call last):
  File "C:\Users\rjwal_000\PycharmProjects\Survey Assist\GSIDatabase.py", line 24, in create_db
    os.remove(GSIDatabase.DATABASE_PATH)
PermissionError: [WinError 32] The process cannot access the file because it is being used by another process: 'GSI Files\\GSI_database.db'
2020-03-21 16:53:23,926:Survey Assist:Database in use.  Unable to delete until it is closed
Traceback (most recent call last):
  File "C:\Users\rjwal_000\PycharmProjects\Survey Assist\GSIDatabase.py", line 24, in create_db
    os.remove(GSIDatabase.DATABASE_PATH)
PermissionError: [WinError 32] The process cannot access the file because it is being used by another process: 'GSI Files\\GSI_database.db'
2020-03-21 16:53:45,502:Survey Assist:Database in use.  Unable to delete until it is closed
Traceback (most recent call last):
  File "C:\Users\rjwal_000\PycharmProjects\Survey Assist\GSIDatabase.py", line 24, in create_db
    os.remove(GSIDatabase.DATABASE_PATH)
PermissionError: [WinError 32] The process cannot access the file because it is being used by another process: 'GSI Files\\GSI_database.db'
2020-03-21 16:54:22,093:Survey Assist:Database in use.  Unable to delete until it is closed
Traceback (most recent call last):
  File "C:\Users\rjwal_000\PycharmProjects\Survey Assist\GSIDatabase.py", line 24, in create_db
    os.remove(GSIDatabase.DATABASE_PATH)
PermissionError: [WinError 32] The process cannot access the file because it is being used by another process: 'GSI Files\\GSI_database.db'
2020-03-21 16:54:56,078:Survey Assist:Database in use.  Unable to delete until it is closed
Traceback (most recent call last):
  File "C:\Users\rjwal_000\PycharmProjects\Survey Assist\GSIDatabase.py", line 24, in create_db
    os.remove(GSIDatabase.DATABASE_PATH)
PermissionError: [WinError 32] The process cannot access the file because it is being used by another process: 'GSI Files\\GSI_database.db'
2020-03-21 16:56:12,697:Survey Assist:Database in use.  Unable to delete until it is closed
Traceback (most recent call last):
  File "C:\Users\rjwal_000\PycharmProjects\Survey Assist\GSIDatabase.py", line 24, in create_db
    os.remove(GSIDatabase.DATABASE_PATH)
PermissionError: [WinError 32] The process cannot access the file because it is being used by another process: 'GSI Files\\GSI_database.db'
2020-03-21 18:56:54,973:Survey Assist:Database in use.  Unable to delete until it is closed
Traceback (most recent call last):
  File "C:\Users\rjwal_000\PycharmProjects\Survey Assist\GSIDatabase.py", line 24, in create_db
    os.remove(GSIDatabase.DATABASE_PATH)
PermissionError: [WinError 32] The process cannot access the file because it is being used by another process: 'GSI Files\\GSI_database.db'
2020-03-21 18:58:06,904:Survey Assist:Database in use.  Unable to delete until it is closed
Traceback (most recent call last):
  File "C:\Users\rjwal_000\PycharmProjects\Survey Assist\GSIDatabase.py", line 24, in create_db
    os.remove(GSIDatabase.DATABASE_PATH)
PermissionError: [WinError 32] The process cannot access the file because it is being used by another process: 'GSI Files\\GSI_database.db'
2020-03-21 18:58:29,592:Survey Assist:Database in use.  Unable to delete until it is closed
Traceback (most recent call last):
  File "C:\Users\rjwal_000\PycharmProjects\Survey Assist\GSIDatabase.py", line 24, in create_db
    os.remove(GSIDatabase.DATABASE_PATH)
PermissionError: [WinError 32] The process cannot access the file because it is being used by another process: 'GSI Files\\GSI_database.db'
2020-03-21 19:03:52,229:Survey Assist:Database in use.  Unable to delete until it is closed
Traceback (most recent call last):
  File "C:\Users\rjwal_000\PycharmProjects\Survey Assist\GSIDatabase.py", line 24, in create_db
    os.remove(GSIDatabase.DATABASE_PATH)
PermissionError: [WinError 32] The process cannot access the file because it is being used by another process: 'GSI Files\\GSI_database.db'
2020-03-21 19:04:14,908:Survey Assist:Database in use.  Unable to delete until it is closed
Traceback (most recent call last):
  File "C:\Users\rjwal_000\PycharmProjects\Survey Assist\GSIDatabase.py", line 24, in create_db
    os.remove(GSIDatabase.DATABASE_PATH)
PermissionError: [WinError 32] The process cannot access the file because it is being used by another process: 'GSI Files\\GSI_database.db'
2020-03-21 19:04:56,196:Survey Assist:Database in use.  Unable to delete until it is closed
Traceback (most recent call last):
  File "C:\Users\rjwal_000\PycharmProjects\Survey Assist\GSIDatabase.py", line 24, in create_db
    os.remove(GSIDatabase.DATABASE_PATH)
PermissionError: [WinError 32] The process cannot access the file because it is being used by another process: 'GSI Files\\GSI_database.db'
2020-03-22 08:57:55,690:Survey Assist:Database in use.  Unable to delete until it is closed
Traceback (most recent call last):
  File "C:\Users\rjwal_000\PycharmProjects\Survey Assist\GSIDatabase.py", line 24, in create_db
    os.remove(GSIDatabase.DATABASE_PATH)
PermissionError: [WinError 32] The process cannot access the file because it is being used by another process: 'GSI Files\\GSI_database.db'
2020-03-22 08:58:06,537:Survey Assist:Database in use.  Unable to delete until it is closed
Traceback (most recent call last):
  File "C:\Users\rjwal_000\PycharmProjects\Survey Assist\GSIDatabase.py", line 24, in create_db
    os.remove(GSIDatabase.DATABASE_PATH)
PermissionError: [WinError 32] The process cannot access the file because it is being used by another process: 'GSI Files\\GSI_database.db'
2020-03-22 08:58:24,178:Survey Assist:Database in use.  Unable to delete until it is closed
Traceback (most recent call last):
  File "C:\Users\rjwal_000\PycharmProjects\Survey Assist\GSIDatabase.py", line 24, in create_db
    os.remove(GSIDatabase.DATABASE_PATH)
PermissionError: [WinError 32] The process cannot access the file because it is being used by another process: 'GSI Files\\GSI_database.db'
2020-03-22 08:59:01,842:Survey Assist:Database in use.  Unable to delete until it is closed
Traceback (most recent call last):
  File "C:\Users\rjwal_000\PycharmProjects\Survey Assist\GSIDatabase.py", line 24, in create_db
    os.remove(GSIDatabase.DATABASE_PATH)
PermissionError: [WinError 32] The process cannot access the file because it is being used by another process: 'GSI Files\\GSI_database.db'
2020-03-22 09:01:07,961:Survey Assist:Database in use.  Unable to delete until it is closed
Traceback (most recent call last):
  File "C:\Users\rjwal_000\PycharmProjects\Survey Assist\GSIDatabase.py", line 24, in create_db
    os.remove(GSIDatabase.DATABASE_PATH)
PermissionError: [WinError 32] The process cannot access the file because it is being used by another process: 'GSI Files\\GSI_database.db'
2020-03-22 16:00:07,964:Survey Assist:Database in use.  Unable to delete until it is closed
Traceback (most recent call last):
  File "C:\Users\rjwal_000\PycharmProjects\Survey Assist\GSIDatabase.py", line 24, in create_db
    os.remove(GSIDatabase.DATABASE_PATH)
PermissionError: [WinError 32] The process cannot access the file because it is being used by another process: 'GSI Files\\GSI_database.db'
2020-03-22 16:01:04,095:Survey Assist:Database in use.  Unable to delete until it is closed
Traceback (most recent call last):
  File "C:\Users\rjwal_000\PycharmProjects\Survey Assist\GSIDatabase.py", line 24, in create_db
    os.remove(GSIDatabase.DATABASE_PATH)
PermissionError: [WinError 32] The process cannot access the file because it is being used by another process: 'GSI Files\\GSI_database.db'
2020-03-22 16:08:30,684:Survey Assist:Database in use.  Unable to delete until it is closed
Traceback (most recent call last):
  File "C:\Users\rjwal_000\PycharmProjects\Survey Assist\GSIDatabase.py", line 24, in create_db
    os.remove(GSIDatabase.DATABASE_PATH)
PermissionError: [WinError 32] The process cannot access the file because it is being used by another process: 'GSI Files\\GSI_database.db'
2020-03-22 16:09:35,914:Survey Assist:File doesn't appear to be a valid GSI file.  Missing Key ID: +00000000000CUL75
Traceback (most recent call last):
  File "C:\Users\rjwal_000\PycharmProjects\Survey Assist\GSI.py", line 105, in format_gsi
    field_name = GSI.GSI_WORD_ID_DICT[two_digit_id]
KeyError: '*1'
2020-03-22 16:10:21,502:Survey Assist:File doesn't appear to be a valid GSI file.  Missing Key ID: +00000000000CUL75
Traceback (most recent call last):
  File "C:\Users\rjwal_000\PycharmProjects\Survey Assist\GSI.py", line 105, in format_gsi
    field_name = GSI.GSI_WORD_ID_DICT[two_digit_id]
KeyError: '*1'
2020-03-22 16:10:23,843:Survey Assist:Database in use.  Unable to delete until it is closed
Traceback (most recent call last):
  File "C:\Users\rjwal_000\PycharmProjects\Survey Assist\GSIDatabase.py", line 24, in create_db
    os.remove(GSIDatabase.DATABASE_PATH)
PermissionError: [WinError 32] The process cannot access the file because it is being used by another process: 'GSI Files\\GSI_database.db'
2020-03-22 16:19:18,424:Survey Assist:File doesn't appear to be a valid GSI file.  Missing Key ID: +00000000000CUL75
Traceback (most recent call last):
  File "C:\Users\rjwal_000\PycharmProjects\Survey Assist\GSI.py", line 105, in format_gsi
    field_name = GSI.GSI_WORD_ID_DICT[two_digit_id]
KeyError: '*1'
2020-03-22 16:19:19,853:Survey Assist:Database in use.  Unable to delete until it is closed
Traceback (most recent call last):
  File "C:\Users\rjwal_000\PycharmProjects\Survey Assist\GSIDatabase.py", line 24, in create_db
    os.remove(GSIDatabase.DATABASE_PATH)
PermissionError: [WinError 32] The process cannot access the file because it is being used by another process: 'GSI Files\\GSI_database.db'
2020-03-22 16:20:12,473:Survey Assist:File doesn't appear to be a valid GSI file.  Missing Key ID: +00000000000CUL75
Traceback (most recent call last):
  File "C:\Users\rjwal_000\PycharmProjects\Survey Assist\GSI.py", line 105, in format_gsi
    field_name = GSI.GSI_WORD_ID_DICT[two_digit_id]
KeyError: '*1'
2020-03-22 16:48:42,765:Survey Assist:Database in use.  Unable to delete until it is closed
Traceback (most recent call last):
  File "C:\Users\rjwal_000\PycharmProjects\Survey Assist\GSIDatabase.py", line 24, in create_db
    os.remove(GSIDatabase.DATABASE_PATH)
PermissionError: [WinError 32] The process cannot access the file because it is being used by another process: 'GSI Files\\GSI_database.db'
2020-03-22 16:48:47,220:Survey Assist:File doesn't appear to be a valid GSI file.  Missing Key ID: +00000000000CUL75
Traceback (most recent call last):
  File "C:\Users\rjwal_000\PycharmProjects\Survey Assist\GSI.py", line 105, in format_gsi
    field_name = GSI.GSI_WORD_ID_DICT[two_digit_id]
KeyError: '*1'
2020-03-22 16:48:48,653:Survey Assist:Database in use.  Unable to delete until it is closed
Traceback (most recent call last):
  File "C:\Users\rjwal_000\PycharmProjects\Survey Assist\GSIDatabase.py", line 24, in create_db
    os.remove(GSIDatabase.DATABASE_PATH)
PermissionError: [WinError 32] The process cannot access the file because it is being used by another process: 'GSI Files\\GSI_database.db'
2020-03-22 16:50:11,936:Survey Assist:Database in use.  Unable to delete until it is closed
Traceback (most recent call last):
  File "C:\Users\rjwal_000\PycharmProjects\Survey Assist\GSIDatabase.py", line 24, in create_db
    os.remove(GSIDatabase.DATABASE_PATH)
PermissionError: [WinError 32] The process cannot access the file because it is being used by another process: 'GSI Files\\GSI_database.db'
2020-03-22 16:50:20,888:Survey Assist:Database in use.  Unable to delete until it is closed
Traceback (most recent call last):
  File "C:\Users\rjwal_000\PycharmProjects\Survey Assist\GSIDatabase.py", line 24, in create_db
    os.remove(GSIDatabase.DATABASE_PATH)
PermissionError: [WinError 32] The process cannot access the file because it is being used by another process: 'GSI Files\\GSI_database.db'
2020-03-22 17:21:19,022:Survey Assist:File doesn't appear to be a valid GSI file.  Missing Key ID: +00000000000CUL75
Traceback (most recent call last):
  File "C:\Users\rjwal_000\PycharmProjects\Survey Assist\GSI.py", line 105, in format_gsi
    field_name = GSI.GSI_WORD_ID_DICT[two_digit_id]
KeyError: '*1'
2020-03-22 17:21:48,783:Survey Assist:File doesn't appear to be a valid GSI file.  Missing Key ID: +00000000000CUL75
Traceback (most recent call last):
  File "C:\Users\rjwal_000\PycharmProjects\Survey Assist\GSI.py", line 105, in format_gsi
    field_name = GSI.GSI_WORD_ID_DICT[two_digit_id]
KeyError: '*1'
2020-03-22 17:21:49,997:Survey Assist:Database in use.  Unable to delete until it is closed
Traceback (most recent call last):
  File "C:\Users\rjwal_000\PycharmProjects\Survey Assist\GSIDatabase.py", line 24, in create_db
    os.remove(GSIDatabase.DATABASE_PATH)
PermissionError: [WinError 32] The process cannot access the file because it is being used by another process: 'GSI Files\\GSI_database.db'
2020-03-22 17:25:44,457:Survey Assist:File doesn't appear to be a valid GSI file.  Missing Key ID: +00000000000STN03
Traceback (most recent call last):
  File "C:\Users\rjwal_000\PycharmProjects\Survey Assist\GSI.py", line 105, in format_gsi
    field_name = GSI.GSI_WORD_ID_DICT[two_digit_id]
KeyError: '*1'
2020-03-22 17:25:46,062:Survey Assist:Database in use.  Unable to delete until it is closed
Traceback (most recent call last):
  File "C:\Users\rjwal_000\PycharmProjects\Survey Assist\GSIDatabase.py", line 24, in create_db
    os.remove(GSIDatabase.DATABASE_PATH)
PermissionError: [WinError 32] The process cannot access the file because it is being used by another process: 'GSI Files\\GSI_database.db'
2020-03-22 17:26:38,769:Survey Assist:File doesn't appear to be a valid GSI file.  Missing Key ID: +00000000000STN03
Traceback (most recent call last):
  File "C:\Users\rjwal_000\PycharmProjects\Survey Assist\GSI.py", line 105, in format_gsi
    field_name = GSI.GSI_WORD_ID_DICT[two_digit_id]
KeyError: '*1'
2020-03-22 17:27:04,848:Survey Assist:Database in use.  Unable to delete until it is closed
Traceback (most recent call last):
  File "C:\Users\rjwal_000\PycharmProjects\Survey Assist\GSIDatabase.py", line 24, in create_db
    os.remove(GSIDatabase.DATABASE_PATH)
PermissionError: [WinError 32] The process cannot access the file because it is being used by another process: 'GSI Files\\GSI_database.db'
2020-03-22 17:27:43,807:Survey Assist:File doesn't appear to be a valid GSI file.  Missing Key ID: +00000000000STN03
Traceback (most recent call last):
  File "C:\Users\rjwal_000\PycharmProjects\Survey Assist\GSI.py", line 105, in format_gsi
    field_name = GSI.GSI_WORD_ID_DICT[two_digit_id]
KeyError: '*1'
2020-03-22 17:27:44,991:Survey Assist:Database in use.  Unable to delete until it is closed
Traceback (most recent call last):
  File "C:\Users\rjwal_000\PycharmProjects\Survey Assist\GSIDatabase.py", line 24, in create_db
    os.remove(GSIDatabase.DATABASE_PATH)
PermissionError: [WinError 32] The process cannot access the file because it is being used by another process: 'GSI Files\\GSI_database.db'
2020-03-22 17:28:16,937:Survey Assist:Database in use.  Unable to delete until it is closed
Traceback (most recent call last):
  File "C:\Users\rjwal_000\PycharmProjects\Survey Assist\GSIDatabase.py", line 24, in create_db
    os.remove(GSIDatabase.DATABASE_PATH)
PermissionError: [WinError 32] The process cannot access the file because it is being used by another process: 'GSI Files\\GSI_database.db'
2020-03-22 17:28:46,681:Survey Assist:File doesn't appear to be a valid GSI file.  Missing Key ID: +00000000000STN03
Traceback (most recent call last):
  File "C:\Users\rjwal_000\PycharmProjects\Survey Assist\GSI.py", line 105, in format_gsi
    field_name = GSI.GSI_WORD_ID_DICT[two_digit_id]
KeyError: '*1'
2020-03-22 17:28:51,780:Survey Assist:Database in use.  Unable to delete until it is closed
Traceback (most recent call last):
  File "C:\Users\rjwal_000\PycharmProjects\Survey Assist\GSIDatabase.py", line 24, in create_db
    os.remove(GSIDatabase.DATABASE_PATH)
PermissionError: [WinError 32] The process cannot access the file because it is being used by another process: 'GSI Files\\GSI_database.db'
2020-03-22 17:35:42,760:Survey Assist:File doesn't appear to be a valid GSI file.  Missing Key ID: +00000000000STN03
Traceback (most recent call last):
  File "C:\Users\rjwal_000\PycharmProjects\Survey Assist\GSI.py", line 105, in format_gsi
    field_name = GSI.GSI_WORD_ID_DICT[two_digit_id]
KeyError: '*1'
2020-03-22 17:37:05,952:Survey Assist:Database in use.  Unable to delete until it is closed
Traceback (most recent call last):
  File "C:\Users\rjwal_000\PycharmProjects\Survey Assist\GSIDatabase.py", line 24, in create_db
    os.remove(GSIDatabase.DATABASE_PATH)
PermissionError: [WinError 32] The process cannot access the file because it is being used by another process: 'GSI Files\\GSI_database.db'
2020-03-22 17:37:48,281:Survey Assist:Database in use.  Unable to delete until it is closed
Traceback (most recent call last):
  File "C:\Users\rjwal_000\PycharmProjects\Survey Assist\GSIDatabase.py", line 24, in create_db
    os.remove(GSIDatabase.DATABASE_PATH)
PermissionError: [WinError 32] The process cannot access the file because it is being used by another process: 'GSI Files\\GSI_database.db'
2020-03-22 17:38:00,859:Survey Assist:Database in use.  Unable to delete until it is closed
Traceback (most recent call last):
  File "C:\Users\rjwal_000\PycharmProjects\Survey Assist\GSIDatabase.py", line 24, in create_db
    os.remove(GSIDatabase.DATABASE_PATH)
PermissionError: [WinError 32] The process cannot access the file because it is being used by another process: 'GSI Files\\GSI_database.db'
2020-03-22 17:38:20,710:Survey Assist:File doesn't appear to be a valid GSI file.  Missing Key ID: +00000000000STN03
Traceback (most recent call last):
  File "C:\Users\rjwal_000\PycharmProjects\Survey Assist\GSI.py", line 105, in format_gsi
    field_name = GSI.GSI_WORD_ID_DICT[two_digit_id]
KeyError: '*1'
2020-03-22 17:38:21,967:Survey Assist:Database in use.  Unable to delete until it is closed
Traceback (most recent call last):
  File "C:\Users\rjwal_000\PycharmProjects\Survey Assist\GSIDatabase.py", line 24, in create_db
    os.remove(GSIDatabase.DATABASE_PATH)
PermissionError: [WinError 32] The process cannot access the file because it is being used by another process: 'GSI Files\\GSI_database.db'
2020-03-22 17:38:36,608:Survey Assist:Database in use.  Unable to delete until it is closed
Traceback (most recent call last):
  File "C:\Users\rjwal_000\PycharmProjects\Survey Assist\GSIDatabase.py", line 24, in create_db
    os.remove(GSIDatabase.DATABASE_PATH)
PermissionError: [WinError 32] The process cannot access the file because it is being used by another process: 'GSI Files\\GSI_database.db'
2020-03-22 18:52:27,060:Survey Assist:Database in use.  Unable to delete until it is closed
Traceback (most recent call last):
  File "C:\Users\rjwal_000\PycharmProjects\Survey Assist\GSIDatabase.py", line 24, in create_db
    os.remove(GSIDatabase.DATABASE_PATH)
PermissionError: [WinError 32] The process cannot access the file because it is being used by another process: 'GSI Files\\GSI_database.db'
2020-03-22 18:54:12,592:Survey Assist:Database in use.  Unable to delete until it is closed
Traceback (most recent call last):
  File "C:\Users\rjwal_000\PycharmProjects\Survey Assist\GSIDatabase.py", line 24, in create_db
    os.remove(GSIDatabase.DATABASE_PATH)
PermissionError: [WinError 32] The process cannot access the file because it is being used by another process: 'GSI Files\\GSI_database.db'
2020-03-22 18:54:21,294:Survey Assist:Database in use.  Unable to delete until it is closed
Traceback (most recent call last):
  File "C:\Users\rjwal_000\PycharmProjects\Survey Assist\GSIDatabase.py", line 24, in create_db
    os.remove(GSIDatabase.DATABASE_PATH)
PermissionError: [WinError 32] The process cannot access the file because it is being used by another process: 'GSI Files\\GSI_database.db'
2020-03-22 18:54:31,571:Survey Assist:Database in use.  Unable to delete until it is closed
Traceback (most recent call last):
  File "C:\Users\rjwal_000\PycharmProjects\Survey Assist\GSIDatabase.py", line 24, in create_db
    os.remove(GSIDatabase.DATABASE_PATH)
PermissionError: [WinError 32] The process cannot access the file because it is being used by another process: 'GSI Files\\GSI_database.db'
2020-03-22 18:54:48,002:Survey Assist:Database in use.  Unable to delete until it is closed
Traceback (most recent call last):
  File "C:\Users\rjwal_000\PycharmProjects\Survey Assist\GSIDatabase.py", line 24, in create_db
    os.remove(GSIDatabase.DATABASE_PATH)
PermissionError: [WinError 32] The process cannot access the file because it is being used by another process: 'GSI Files\\GSI_database.db'
2020-03-22 18:55:12,841:Survey Assist:Database in use.  Unable to delete until it is closed
Traceback (most recent call last):
  File "C:\Users\rjwal_000\PycharmProjects\Survey Assist\GSIDatabase.py", line 24, in create_db
    os.remove(GSIDatabase.DATABASE_PATH)
PermissionError: [WinError 32] The process cannot access the file because it is being used by another process: 'GSI Files\\GSI_database.db'
2020-03-22 18:59:34,297:Survey Assist:Database in use.  Unable to delete until it is closed
Traceback (most recent call last):
  File "C:\Users\rjwal_000\PycharmProjects\Survey Assist\GSIDatabase.py", line 24, in create_db
    os.remove(GSIDatabase.DATABASE_PATH)
PermissionError: [WinError 32] The process cannot access the file because it is being used by another process: 'GSI Files\\GSI_database.db'
2020-03-23 17:12:53,265:Survey Assist:Database in use.  Unable to delete until it is closed
Traceback (most recent call last):
  File "C:\Users\rjwal_000\PycharmProjects\Survey Assist\GSIDatabase.py", line 24, in create_db
    os.remove(GSIDatabase.DATABASE_PATH)
PermissionError: [WinError 32] The process cannot access the file because it is being used by another process: 'GSI Files\\GSI_database.db'
2020-03-23 17:13:06,233:Survey Assist:Database in use.  Unable to delete until it is closed
Traceback (most recent call last):
  File "C:\Users\rjwal_000\PycharmProjects\Survey Assist\GSIDatabase.py", line 24, in create_db
    os.remove(GSIDatabase.DATABASE_PATH)
PermissionError: [WinError 32] The process cannot access the file because it is being used by another process: 'GSI Files\\GSI_database.db'
2020-03-23 17:13:11,686:Survey Assist:Database in use.  Unable to delete until it is closed
Traceback (most recent call last):
  File "C:\Users\rjwal_000\PycharmProjects\Survey Assist\GSIDatabase.py", line 24, in create_db
    os.remove(GSIDatabase.DATABASE_PATH)
PermissionError: [WinError 32] The process cannot access the file because it is being used by another process: 'GSI Files\\GSI_database.db'
2020-03-23 17:13:37,031:Survey Assist:Database in use.  Unable to delete until it is closed
Traceback (most recent call last):
  File "C:\Users\rjwal_000\PycharmProjects\Survey Assist\GSIDatabase.py", line 24, in create_db
    os.remove(GSIDatabase.DATABASE_PATH)
PermissionError: [WinError 32] The process cannot access the file because it is being used by another process: 'GSI Files\\GSI_database.db'
2020-03-23 17:13:51,357:Survey Assist:Database in use.  Unable to delete until it is closed
Traceback (most recent call last):
  File "C:\Users\rjwal_000\PycharmProjects\Survey Assist\GSIDatabase.py", line 24, in create_db
    os.remove(GSIDatabase.DATABASE_PATH)
PermissionError: [WinError 32] The process cannot access the file because it is being used by another process: 'GSI Files\\GSI_database.db'
2020-03-23 17:14:14,338:Survey Assist:Database in use.  Unable to delete until it is closed
Traceback (most recent call last):
  File "C:\Users\rjwal_000\PycharmProjects\Survey Assist\GSIDatabase.py", line 24, in create_db
    os.remove(GSIDatabase.DATABASE_PATH)
PermissionError: [WinError 32] The process cannot access the file because it is being used by another process: 'GSI Files\\GSI_database.db'
2020-03-23 18:01:51,665:Survey Assist:Database in use.  Unable to delete until it is closed
Traceback (most recent call last):
  File "C:\Users\rjwal_000\PycharmProjects\Survey Assist\GSIDatabase.py", line 24, in create_db
    os.remove(GSIDatabase.DATABASE_PATH)
PermissionError: [WinError 32] The process cannot access the file because it is being used by another process: 'GSI Files\\GSI_database.db'
2020-03-23 18:09:00,054:Survey Assist:Database in use.  Unable to delete until it is closed
Traceback (most recent call last):
  File "C:\Users\rjwal_000\PycharmProjects\Survey Assist\GSIDatabase.py", line 24, in create_db
    os.remove(GSIDatabase.DATABASE_PATH)
PermissionError: [WinError 32] The process cannot access the file because it is being used by another process: 'GSI Files\\GSI_database.db'
2020-03-23 18:09:33,486:Survey Assist:Database in use.  Unable to delete until it is closed
Traceback (most recent call last):
  File "C:\Users\rjwal_000\PycharmProjects\Survey Assist\GSIDatabase.py", line 24, in create_db
    os.remove(GSIDatabase.DATABASE_PATH)
PermissionError: [WinError 32] The process cannot access the file because it is being used by another process: 'GSI Files\\GSI_database.db'
2020-03-23 18:39:20,815:Survey Assist:Database in use.  Unable to delete until it is closed
Traceback (most recent call last):
  File "C:\Users\rjwal_000\PycharmProjects\Survey Assist\GSIDatabase.py", line 24, in create_db
    os.remove(GSIDatabase.DATABASE_PATH)
PermissionError: [WinError 32] The process cannot access the file because it is being used by another process: 'GSI Files\\GSI_database.db'
2020-03-23 18:41:08,302:Survey Assist:Database in use.  Unable to delete until it is closed
Traceback (most recent call last):
  File "C:\Users\rjwal_000\PycharmProjects\Survey Assist\GSIDatabase.py", line 24, in create_db
    os.remove(GSIDatabase.DATABASE_PATH)
PermissionError: [WinError 32] The process cannot access the file because it is being used by another process: 'GSI Files\\GSI_database.db'
2020-03-28 15:03:39,623:Survey Assist:Database in use.  Unable to delete until it is closed
Traceback (most recent call last):
  File "C:\Users\rjwal_000\PycharmProjects\Survey Assist\GSIDatabase.py", line 24, in create_db
    os.remove(GSIDatabase.DATABASE_PATH)
PermissionError: [WinError 32] The process cannot access the file because it is being used by another process: 'GSI Files\\GSI_database.db'
2020-03-28 15:07:06,739:Survey Assist:Database in use.  Unable to delete until it is closed
Traceback (most recent call last):
  File "C:\Users\rjwal_000\PycharmProjects\Survey Assist\GSIDatabase.py", line 24, in create_db
    os.remove(GSIDatabase.DATABASE_PATH)
PermissionError: [WinError 32] The process cannot access the file because it is being used by another process: 'GSI Files\\GSI_database.db'
2020-03-29 10:54:47,489:Survey Assist:Database in use.  Unable to delete until it is closed
Traceback (most recent call last):
  File "C:\Users\rjwal_000\PycharmProjects\Survey Assist\GSIDatabase.py", line 24, in create_db
    os.remove(GSIDatabase.DATABASE_PATH)
PermissionError: [WinError 32] The process cannot access the file because it is being used by another process: 'GSI Files\\GSI_database.db'
2020-03-29 10:57:49,946:Survey Assist:Database in use.  Unable to delete until it is closed
Traceback (most recent call last):
  File "C:\Users\rjwal_000\PycharmProjects\Survey Assist\GSIDatabase.py", line 24, in create_db
    os.remove(GSIDatabase.DATABASE_PATH)
PermissionError: [WinError 32] The process cannot access the file because it is being used by another process: 'GSI Files\\GSI_database.db'
2020-03-29 11:10:41,125:Survey Assist:Database in use.  Unable to delete until it is closed
Traceback (most recent call last):
  File "C:\Users\rjwal_000\PycharmProjects\Survey Assist\GSIDatabase.py", line 24, in create_db
    os.remove(GSIDatabase.DATABASE_PATH)
PermissionError: [WinError 32] The process cannot access the file because it is being used by another process: 'GSI Files\\GSI_database.db'
2020-03-29 11:19:51,898:Survey Assist:Database in use.  Unable to delete until it is closed
Traceback (most recent call last):
  File "C:\Users\rjwal_000\PycharmProjects\Survey Assist\GSIDatabase.py", line 24, in create_db
    os.remove(GSIDatabase.DATABASE_PATH)
PermissionError: [WinError 32] The process cannot access the file because it is being used by another process: 'GSI Files\\GSI_database.db'
2020-03-29 11:19:59,774:Survey Assist:Database in use.  Unable to delete until it is closed
Traceback (most recent call last):
  File "C:\Users\rjwal_000\PycharmProjects\Survey Assist\GSIDatabase.py", line 24, in create_db
    os.remove(GSIDatabase.DATABASE_PATH)
PermissionError: [WinError 32] The process cannot access the file because it is being used by another process: 'GSI Files\\GSI_database.db'
2020-03-29 14:29:00,538:Survey Assist:Database in use.  Unable to delete until it is closed
Traceback (most recent call last):
  File "C:\Users\rjwal_000\PycharmProjects\Survey Assist\GSIDatabase.py", line 24, in create_db
    os.remove(GSIDatabase.DATABASE_PATH)
PermissionError: [WinError 32] The process cannot access the file because it is being used by another process: 'GSI Files\\GSI_database.db'
2020-03-29 14:29:12,190:Survey Assist:Database in use.  Unable to delete until it is closed
Traceback (most recent call last):
  File "C:\Users\rjwal_000\PycharmProjects\Survey Assist\GSIDatabase.py", line 24, in create_db
    os.remove(GSIDatabase.DATABASE_PATH)
PermissionError: [WinError 32] The process cannot access the file because it is being used by another process: 'GSI Files\\GSI_database.db'
2020-03-30 21:34:02,152:Survey Assist:Database in use.  Unable to delete until it is closed
Traceback (most recent call last):
  File "C:\Users\rjwal_000\PycharmProjects\Survey Assist\GSIDatabase.py", line 24, in create_db
    os.remove(GSIDatabase.DATABASE_PATH)
PermissionError: [WinError 32] The process cannot access the file because it is being used by another process: 'GSI Files\\GSI_database.db'
2020-03-30 21:34:31,199:Survey Assist:Database in use.  Unable to delete until it is closed
Traceback (most recent call last):
  File "C:\Users\rjwal_000\PycharmProjects\Survey Assist\GSIDatabase.py", line 24, in create_db
    os.remove(GSIDatabase.DATABASE_PATH)
PermissionError: [WinError 32] The process cannot access the file because it is being used by another process: 'GSI Files\\GSI_database.db'
2020-03-30 21:34:52,120:Survey Assist:Database in use.  Unable to delete until it is closed
Traceback (most recent call last):
  File "C:\Users\rjwal_000\PycharmProjects\Survey Assist\GSIDatabase.py", line 24, in create_db
    os.remove(GSIDatabase.DATABASE_PATH)
PermissionError: [WinError 32] The process cannot access the file because it is being used by another process: 'GSI Files\\GSI_database.db'
2020-03-30 21:34:58,166:Survey Assist:Database in use.  Unable to delete until it is closed
Traceback (most recent call last):
  File "C:\Users\rjwal_000\PycharmProjects\Survey Assist\GSIDatabase.py", line 24, in create_db
    os.remove(GSIDatabase.DATABASE_PATH)
PermissionError: [WinError 32] The process cannot access the file because it is being used by another process: 'GSI Files\\GSI_database.db'
2020-03-30 21:35:27,542:Survey Assist:Database in use.  Unable to delete until it is closed
Traceback (most recent call last):
  File "C:\Users\rjwal_000\PycharmProjects\Survey Assist\GSIDatabase.py", line 24, in create_db
    os.remove(GSIDatabase.DATABASE_PATH)
PermissionError: [WinError 32] The process cannot access the file because it is being used by another process: 'GSI Files\\GSI_database.db'
2020-03-30 21:36:23,275:Survey Assist:Database in use.  Unable to delete until it is closed
Traceback (most recent call last):
  File "C:\Users\rjwal_000\PycharmProjects\Survey Assist\GSIDatabase.py", line 24, in create_db
    os.remove(GSIDatabase.DATABASE_PATH)
PermissionError: [WinError 32] The process cannot access the file because it is being used by another process: 'GSI Files\\GSI_database.db'
2020-03-30 21:36:47,994:Survey Assist:Database in use.  Unable to delete until it is closed
Traceback (most recent call last):
  File "C:\Users\rjwal_000\PycharmProjects\Survey Assist\GSIDatabase.py", line 24, in create_db
    os.remove(GSIDatabase.DATABASE_PATH)
PermissionError: [WinError 32] The process cannot access the file because it is being used by another process: 'GSI Files\\GSI_database.db'
2020-03-30 21:37:19,930:Survey Assist:Database in use.  Unable to delete until it is closed
Traceback (most recent call last):
  File "C:\Users\rjwal_000\PycharmProjects\Survey Assist\GSIDatabase.py", line 24, in create_db
    os.remove(GSIDatabase.DATABASE_PATH)
PermissionError: [WinError 32] The process cannot access the file because it is being used by another process: 'GSI Files\\GSI_database.db'
2020-03-30 21:40:12,005:Survey Assist:Database in use.  Unable to delete until it is closed
Traceback (most recent call last):
  File "C:\Users\rjwal_000\PycharmProjects\Survey Assist\GSIDatabase.py", line 24, in create_db
    os.remove(GSIDatabase.DATABASE_PATH)
PermissionError: [WinError 32] The process cannot access the file because it is being used by another process: 'GSI Files\\GSI_database.db'
2020-03-30 21:42:19,211:Survey Assist:Database in use.  Unable to delete until it is closed
Traceback (most recent call last):
  File "C:\Users\rjwal_000\PycharmProjects\Survey Assist\GSIDatabase.py", line 24, in create_db
    os.remove(GSIDatabase.DATABASE_PATH)
PermissionError: [WinError 32] The process cannot access the file because it is being used by another process: 'GSI Files\\GSI_database.db'
2020-03-30 21:48:50,298:Survey Assist:Database in use.  Unable to delete until it is closed
Traceback (most recent call last):
  File "C:\Users\rjwal_000\PycharmProjects\Survey Assist\GSIDatabase.py", line 24, in create_db
    os.remove(GSIDatabase.DATABASE_PATH)
PermissionError: [WinError 32] The process cannot access the file because it is being used by another process: 'GSI Files\\GSI_database.db'
2020-03-30 21:49:37,048:Survey Assist:Database in use.  Unable to delete until it is closed
Traceback (most recent call last):
  File "C:\Users\rjwal_000\PycharmProjects\Survey Assist\GSIDatabase.py", line 24, in create_db
    os.remove(GSIDatabase.DATABASE_PATH)
PermissionError: [WinError 32] The process cannot access the file because it is being used by another process: 'GSI Files\\GSI_database.db'
2020-03-30 21:53:38,263:Survey Assist:Database in use.  Unable to delete until it is closed
Traceback (most recent call last):
  File "C:\Users\rjwal_000\PycharmProjects\Survey Assist\GSIDatabase.py", line 24, in create_db
    os.remove(GSIDatabase.DATABASE_PATH)
PermissionError: [WinError 32] The process cannot access the file because it is being used by another process: 'GSI Files\\GSI_database.db'
2020-03-30 21:53:43,931:Survey Assist:Database in use.  Unable to delete until it is closed
Traceback (most recent call last):
  File "C:\Users\rjwal_000\PycharmProjects\Survey Assist\GSIDatabase.py", line 24, in create_db
    os.remove(GSIDatabase.DATABASE_PATH)
PermissionError: [WinError 32] The process cannot access the file because it is being used by another process: 'GSI Files\\GSI_database.db'
2020-03-30 21:54:10,779:Survey Assist:Database in use.  Unable to delete until it is closed
Traceback (most recent call last):
  File "C:\Users\rjwal_000\PycharmProjects\Survey Assist\GSIDatabase.py", line 24, in create_db
    os.remove(GSIDatabase.DATABASE_PATH)
PermissionError: [WinError 32] The process cannot access the file because it is being used by another process: 'GSI Files\\GSI_database.db'
2020-04-02 12:07:25,006:Survey Assist:Database in use.  Unable to delete until it is closed
Traceback (most recent call last):
  File "C:\Users\Richard\PycharmProjects\Survey Assist\GSIDatabase.py", line 24, in create_db
    os.remove(GSIDatabase.DATABASE_PATH)
PermissionError: [WinError 32] The process cannot access the file because it is being used by another process: 'GSI Files\\GSI_database.db'
2020-04-02 12:30:57,774:Survey Assist:Database in use.  Unable to delete until it is closed
Traceback (most recent call last):
  File "C:\Users\Richard\PycharmProjects\Survey Assist\GSIDatabase.py", line 24, in create_db
    os.remove(GSIDatabase.DATABASE_PATH)
PermissionError: [WinError 32] The process cannot access the file because it is being used by another process: 'GSI Files\\GSI_database.db'
2020-04-02 12:37:35,193:Survey Assist:Database in use.  Unable to delete until it is closed
Traceback (most recent call last):
  File "C:\Users\Richard\PycharmProjects\Survey Assist\GSIDatabase.py", line 24, in create_db
    os.remove(GSIDatabase.DATABASE_PATH)
PermissionError: [WinError 32] The process cannot access the file because it is being used by another process: 'GSI Files\\GSI_database.db'
2020-04-02 12:55:13,325:Survey Assist:Database in use.  Unable to delete until it is closed
Traceback (most recent call last):
  File "C:\Users\Richard\PycharmProjects\Survey Assist\GSIDatabase.py", line 24, in create_db
    os.remove(GSIDatabase.DATABASE_PATH)
PermissionError: [WinError 32] The process cannot access the file because it is being used by another process: 'GSI Files\\GSI_database.db'
2020-04-02 12:55:53,198:Survey Assist:Database in use.  Unable to delete until it is closed
Traceback (most recent call last):
  File "C:\Users\Richard\PycharmProjects\Survey Assist\GSIDatabase.py", line 24, in create_db
    os.remove(GSIDatabase.DATABASE_PATH)
PermissionError: [WinError 32] The process cannot access the file because it is being used by another process: 'GSI Files\\GSI_database.db'
2020-04-02 13:34:30,064:Survey Assist:Database in use.  Unable to delete until it is closed
Traceback (most recent call last):
  File "C:\Users\Richard\PycharmProjects\Survey Assist\GSIDatabase.py", line 24, in create_db
    os.remove(GSIDatabase.DATABASE_PATH)
PermissionError: [WinError 32] The process cannot access the file because it is being used by another process: 'GSI Files\\GSI_database.db'
2020-04-02 13:35:41,547:Survey Assist:Database in use.  Unable to delete until it is closed
Traceback (most recent call last):
  File "C:\Users\Richard\PycharmProjects\Survey Assist\GSIDatabase.py", line 24, in create_db
    os.remove(GSIDatabase.DATABASE_PATH)
PermissionError: [WinError 32] The process cannot access the file because it is being used by another process: 'GSI Files\\GSI_database.db'
2020-04-02 13:41:23,667:Survey Assist:Database in use.  Unable to delete until it is closed
Traceback (most recent call last):
  File "C:\Users\Richard\PycharmProjects\Survey Assist\GSIDatabase.py", line 24, in create_db
    os.remove(GSIDatabase.DATABASE_PATH)
PermissionError: [WinError 32] The process cannot access the file because it is being used by another process: 'GSI Files\\GSI_database.db'
2020-04-02 14:06:18,727:Survey Assist:Database in use.  Unable to delete until it is closed
Traceback (most recent call last):
  File "C:\Users\rjwal_000\PycharmProjects\Survey Assist\GSIDatabase.py", line 24, in create_db
    os.remove(GSIDatabase.DATABASE_PATH)
PermissionError: [WinError 32] The process cannot access the file because it is being used by another process: 'GSI Files\\GSI_database.db'
2020-04-02 14:10:25,590:Survey Assist:Database in use.  Unable to delete until it is closed
Traceback (most recent call last):
  File "C:\Users\rjwal_000\PycharmProjects\Survey Assist\GSIDatabase.py", line 24, in create_db
    os.remove(GSIDatabase.DATABASE_PATH)
PermissionError: [WinError 32] The process cannot access the file because it is being used by another process: 'GSI Files\\GSI_database.db'
