2020-05-22 15:01:49,518:Survey Assist - v1.0:Started Application

2020-05-22 15:01:53,879:Survey Assist - v1.0:OPENING UP A GSI FILE: C:/Users/Richard/Downloads/890MR 150520.GSI
2020-05-22 15:04:34,728:Survey Assist - v1.0:Started Application

2020-05-22 15:04:39,409:Survey Assist - v1.0:OPENING UP A GSI FILE: C:/Users/Richard/Downloads/890MR 150520.GSI
2020-05-22 15:04:52,040:Survey Assist - v1.0:An unexpected error has occurred

update_station_height()

5
Traceback (most recent call last):
  File "C:/Users/Richard/PycharmProjects/Survey Assist/main.py", line 2607, in change_station_height
    self.subsequent_station_setups[line_number].add(formatted_line['Point_ID'])
KeyError: 5
2020-05-22 15:07:35,580:Survey Assist - v1.0:Started Application

2020-05-22 15:07:39,159:Survey Assist - v1.0:OPENING UP A GSI FILE: C:/Users/Richard/Downloads/890MR 150520.GSI
2020-05-22 15:07:54,311:Survey Assist - v1.0:An unexpected error has occurred

update_station_height()

descriptor 'get' for 'dict' objects doesn't apply to 'str' object
Traceback (most recent call last):
  File "C:/Users/Richard/PycharmProjects/Survey Assist/main.py", line 2650, in change_station_height
    prev_averaged_coordinates = new_stn_coordinates.get(point_id) # retrieve previous average coordinates if they exist
TypeError: descriptor 'get' for 'dict' objects doesn't apply to 'str' object
2020-05-22 15:11:51,381:Survey Assist - v1.0:An unexpected error has occurred

update_station_height()

descriptor 'get' for 'dict' objects doesn't apply to 'str' object
Traceback (most recent call last):
  File "C:/Users/Richard/PycharmProjects/Survey Assist/main.py", line 2650, in change_station_height
    prev_averaged_coordinates = new_stn_coordinates.get(point_id) # retrieve previous average coordinates if they exist
TypeError: descriptor 'get' for 'dict' objects doesn't apply to 'str' object
2020-05-22 15:15:39,686:Survey Assist - v1.0:Started Application

2020-05-22 15:15:44,206:Survey Assist - v1.0:OPENING UP A GSI FILE: C:/Users/Richard/Downloads/890MR 150520.GSI
2020-05-22 15:16:30,552:Survey Assist - v1.0:An unexpected error has occurred

update_station_height()

'STN04'
Traceback (most recent call last):
  File "C:/Users/Richard/PycharmProjects/Survey Assist/main.py", line 2659, in change_station_height
    new_stn_elevation = new_stn_coordinates[station][2]
KeyError: 'STN04'
2020-05-22 15:18:34,381:Survey Assist - v1.0:Started Application

2020-05-22 15:18:40,348:Survey Assist - v1.0:OPENING UP A GSI FILE: C:/Users/Richard/Downloads/890MR 150520.GSI
2020-05-22 15:41:57,180:Survey Assist - v1.0:Started Application

2020-05-22 15:42:01,409:Survey Assist - v1.0:OPENING UP A GSI FILE: C:/Users/Richard/Downloads/890MR 150520.GSI
2020-05-22 16:20:01,240:Survey Assist - v1.0:Started Application

2020-05-22 16:20:06,128:Survey Assist - v1.0:OPENING UP A GSI FILE: C:/Users/Richard/Downloads/890MR 150520.GSI
2020-05-22 16:21:05,489:Survey Assist - v1.0:An unexpected error has occurred

update_station_height()

'STN04'
Traceback (most recent call last):
  File "C:/Users/Richard/PycharmProjects/Survey Assist/main.py", line 2660, in change_station_height
    stn_coordinates = self.new_stn_coordinates[station]
KeyError: 'STN04'
2020-05-22 16:25:37,819:Survey Assist - v1.0:Started Application

2020-05-22 16:25:43,455:Survey Assist - v1.0:OPENING UP A GSI FILE: C:/Users/Richard/Downloads/890MR 150520.GSI
2020-05-22 16:27:19,875:Survey Assist - v1.0:Started Application

2020-05-22 16:27:25,659:Survey Assist - v1.0:OPENING UP A GSI FILE: C:/Users/Richard/Downloads/890MR 150520.GSI
2020-05-22 16:29:13,391:Survey Assist - v1.0:Started Application

2020-05-22 16:29:18,207:Survey Assist - v1.0:OPENING UP A GSI FILE: C:/Users/Richard/Downloads/890MR 150520.GSI
2020-05-22 16:29:25,135:Survey Assist - v1.0:An unexpected error has occurred

update_station_height()

'NoneType' object has no attribute 'group'
Traceback (most recent call last):
  File "C:/Users/Richard/PycharmProjects/Survey Assist/main.py", line 2663, in change_station_height
    gsi.update_station_elevation(line_number, new_stn_elevation)
  File "C:\Users\Richard\PycharmProjects\Survey Assist\GSI.py", line 134, in update_station_elevation
    org_field_value = match.group()
AttributeError: 'NoneType' object has no attribute 'group'
2020-05-22 16:30:04,125:Survey Assist - v1.0:Started Application

2020-05-22 16:30:08,018:Survey Assist - v1.0:OPENING UP A GSI FILE: C:/Users/Richard/Downloads/890MR 150520.GSI
2020-05-22 16:32:31,578:Survey Assist - v1.0:An unexpected error has occurred

update_station_height()

'STN04'
Traceback (most recent call last):
  File "C:/Users/Richard/PycharmProjects/Survey Assist/main.py", line 2660, in change_station_height
    stn_coordinates = self.new_stn_coordinates[station]
KeyError: 'STN04'
2020-05-22 16:34:29,411:Survey Assist - v1.0:Started Application

2020-05-22 16:34:37,393:Survey Assist - v1.0:OPENING UP A GSI FILE: C:/Users/Richard/Downloads/890MR 150520.GSI
2020-05-22 16:35:10,412:Survey Assist - v1.0:An unexpected error has occurred

update_station_height()

'STN04'
Traceback (most recent call last):
  File "C:/Users/Richard/PycharmProjects/Survey Assist/main.py", line 2660, in change_station_height
    stn_coordinates = self.new_stn_coordinates[station]
KeyError: 'STN04'
