2020-04-27 18:46:24,730:Survey Assist:Database in use.  Unable to delete until it is closed
Traceback (most recent call last):
  File "C:\Users\Richard\PycharmProjects\Survey Assist\GSI.py", line 1081, in create_db
    os.remove(GSIDatabase.DATABASE_PATH)
PermissionError: [WinError 32] The process cannot access the file because it is being used by another process: 'GSI Files\\GSI_database.db'
2020-04-27 18:46:46,507:Survey Assist:Database in use.  Unable to delete until it is closed
Traceback (most recent call last):
  File "C:\Users\Richard\PycharmProjects\Survey Assist\GSI.py", line 1081, in create_db
    os.remove(GSIDatabase.DATABASE_PATH)
PermissionError: [WinError 32] The process cannot access the file because it is being used by another process: 'GSI Files\\GSI_database.db'
2020-04-27 18:46:51,566:Survey Assist:Database in use.  Unable to delete until it is closed
Traceback (most recent call last):
  File "C:\Users\Richard\PycharmProjects\Survey Assist\GSI.py", line 1081, in create_db
    os.remove(GSIDatabase.DATABASE_PATH)
PermissionError: [WinError 32] The process cannot access the file because it is being used by another process: 'GSI Files\\GSI_database.db'
2020-04-27 18:47:51,713:Survey Assist:Database in use.  Unable to delete until it is closed
Traceback (most recent call last):
  File "C:\Users\Richard\PycharmProjects\Survey Assist\GSI.py", line 1081, in create_db
    os.remove(GSIDatabase.DATABASE_PATH)
PermissionError: [WinError 32] The process cannot access the file because it is being used by another process: 'GSI Files\\GSI_database.db'
2020-05-02 16:55:57,354:Survey Assist - v1.0:Error creating executing SQL query
Traceback (most recent call last):
  File "C:/Users/rjwal_000/PycharmProjects/Survey Assist/main.py", line 516, in check_3d_survey
    errors, error_points = gsi.check_3D_survey(database.conn)
  File "C:\Users\rjwal_000\PycharmProjects\Survey Assist\GSI.py", line 900, in check_3D_survey
    with conn:
AttributeError: __exit__
2020-05-02 16:57:41,888:Survey Assist - v1.0:Error creating executing SQL query
Traceback (most recent call last):
  File "C:/Users/rjwal_000/PycharmProjects/Survey Assist/main.py", line 516, in check_3d_survey
    errors, error_points = gsi.check_3D_survey(database.conn)
  File "C:\Users\rjwal_000\PycharmProjects\Survey Assist\GSI.py", line 900, in check_3D_survey
    with conn:
AttributeError: __exit__
2020-05-03 11:44:26,345:Survey Assist - v1.0:Error creating executing SQL query
Traceback (most recent call last):
  File "C:/Users/Richard/PycharmProjects/Survey Assist/main.py", line 527, in check_3d_survey
    CustomDialogBox(self.master, error_text)
TypeError: __init__() takes 2 positional arguments but 3 were given
2020-05-03 11:53:50,906:Survey Assist - v1.0:Error creating executing SQL query
Traceback (most recent call last):
  File "C:/Users/Richard/PycharmProjects/Survey Assist/main.py", line 527, in check_3d_survey
    CustomDialogBox(self.master, error_text)
  File "C:\Users\Richard\PycharmProjects\Survey Assist\utilities.py", line 102, in __init__
    self.top = tk.Toplevel(master, "TITLE")
  File "C:\Users\Richard\AppData\Local\Programs\Python\Python37-32\lib\tkinter\__init__.py", line 2342, in __init__
    BaseWidget.__init__(self, master, 'toplevel', cnf, {}, extra)
  File "C:\Users\Richard\AppData\Local\Programs\Python\Python37-32\lib\tkinter\__init__.py", line 2295, in __init__
    classes = [(k, v) for k, v in cnf.items() if isinstance(k, type)]
AttributeError: 'str' object has no attribute 'items'
2020-05-03 12:09:44,807:Survey Assist - v1.0:Error creating executing SQL query
Traceback (most recent call last):
  File "C:/Users/Richard/PycharmProjects/Survey Assist/main.py", line 527, in check_3d_survey
    CustomDialogBox(self.master, error_text)
  File "C:\Users\Richard\PycharmProjects\Survey Assist\utilities.py", line 114, in __init__
    self.scrolled_text.pack(fill='both', expand=True, selectborderwidth=2, padx=2, pady=2)
  File "C:\Users\Richard\AppData\Local\Programs\Python\Python37-32\lib\tkinter\__init__.py", line 2143, in pack_configure
    + self._options(cnf, kw))
_tkinter.TclError: bad option "-selectborderwidth": must be -after, -anchor, -before, -expand, -fill, -in, -ipadx, -ipady, -padx, -pady, or -side
2020-05-03 12:55:34,227:Survey Assist - v1.0:Error creating executing SQL query
Traceback (most recent call last):
  File "C:/Users/Richard/PycharmProjects/Survey Assist/main.py", line 527, in check_3d_survey
    CustomDialogBox(self.master, error_text)
  File "C:\Users\Richard\PycharmProjects\Survey Assist\utilities.py", line 112, in __init__
    editArea.insert(msg)
TypeError: insert() missing 1 required positional argument: 'chars'
2020-05-03 12:56:09,389:Survey Assist - v1.0:Error creating executing SQL query
Traceback (most recent call last):
  File "C:/Users/Richard/PycharmProjects/Survey Assist/main.py", line 527, in check_3d_survey
    CustomDialogBox(self.master, error_text)
  File "C:\Users\Richard\PycharmProjects\Survey Assist\utilities.py", line 112, in __init__
    editArea.insert(0, msg)
  File "C:\Users\Richard\AppData\Local\Programs\Python\Python37-32\lib\tkinter\__init__.py", line 3272, in insert
    self.tk.call((self._w, 'insert', index, chars) + args)
_tkinter.TclError: bad text index "0"
2020-05-03 12:59:19,699:Survey Assist - v1.0:Error creating executing SQL query
Traceback (most recent call last):
  File "C:/Users/Richard/PycharmProjects/Survey Assist/main.py", line 527, in check_3d_survey
    CustomDialogBox(self.master, error_text)
  File "C:\Users\Richard\PycharmProjects\Survey Assist\utilities.py", line 116, in __init__
    frame1.pack(self.top, fill="both", expand=True)
  File "C:\Users\Richard\AppData\Local\Programs\Python\Python37-32\lib\tkinter\__init__.py", line 2143, in pack_configure
    + self._options(cnf, kw))
_tkinter.TclError: bad option "-bd": must be -after, -anchor, -before, -expand, -fill, -in, -ipadx, -ipady, -padx, -pady, or -side
