2020-04-27 18:46:24,730:Survey Assist:Database in use.  Unable to delete until it is closed
Traceback (most recent call last):
  File "C:\Users\Richard\PycharmProjects\Survey Assist\GSI.py", line 1081, in create_db
    os.remove(GSIDatabase.DATABASE_PATH)
PermissionError: [WinError 32] The process cannot access the file because it is being used by another process: 'GSI Files\\GSI_database.db'
2020-04-27 18:46:46,507:Survey Assist:Database in use.  Unable to delete until it is closed
Traceback (most recent call last):
  File "C:\Users\Richard\PycharmProjects\Survey Assist\GSI.py", line 1081, in create_db
    os.remove(GSIDatabase.DATABASE_PATH)
PermissionError: [WinError 32] The process cannot access the file because it is being used by another process: 'GSI Files\\GSI_database.db'
2020-04-27 18:46:51,566:Survey Assist:Database in use.  Unable to delete until it is closed
Traceback (most recent call last):
  File "C:\Users\Richard\PycharmProjects\Survey Assist\GSI.py", line 1081, in create_db
    os.remove(GSIDatabase.DATABASE_PATH)
PermissionError: [WinError 32] The process cannot access the file because it is being used by another process: 'GSI Files\\GSI_database.db'
2020-04-27 18:47:51,713:Survey Assist:Database in use.  Unable to delete until it is closed
Traceback (most recent call last):
  File "C:\Users\Richard\PycharmProjects\Survey Assist\GSI.py", line 1081, in create_db
    os.remove(GSIDatabase.DATABASE_PATH)
PermissionError: [WinError 32] The process cannot access the file because it is being used by another process: 'GSI Files\\GSI_database.db'
