2020-05-29 10:22:30,006:Survey Assist - v1.0:Started Application

2020-05-29 10:22:40,656:Survey Assist - v1.0:OPENING UP A GSI FILE: C:/Users/rjwal_000/PycharmProjects/Survey Assist/Test Files/GSI Files/2D Survey MR050819.GSI
2020-05-29 10:25:17,609:Survey Assist - v1.0:Started Application

2020-05-29 10:25:22,766:Survey Assist - v1.0:OPENING UP A GSI FILE: C:/Users/rjwal_000/PycharmProjects/Survey Assist/Test Files/GSI Files/2D Survey MR050819.GSI
2020-05-29 10:25:48,666:Survey Assist - v1.0:Started Application

2020-05-29 10:25:52,891:Survey Assist - v1.0:OPENING UP A GSI FILE: C:/Users/rjwal_000/PycharmProjects/Survey Assist/Test Files/GSI Files/2D Survey MR050819.GSI
2020-05-29 10:26:37,626:Survey Assist - v1.0:OPENING UP A GSI FILE: C:/Users/rjwal_000/PycharmProjects/Survey Assist/Test Files/GSI Files/2D Survey MR050819_PCUpdated.gsi
2020-05-29 10:29:26,294:Survey Assist - v1.0:Started Application

2020-05-29 10:29:31,919:Survey Assist - v1.0:Started Application

2020-05-29 10:29:39,110:Survey Assist - v1.0:OPENING UP A GSI FILE: C:/Users/rjwal_000/PycharmProjects/Survey Assist/Test Files/GSI Files/2D Survey MR050819_PCUpdated.gsi
2020-05-29 10:35:56,256:Survey Assist - v1.0:Started Application

2020-05-29 10:36:00,969:Survey Assist - v1.0:OPENING UP A GSI FILE: C:/Users/rjwal_000/PycharmProjects/Survey Assist/Test Files/GSI Files/2D Survey MR050819_PCUpdated.gsi
2020-05-29 10:36:07,813:Survey Assist - v1.0:OPENING UP A GSI FILE: C:/Users/rjwal_000/PycharmProjects/Survey Assist/Test Files/GSI Files/2D Survey MR050819_PCUpdated.gsi
2020-05-29 10:39:13,554:Survey Assist - v1.0:Started Application

2020-05-29 10:39:18,156:Survey Assist - v1.0:OPENING UP A GSI FILE: C:/Users/rjwal_000/PycharmProjects/Survey Assist/Test Files/GSI Files/2D Survey MR050819_PCUpdated.gsi
2020-05-29 10:40:25,465:Survey Assist - v1.0:Started Application

2020-05-29 10:40:30,797:Survey Assist - v1.0:OPENING UP A GSI FILE: C:/Users/rjwal_000/PycharmProjects/Survey Assist/Test Files/GSI Files/2D Survey MR050819_PCUpdated.gsi
2020-05-29 10:41:40,730:Survey Assist - v1.0:Started Application

2020-05-29 10:41:45,203:Survey Assist - v1.0:OPENING UP A GSI FILE: C:/Users/rjwal_000/PycharmProjects/Survey Assist/Test Files/GSI Files/2D Survey MR050819_PCUpdated.gsi
2020-05-29 10:42:08,649:Survey Assist - v1.0:Started Application

2020-05-29 10:42:12,297:Survey Assist - v1.0:OPENING UP A GSI FILE: C:/Users/rjwal_000/PycharmProjects/Survey Assist/Test Files/GSI Files/2D Survey MR050819_PCUpdated.gsi
2020-05-29 10:42:49,360:Survey Assist - v1.0:OPENING UP A GSI FILE: C:/Users/rjwal_000/PycharmProjects/Survey Assist/Test Files/GSI Files/2D Survey MR050819.GSI
2020-05-29 10:42:59,265:Survey Assist - v1.0:OPENING UP A GSI FILE: C:/Users/rjwal_000/PycharmProjects/Survey Assist/Test Files/GSI Files/3D MR_120819_3D error change.gsi
2020-05-29 10:43:12,844:Survey Assist - v1.0:OPENING UP A GSI FILE: C:/Users/rjwal_000/PycharmProjects/Survey Assist/Test Files/GSI Files/MR140519.GSI
2020-05-29 10:44:17,274:Survey Assist - v1.0:Started Application

2020-05-29 10:44:21,688:Survey Assist - v1.0:OPENING UP A GSI FILE: C:/Users/rjwal_000/PycharmProjects/Survey Assist/Test Files/GSI Files/MR140519.GSI
2020-05-29 10:45:56,909:Survey Assist - v1.0:Started Application

2020-05-29 10:46:45,889:Survey Assist - v1.0:Started Application

2020-05-29 10:47:06,844:Survey Assist - v1.0:OPENING UP A GSI FILE: C:/Users/rjwal_000/PycharmProjects/Survey Assist/Test Files/GSI Files/HCCL 030719.GSI
2020-05-29 10:47:55,502:Survey Assist - v1.0:Started Application

2020-05-29 10:47:59,828:Survey Assist - v1.0:OPENING UP A GSI FILE: C:/Users/rjwal_000/PycharmProjects/Survey Assist/Test Files/GSI Files/HCCL 030719.GSI
2020-05-29 10:48:24,353:Survey Assist - v1.0:Started Application

2020-05-29 10:48:28,469:Survey Assist - v1.0:OPENING UP A GSI FILE: C:/Users/rjwal_000/PycharmProjects/Survey Assist/Test Files/GSI Files/HCCL 030719.GSI
2020-05-29 10:49:15,640:Survey Assist - v1.0:OPENING UP A GSI FILE: C:/Users/rjwal_000/PycharmProjects/Survey Assist/Test Files/GSI Files/ARTC_903_compnet 240220.GSI
2020-05-29 10:50:09,188:Survey Assist - v1.0:OPENING UP A GSI FILE: C:/Users/rjwal_000/PycharmProjects/Survey Assist/Test Files/GSI Files/3D MR_120819_3D error change.gsi
2020-05-29 10:50:58,378:Survey Assist - v1.0:Started Application

2020-05-29 10:51:04,016:Survey Assist - v1.0:OPENING UP A GSI FILE: C:/Users/rjwal_000/PycharmProjects/Survey Assist/Test Files/GSI Files/3D MR_120819_3D error change.gsi
2020-05-29 10:51:10,079:Survey Assist - v1.0:OPENING UP A GSI FILE: C:/Users/rjwal_000/Downloads/890MR 150520_EDITED_STNUpdated_TgtUpdated.gsi
2020-05-29 11:30:28,368:Survey Assist - v1.0:Started Application

2020-05-29 11:30:39,396:Survey Assist - v1.0:OPENING UP A GSI FILE: C:/Users/Richard/Downloads/ARTC_903_MON_V2_TS15_200420_combine.GSI
2020-05-29 14:09:06,662:Survey Assist - v1.0:Started Application

2020-05-29 14:11:56,447:Survey Assist - v1.0:Started Application

2020-06-01 17:13:16,243:Survey Assist - v1.0:Started Application

2020-06-01 17:17:25,824:Survey Assist - v1.0:Started Application

2020-06-01 17:19:27,159:Survey Assist - v1.0:Started Application

2020-06-01 17:19:49,609:Survey Assist - v1.0:OPENING UP A GSI FILE: C:/Users/Richard/PycharmProjects/Survey Assist/Test Files/GSI Files/2D Survey MR050819.GSI
2020-06-01 17:23:27,826:Survey Assist - v1.0:Started Application

2020-06-01 17:33:35,885:Survey Assist - v1.0:Started Application

2020-06-02 16:46:46,706:Survey Assist - v1.0:Started Application

2020-06-02 16:48:08,379:Survey Assist - v1.0:Started Application

2020-06-02 16:49:40,309:Survey Assist - v1.0:Started Application

2020-06-07 08:45:13,903:Survey Assist - v1.0:Started Application

2020-06-07 08:45:39,856:Survey Assist - v1.0:OPENING UP A GSI FILE: C:/Users/rjwal_000/PycharmProjects/Survey Assist/Test Files/GSI Files/3D MR_120819_3D error change.gsi
2020-06-11 08:54:04,190:Survey Assist - v1.0:Started Application

2020-06-11 08:55:29,511:Survey Assist - v1.0:Started Application

2020-06-11 09:01:26,872:Survey Assist - v1.0:Started Application

2020-06-11 09:04:13,834:Survey Assist - v1.0:Started Application

2020-06-11 09:05:13,110:Survey Assist - v1.0:Started Application

2020-06-11 09:05:38,208:Survey Assist - v1.0:Started Application

2020-06-11 09:06:52,494:Survey Assist - v1.0:Started Application

2020-06-11 09:10:11,072:Survey Assist - v1.0:Started Application

2020-06-11 09:12:18,064:Survey Assist - v1.0:Started Application

2020-06-11 09:12:23,664:Survey Assist - v1.0:OPENING UP A GSI FILE: C:/Users/rjwal_000/Downloads/MR200620_EDIT.GSI
2020-06-11 09:17:04,994:Survey Assist - v1.0:Started Application

2020-06-11 09:17:11,711:Survey Assist - v1.0:OPENING UP A GSI FILE: C:/Users/rjwal_000/Downloads/MR200620_EDIT.GSI
2020-06-11 09:19:47,415:Survey Assist - v1.0:Started Application

2020-06-11 09:19:53,867:Survey Assist - v1.0:OPENING UP A GSI FILE: C:/Users/rjwal_000/Downloads/MR200620_EDIT.GSI
2020-06-11 09:20:52,595:Survey Assist - v1.0:Started Application

2020-06-11 09:20:58,070:Survey Assist - v1.0:OPENING UP A GSI FILE: C:/Users/rjwal_000/Downloads/MR200620_EDIT.GSI
2020-06-11 09:23:49,662:Survey Assist - v1.0:Started Application

2020-06-11 09:34:56,891:Survey Assist - v1.0:Started Application

2020-06-11 09:35:13,257:Survey Assist - v1.0:OPENING UP A GSI FILE: C:/Users/rjwal_000/Downloads/MR200620_EDIT.GSI
2020-06-11 09:35:52,653:Survey Assist - v1.0:Started Application

2020-06-11 09:40:51,660:Survey Assist - v1.0:Started Application

2020-06-11 09:41:13,062:Survey Assist - v1.0:Started Application

2020-06-11 09:41:21,109:Survey Assist - v1.0:Started Application

2020-06-11 09:44:40,185:Survey Assist - v1.0:Started Application

2020-06-11 09:45:00,041:Survey Assist - v1.0:Started Application

2020-06-11 09:45:46,167:Survey Assist - v1.0:Started Application

2020-06-11 09:47:02,573:Survey Assist - v1.0:Started Application

2020-06-11 09:47:15,707:Survey Assist - v1.0:Started Application

2020-06-11 09:48:27,089:Survey Assist - v1.0:Started Application

2020-06-11 09:59:44,392:Survey Assist - v1.0:Started Application

2020-06-11 10:00:32,600:Survey Assist - v1.0:Started Application

2020-06-11 10:02:38,708:Survey Assist - v1.0:Started Application

2020-06-11 11:46:42,107:Survey Assist - v1.0:Started Application

2020-06-11 11:48:18,490:Survey Assist - v1.0:Started Application

2020-06-11 11:49:38,957:Survey Assist - v1.0:Started Application

2020-06-11 11:50:28,825:Survey Assist - v1.0:Started Application

2020-06-11 11:58:50,305:Survey Assist - v1.0:Started Application

2020-06-11 11:59:35,948:Survey Assist - v1.0:Started Application

2020-06-11 11:59:49,918:Survey Assist - v1.0:Started Application

2020-06-11 12:00:10,492:Survey Assist - v1.0:OPENING UP A GSI FILE: C:/Users/rjwal_000/Downloads/MR200620_EDIT.GSI
2020-06-11 12:00:22,889:Survey Assist - v1.0:Started Application

2020-06-11 12:00:57,820:Survey Assist - v1.0:OPENING UP A GSI FILE: C:/Users/rjwal_000/Downloads/MR200620_EDIT.GSI
2020-06-11 12:01:24,695:Survey Assist - v1.0:OPENING UP A GSI FILE: C:/Users/rjwal_000/PycharmProjects/Survey Assist/Test Files/GSI Files/HCCL 030719.GSI
2020-06-11 12:02:34,327:Survey Assist - v1.0:Started Application

2020-06-11 12:03:19,257:Survey Assist - v1.0:Started Application

2020-06-11 12:03:45,133:Survey Assist - v1.0:OPENING UP A GSI FILE: C:/Users/rjwal_000/PycharmProjects/Survey Assist/Test Files/GSI Files/HCCL 030719.GSI
2020-06-11 12:04:56,463:Survey Assist - v1.0:Started Application

2020-06-11 12:05:28,959:Survey Assist - v1.0:Started Application

2020-06-11 12:05:38,596:Survey Assist - v1.0:Started Application

2020-06-11 12:05:50,492:Survey Assist - v1.0:OPENING UP A GSI FILE: C:/Users/rjwal_000/Downloads/MR200620_EDIT.GSI
2020-06-11 12:08:36,129:Survey Assist - v1.0:Started Application

2020-06-11 12:08:47,627:Survey Assist - v1.0:Started Application

2020-06-11 12:10:15,862:Survey Assist - v1.0:Started Application

2020-06-11 12:10:33,783:Survey Assist - v1.0:Started Application

2020-06-11 12:10:39,161:Survey Assist - v1.0:Started Application

2020-06-11 12:12:00,641:Survey Assist - v1.0:Started Application

2020-06-11 12:14:52,214:Survey Assist - v1.0:Started Application

2020-06-11 12:15:34,261:Survey Assist - v1.0:Started Application

2020-06-11 12:15:56,865:Survey Assist - v1.0:Started Application

2020-06-11 12:16:59,398:Survey Assist - v1.0:Started Application

2020-06-11 12:18:06,996:Survey Assist - v1.0:Started Application

2020-06-11 12:18:23,845:Survey Assist - v1.0:Started Application

2020-06-11 12:18:44,768:Survey Assist - v1.0:Started Application

2020-06-11 12:22:12,490:Survey Assist - v1.0:Started Application

2020-06-11 12:24:26,223:Survey Assist - v1.0:Started Application

2020-06-11 12:24:55,647:Survey Assist - v1.0:Started Application

2020-06-11 12:25:04,115:Survey Assist - v1.0:Started Application

2020-06-11 12:25:20,959:Survey Assist - v1.0:Started Application

2020-06-11 12:25:55,255:Survey Assist - v1.0:Started Application

2020-06-11 12:26:14,439:Survey Assist - v1.0:Started Application

2020-06-11 12:26:40,806:Survey Assist - v1.0:Started Application

2020-06-11 12:26:51,351:Survey Assist - v1.0:Started Application

2020-06-11 12:27:07,245:Survey Assist - v1.0:Started Application

2020-06-11 12:31:57,958:Survey Assist - v1.0:Started Application

2020-06-11 12:32:58,703:Survey Assist - v1.0:Started Application

2020-06-11 12:35:17,598:Survey Assist - v1.0:Started Application

2020-06-11 12:35:45,156:Survey Assist - v1.0:Started Application

2020-06-11 12:36:04,871:Survey Assist - v1.0:Started Application

2020-06-11 12:36:27,561:Survey Assist - v1.0:Started Application

2020-06-11 12:39:03,115:Survey Assist - v1.0:Started Application

2020-06-11 12:44:48,353:Survey Assist - v1.0:Started Application

2020-06-11 12:45:06,352:Survey Assist - v1.0:OPENING UP A GSI FILE: C:/Users/rjwal_000/Downloads/MR200620_EDIT.GSI
2020-06-11 12:47:50,523:Survey Assist - v1.0:Started Application

2020-06-11 13:29:28,202:Survey Assist - v1.0:Started Application

2020-06-11 13:31:17,840:Survey Assist - v1.0:Started Application

2020-06-11 13:31:35,861:Survey Assist - v1.0:Started Application

2020-06-11 13:38:44,096:Survey Assist - v1.0:Started Application

2020-06-11 13:39:37,137:Survey Assist - v1.0:Started Application

2020-06-11 13:39:54,835:Survey Assist - v1.0:Started Application

2020-06-11 13:40:30,918:Survey Assist - v1.0:Started Application

2020-06-11 13:43:57,111:Survey Assist - v1.0:Started Application

2020-06-11 13:44:16,850:Survey Assist - v1.0:Started Application

2020-06-11 13:45:08,068:Survey Assist - v1.0:Started Application

2020-06-11 13:45:38,760:Survey Assist - v1.0:Started Application

2020-06-11 13:48:36,295:Survey Assist - v1.0:Started Application

2020-06-11 13:52:55,677:Survey Assist - v1.0:Started Application

2020-06-11 13:53:33,475:Survey Assist - v1.0:Started Application

2020-06-11 13:54:59,411:Survey Assist - v1.0:Started Application

2020-06-11 13:57:14,747:Survey Assist - v1.0:Started Application

2020-06-11 13:58:47,016:Survey Assist - v1.0:Started Application

2020-06-11 13:58:57,469:Survey Assist - v1.0:Started Application

2020-06-11 13:59:02,907:Survey Assist - v1.0:OPENING UP A GSI FILE: C:/Users/rjwal_000/PycharmProjects/Survey Assist/Test Files/GSI Files/HCCL 030719.GSI
2020-06-11 14:01:06,648:Survey Assist - v1.0:Started Application

2020-06-11 14:05:35,005:Survey Assist - v1.0:Started Application

2020-06-11 14:06:31,542:Survey Assist - v1.0:Started Application

2020-06-11 14:07:50,640:Survey Assist - v1.0:Started Application

2020-06-11 14:08:10,845:Survey Assist - v1.0:Started Application

2020-06-11 14:21:39,098:Survey Assist - v1.0:Started Application

2020-06-11 14:22:29,516:Survey Assist - v1.0:Started Application

2020-06-11 14:23:19,870:Survey Assist - v1.0:Started Application

2020-06-11 16:04:54,014:Survey Assist - v1.0:Started Application

2020-06-11 16:05:22,010:Survey Assist - v1.0:Started Application

2020-06-11 16:05:26,535:Survey Assist - v1.0:Started Application

2020-06-11 16:06:16,759:Survey Assist - v1.0:Started Application

2020-06-11 16:08:13,882:Survey Assist - v1.0:Started Application

2020-06-11 16:37:48,274:Survey Assist - v1.0:Started Application

2020-06-11 16:41:52,681:Survey Assist - v1.0:Started Application

2020-06-11 16:42:17,916:Survey Assist - v1.0:Started Application

2020-06-11 16:46:46,831:Survey Assist - v1.0:Started Application

2020-06-11 16:53:18,765:Survey Assist - v1.0:Started Application

2020-06-11 16:53:59,297:Survey Assist - v1.0:Started Application

2020-06-11 16:55:50,213:Survey Assist - v1.0:Started Application

2020-06-11 16:57:10,400:Survey Assist - v1.0:Started Application

2020-06-11 16:57:20,727:Survey Assist - v1.0:Started Application

2020-06-11 17:00:53,574:Survey Assist - v1.0:Started Application

2020-06-11 17:01:47,705:Survey Assist - v1.0:Started Application

2020-06-12 09:16:10,538:Survey Assist - v1.0:Started Application

2020-06-12 09:28:21,922:Survey Assist - v1.0:Started Application

2020-06-12 09:28:50,853:Survey Assist - v1.0:Started Application

2020-06-12 09:29:09,124:Survey Assist - v1.0:Started Application

2020-06-12 09:58:52,723:Survey Assist - v1.0:Started Application

2020-06-12 09:58:52,743:Survey Assist - v1.0:Error has occurred in JobTracker init().

[Errno 2] No such file or directory: 'C:\\Users\\rjwal_000\\PycharmProjects\\Survey Assist\\Test Files\\Survey Data\\2020\\Job Tracker Digital System.xlsm'
Traceback (most recent call last):
  File "C:\Users\rjwal_000\PycharmProjects\Survey Assist\job_tracker.py", line 19, in __init__
    self.workbook = load_workbook(self.job_tracker_filepath, read_only=True)
  File "C:\Python34\lib\site-packages\openpyxl\reader\excel.py", line 147, in load_workbook
    archive = _validate_archive(filename)
  File "C:\Python34\lib\site-packages\openpyxl\reader\excel.py", line 97, in _validate_archive
    archive = ZipFile(filename, 'r')
  File "C:\Python34\lib\zipfile.py", line 923, in __init__
    self.fp = io.open(file, modeDict[mode])
FileNotFoundError: [Errno 2] No such file or directory: 'C:\\Users\\rjwal_000\\PycharmProjects\\Survey Assist\\Test Files\\Survey Data\\2020\\Job Tracker Digital System.xlsm'
2020-06-12 10:03:23,450:Survey Assist - v1.0:Started Application

2020-06-12 10:03:23,488:Survey Assist - v1.0:Job Tracker excel spreadsheet not found

[Errno 2] No such file or directory: 'C:\\Users\\rjwal_000\\PycharmProjects\\Survey Assist\\Test Files\\Survey Data\\2020\\Job Tracker Digital System.xlsm'
Traceback (most recent call last):
  File "C:\Users\rjwal_000\PycharmProjects\Survey Assist\job_tracker.py", line 19, in __init__
    self.workbook = load_workbook(self.job_tracker_filepath, read_only=True)
  File "C:\Python34\lib\site-packages\openpyxl\reader\excel.py", line 147, in load_workbook
    archive = _validate_archive(filename)
  File "C:\Python34\lib\site-packages\openpyxl\reader\excel.py", line 97, in _validate_archive
    archive = ZipFile(filename, 'r')
  File "C:\Python34\lib\zipfile.py", line 923, in __init__
    self.fp = io.open(file, modeDict[mode])
FileNotFoundError: [Errno 2] No such file or directory: 'C:\\Users\\rjwal_000\\PycharmProjects\\Survey Assist\\Test Files\\Survey Data\\2020\\Job Tracker Digital System.xlsm'
2020-06-12 10:03:37,191:Survey Assist - v1.0:An unexpected error has occurred

btn_job_tracker()

[WinError 2] The system cannot find the file specified: 'C:\\Users\\rjwal_000\\PycharmProjects\\Survey Assist\\Test Files\\Survey Data\\2020\\Job Tracker Digital System.xlsm'
Traceback (most recent call last):
  File "C:/Users/rjwal_000/PycharmProjects/Survey Assist/main.py", line 1565, in job_tracker_open_excel
    os.startfile(self.job_tracker_filepath)
FileNotFoundError: [WinError 2] The system cannot find the file specified: 'C:\\Users\\rjwal_000\\PycharmProjects\\Survey Assist\\Test Files\\Survey Data\\2020\\Job Tracker Digital System.xlsm'
2020-06-12 10:03:53,109:Survey Assist - v1.0:Started Application

2020-06-12 10:15:35,479:Survey Assist - v1.0:Started Application

2020-06-12 10:15:58,998:Survey Assist - v1.0:Started Application

2020-06-12 10:16:22,212:Survey Assist - v1.0:Started Application

2020-06-12 10:16:39,856:Survey Assist - v1.0:Started Application

2020-06-12 10:16:58,574:Survey Assist - v1.0:Started Application

2020-06-12 10:20:00,475:Survey Assist - v1.0:Started Application

2020-06-12 10:22:08,054:Survey Assist - v1.0:Started Application

2020-06-12 10:23:10,044:Survey Assist - v1.0:Started Application

2020-06-12 10:30:42,558:Survey Assist - v1.0:Started Application

2020-06-12 10:32:44,562:Survey Assist - v1.0:Started Application

2020-06-12 10:35:37,358:Survey Assist - v1.0:Started Application

2020-06-12 10:35:37,392:Survey Assist - v1.0:Error has occurred in JobTracker init().

tuple index out of range
Traceback (most recent call last):
  File "C:\Users\rjwal_000\PycharmProjects\Survey Assist\job_tracker.py", line 21, in __init__
    self.create_list_of_job_tracker_jobs()
  File "C:\Users\rjwal_000\PycharmProjects\Survey Assist\job_tracker.py", line 42, in create_list_of_job_tracker_jobs
    survey_job = SurveyJob(row[0].value, row[1].value, row[2].value, row[3].value, row[4].value)
IndexError: tuple index out of range
2020-06-12 10:36:55,202:Survey Assist - v1.0:Started Application

2020-06-12 10:36:55,233:Survey Assist - v1.0:Error has occurred in JobTracker init().

tuple index out of range
Traceback (most recent call last):
  File "C:\Users\rjwal_000\PycharmProjects\Survey Assist\job_tracker.py", line 21, in __init__
    self.create_list_of_job_tracker_jobs()
  File "C:\Users\rjwal_000\PycharmProjects\Survey Assist\job_tracker.py", line 42, in create_list_of_job_tracker_jobs
    survey_job = SurveyJob(row[0].value, row[1].value, row[2].value, row[3].value, row[4].value)
IndexError: tuple index out of range
2020-06-12 10:37:53,521:Survey Assist - v1.0:Started Application

2020-06-12 10:41:23,536:Survey Assist - v1.0:Started Application

2020-06-12 10:41:23,575:Survey Assist - v1.0:Error has occurred in JobTracker init().

'datetime.datetime' object has no attribute 'split'
Traceback (most recent call last):
  File "C:\Users\rjwal_000\PycharmProjects\Survey Assist\job_tracker.py", line 21, in __init__
    self.create_list_of_job_tracker_jobs()
  File "C:\Users\rjwal_000\PycharmProjects\Survey Assist\job_tracker.py", line 44, in create_list_of_job_tracker_jobs
    survey_job = SurveyJob(row[0].value, row[1].value.split[0], row[2].value, row[3].value, row[4].value)
AttributeError: 'datetime.datetime' object has no attribute 'split'
2020-06-12 10:42:31,864:Survey Assist - v1.0:Started Application

2020-06-12 10:42:31,897:Survey Assist - v1.0:Error has occurred in JobTracker init().

'builtin_function_or_method' object is not subscriptable
Traceback (most recent call last):
  File "C:\Users\rjwal_000\PycharmProjects\Survey Assist\job_tracker.py", line 21, in __init__
    self.create_list_of_job_tracker_jobs()
  File "C:\Users\rjwal_000\PycharmProjects\Survey Assist\job_tracker.py", line 44, in create_list_of_job_tracker_jobs
    survey_job = SurveyJob(row[0].value, str(row[1].value).split[0], row[2].value, row[3].value, row[4].value)
TypeError: 'builtin_function_or_method' object is not subscriptable
2020-06-12 10:43:24,806:Survey Assist - v1.0:Started Application

2020-06-12 10:44:56,935:Survey Assist - v1.0:Started Application

2020-06-12 10:44:56,973:Survey Assist - v1.0:Error has occurred in JobTracker init().

'datetime.datetime' object has no attribute 'ToString'
Traceback (most recent call last):
  File "C:\Users\rjwal_000\PycharmProjects\Survey Assist\job_tracker.py", line 21, in __init__
    self.create_list_of_job_tracker_jobs()
  File "C:\Users\rjwal_000\PycharmProjects\Survey Assist\job_tracker.py", line 43, in create_list_of_job_tracker_jobs
    print(date.ToString("dd/MM/yyyy"))
AttributeError: 'datetime.datetime' object has no attribute 'ToString'
2020-06-12 10:45:46,384:Survey Assist - v1.0:Started Application

2020-06-12 10:45:46,414:Survey Assist - v1.0:Error has occurred in JobTracker init().

'datetime.datetime' object has no attribute 'ToString'
Traceback (most recent call last):
  File "C:\Users\rjwal_000\PycharmProjects\Survey Assist\job_tracker.py", line 21, in __init__
    self.create_list_of_job_tracker_jobs()
  File "C:\Users\rjwal_000\PycharmProjects\Survey Assist\job_tracker.py", line 43, in create_list_of_job_tracker_jobs
    print(date.ToString("dd'/'MM'/'yyyy"))
AttributeError: 'datetime.datetime' object has no attribute 'ToString'
2020-06-12 10:49:24,744:Survey Assist - v1.0:Started Application

2020-06-12 10:49:50,105:Survey Assist - v1.0:Started Application

2020-06-12 10:54:22,021:Survey Assist - v1.0:Started Application

2020-06-12 10:54:45,980:Survey Assist - v1.0:Started Application

2020-06-12 10:55:19,505:Survey Assist - v1.0:Started Application

2020-06-12 10:56:33,798:Survey Assist - v1.0:Started Application

2020-06-12 11:03:34,377:Survey Assist - v1.0:Started Application

2020-06-12 11:03:51,997:Survey Assist - v1.0:Started Application

2020-06-12 11:05:44,064:Survey Assist - v1.0:Started Application

2020-06-12 11:09:40,153:Survey Assist - v1.0:Started Application

2020-06-12 11:11:26,897:Survey Assist - v1.0:Started Application

2020-06-12 11:11:37,814:Survey Assist - v1.0:Started Application

2020-06-12 11:12:21,222:Survey Assist - v1.0:Started Application

2020-06-12 11:14:20,823:Survey Assist - v1.0:Started Application

2020-06-12 11:14:31,100:Survey Assist - v1.0:Started Application

2020-06-12 11:14:53,226:Survey Assist - v1.0:Started Application

2020-06-12 11:16:39,378:Survey Assist - v1.0:Started Application

2020-06-12 11:19:25,425:Survey Assist - v1.0:Started Application

2020-06-12 11:20:36,479:Survey Assist - v1.0:Started Application

2020-06-12 11:21:37,050:Survey Assist - v1.0:Started Application

2020-06-12 11:22:55,342:Survey Assist - v1.0:Started Application

2020-06-12 11:23:15,454:Survey Assist - v1.0:Started Application

2020-06-12 11:23:31,834:Survey Assist - v1.0:Started Application

2020-06-12 11:26:39,310:Survey Assist - v1.0:Started Application

2020-06-12 11:27:15,727:Survey Assist - v1.0:Started Application

2020-06-12 11:27:27,561:Survey Assist - v1.0:Started Application

2020-06-12 11:27:37,522:Survey Assist - v1.0:Started Application

2020-06-12 11:28:34,615:Survey Assist - v1.0:Started Application

2020-06-12 11:28:54,645:Survey Assist - v1.0:Started Application

2020-06-12 11:29:31,584:Survey Assist - v1.0:Started Application

2020-06-12 11:29:58,188:Survey Assist - v1.0:Started Application

2020-06-12 11:30:14,950:Survey Assist - v1.0:Started Application

2020-06-12 11:30:43,165:Survey Assist - v1.0:Started Application

2020-06-12 11:31:02,550:Survey Assist - v1.0:Started Application

2020-06-12 11:31:29,411:Survey Assist - v1.0:Started Application

2020-06-12 11:33:15,168:Survey Assist - v1.0:Started Application

2020-06-12 11:33:56,442:Survey Assist - v1.0:Started Application

2020-06-12 11:35:31,875:Survey Assist - v1.0:Started Application

2020-06-12 11:36:05,350:Survey Assist - v1.0:Started Application

2020-06-12 11:36:58,631:Survey Assist - v1.0:Started Application

2020-06-12 11:54:49,185:Survey Assist - v1.0:Started Application

2020-06-12 11:55:19,921:Survey Assist - v1.0:Started Application

2020-06-12 11:56:29,058:Survey Assist - v1.0:Started Application

2020-06-12 11:58:42,837:Survey Assist - v1.0:Started Application

2020-06-12 11:58:54,971:Survey Assist - v1.0:Job Tracker excel spreadsheet currently in use

[Errno 13] Permission denied: 'C:\\Users\\rjwal_000\\PycharmProjects\\Survey Assist\\Test Files\\Survey Data\\2020\\Job Tracker Digital System.xlsm'
Traceback (most recent call last):
  File "C:/Users/rjwal_000/PycharmProjects/Survey Assist/main.py", line 2145, in save_job_to_excel
    workbook.save(filename=self.job_tracker_filepath)
  File "C:\Python34\lib\site-packages\openpyxl\workbook\workbook.py", line 391, in save
    save_workbook(self, filename)
  File "C:\Python34\lib\site-packages\openpyxl\writer\excel.py", line 282, in save_workbook
    archive = ZipFile(filename, 'w', ZIP_DEFLATED, allowZip64=True)
  File "C:\Python34\lib\zipfile.py", line 923, in __init__
    self.fp = io.open(file, modeDict[mode])
PermissionError: [Errno 13] Permission denied: 'C:\\Users\\rjwal_000\\PycharmProjects\\Survey Assist\\Test Files\\Survey Data\\2020\\Job Tracker Digital System.xlsm'
2020-06-12 12:00:28,707:Survey Assist - v1.0:Started Application

2020-06-12 12:00:30,717:Survey Assist - v1.0:Job Tracker excel spreadsheet currently in use

[Errno 13] Permission denied: 'C:\\Users\\rjwal_000\\PycharmProjects\\Survey Assist\\Test Files\\Survey Data\\2020\\Job Tracker Digital System.xlsm'
Traceback (most recent call last):
  File "C:/Users/rjwal_000/PycharmProjects/Survey Assist/main.py", line 2145, in save_job_to_excel
    workbook.save(filename=self.job_tracker_filepath)
  File "C:\Python34\lib\site-packages\openpyxl\workbook\workbook.py", line 391, in save
    save_workbook(self, filename)
  File "C:\Python34\lib\site-packages\openpyxl\writer\excel.py", line 282, in save_workbook
    archive = ZipFile(filename, 'w', ZIP_DEFLATED, allowZip64=True)
  File "C:\Python34\lib\zipfile.py", line 923, in __init__
    self.fp = io.open(file, modeDict[mode])
PermissionError: [Errno 13] Permission denied: 'C:\\Users\\rjwal_000\\PycharmProjects\\Survey Assist\\Test Files\\Survey Data\\2020\\Job Tracker Digital System.xlsm'
2020-06-12 12:04:52,588:Survey Assist - v1.0:Started Application

2020-06-12 12:04:57,116:Survey Assist - v1.0:Job Tracker excel spreadsheet currently in use

[Errno 13] Permission denied: 'C:\\Users\\rjwal_000\\PycharmProjects\\Survey Assist\\Test Files\\Survey Data\\2020\\Job Tracker Digital System.xlsm'
Traceback (most recent call last):
  File "C:/Users/rjwal_000/PycharmProjects/Survey Assist/main.py", line 2145, in save_job_to_excel
    workbook.save(filename=self.job_tracker_filepath)
  File "C:\Python34\lib\site-packages\openpyxl\workbook\workbook.py", line 391, in save
    save_workbook(self, filename)
  File "C:\Python34\lib\site-packages\openpyxl\writer\excel.py", line 282, in save_workbook
    archive = ZipFile(filename, 'w', ZIP_DEFLATED, allowZip64=True)
  File "C:\Python34\lib\zipfile.py", line 923, in __init__
    self.fp = io.open(file, modeDict[mode])
PermissionError: [Errno 13] Permission denied: 'C:\\Users\\rjwal_000\\PycharmProjects\\Survey Assist\\Test Files\\Survey Data\\2020\\Job Tracker Digital System.xlsm'
2020-06-12 12:14:28,472:Survey Assist - v1.0:Started Application

2020-06-12 12:15:10,409:Survey Assist - v1.0:Started Application

2020-06-12 12:18:31,049:Survey Assist - v1.0:Started Application

2020-06-12 12:19:44,060:Survey Assist - v1.0:Started Application

2020-06-12 12:19:53,051:Survey Assist - v1.0:Error has occurred in JobTracker init().

invalid literal for int() with base 10: ''
Traceback (most recent call last):
  File "C:/Users/rjwal_000/PycharmProjects/Survey Assist/main.py", line 2142, in save_job_to_excel
    actions_sheet["D11"] = self.calcs_checkbox_var.get()
  File "C:\Python34\lib\tkinter\__init__.py", line 358, in get
    return getint(self._tk.globalgetvar(self._name))
ValueError: invalid literal for int() with base 10: ''
2020-06-12 12:21:36,921:Survey Assist - v1.0:Started Application

2020-06-12 12:21:43,348:Survey Assist - v1.0:Error has occurred in JobTracker init().

get() missing 1 required positional argument: 'self'
Traceback (most recent call last):
  File "C:/Users/rjwal_000/PycharmProjects/Survey Assist/main.py", line 2143, in save_job_to_excel
    actions_sheet["E11"] = self.results_checkbox_var.get()
TypeError: get() missing 1 required positional argument: 'self'
2020-06-12 12:22:31,771:Survey Assist - v1.0:Started Application

2020-06-12 12:48:56,067:Survey Assist - v1.0:Started Application

2020-06-12 12:48:57,248:Survey Assist - v1.0:Job Tracker excel spreadsheet not found

[Errno 2] No such file or directory: '/dst/test_copy.txt'
Traceback (most recent call last):
  File "C:/Users/rjwal_000/PycharmProjects/Survey Assist/main.py", line 2136, in save_job_to_excel
    shutil.copy2(self.job_tracker_filepath, '/dst/test_copy.txt')
  File "C:\Python34\lib\shutil.py", line 245, in copy2
    copyfile(src, dst, follow_symlinks=follow_symlinks)
  File "C:\Python34\lib\shutil.py", line 109, in copyfile
    with open(dst, 'wb') as fdst:
FileNotFoundError: [Errno 2] No such file or directory: '/dst/test_copy.txt'
2020-06-12 12:49:39,036:Survey Assist - v1.0:Started Application

2020-06-12 12:54:49,545:Survey Assist - v1.0:Started Application

2020-06-12 12:55:15,755:Survey Assist - v1.0:Started Application

2020-06-12 12:55:48,939:Survey Assist - v1.0:Started Application

2020-06-12 12:56:00,604:Survey Assist - v1.0:Started Application

2020-06-12 12:57:23,803:Survey Assist - v1.0:Started Application

2020-06-12 12:57:25,668:Survey Assist - v1.0:Job Tracker excel spreadsheet currently in use

[Errno 13] Permission denied: 'C:\\Users\\rjwal_000\\PycharmProjects\\Survey Assist\\Test Files\\Survey Data\\2020\\Job Tracker Digital System.xlsm'
Traceback (most recent call last):
  File "C:/Users/rjwal_000/PycharmProjects/Survey Assist/main.py", line 2152, in save_job_to_excel
    workbook.save(filename=self.job_tracker_filepath)
  File "C:\Python34\lib\site-packages\openpyxl\workbook\workbook.py", line 391, in save
    save_workbook(self, filename)
  File "C:\Python34\lib\site-packages\openpyxl\writer\excel.py", line 282, in save_workbook
    archive = ZipFile(filename, 'w', ZIP_DEFLATED, allowZip64=True)
  File "C:\Python34\lib\zipfile.py", line 923, in __init__
    self.fp = io.open(file, modeDict[mode])
PermissionError: [Errno 13] Permission denied: 'C:\\Users\\rjwal_000\\PycharmProjects\\Survey Assist\\Test Files\\Survey Data\\2020\\Job Tracker Digital System.xlsm'
2020-06-12 12:58:23,643:Survey Assist - v1.0:Started Application

2020-06-12 13:03:10,781:Survey Assist - v1.0:Started Application

2020-06-12 13:11:27,738:Survey Assist - v1.0:Started Application

2020-06-12 13:11:27,755:Survey Assist - v1.0:Job Tracker excel spreadsheet not found

[Errno 2] No such file or directory: 'C:\\Users\\rjwal_000\\PycharmProjects\\Survey Assist\\Test Files\\Survey Data\\2020\\Job Tracker Digital System.xlsm'
Traceback (most recent call last):
  File "C:\Users\rjwal_000\PycharmProjects\Survey Assist\job_tracker.py", line 19, in __init__
    self.workbook = load_workbook(self.job_tracker_filepath, read_only=True)
  File "C:\Python34\lib\site-packages\openpyxl\reader\excel.py", line 147, in load_workbook
    archive = _validate_archive(filename)
  File "C:\Python34\lib\site-packages\openpyxl\reader\excel.py", line 97, in _validate_archive
    archive = ZipFile(filename, 'r')
  File "C:\Python34\lib\zipfile.py", line 923, in __init__
    self.fp = io.open(file, modeDict[mode])
FileNotFoundError: [Errno 2] No such file or directory: 'C:\\Users\\rjwal_000\\PycharmProjects\\Survey Assist\\Test Files\\Survey Data\\2020\\Job Tracker Digital System.xlsm'
2020-06-12 13:11:31,718:Survey Assist - v1.0:Job Tracker excel spreadsheet not found

[Errno 2] No such file or directory: 'C:\\Users\\rjwal_000\\PycharmProjects\\Survey Assist\\Test Files\\Survey Data\\2020\\Job Tracker Digital System.xlsm'
Traceback (most recent call last):
  File "C:\Users\rjwal_000\PycharmProjects\Survey Assist\job_tracker.py", line 19, in __init__
    self.workbook = load_workbook(self.job_tracker_filepath, read_only=True)
  File "C:\Python34\lib\site-packages\openpyxl\reader\excel.py", line 147, in load_workbook
    archive = _validate_archive(filename)
  File "C:\Python34\lib\site-packages\openpyxl\reader\excel.py", line 97, in _validate_archive
    archive = ZipFile(filename, 'r')
  File "C:\Python34\lib\zipfile.py", line 923, in __init__
    self.fp = io.open(file, modeDict[mode])
FileNotFoundError: [Errno 2] No such file or directory: 'C:\\Users\\rjwal_000\\PycharmProjects\\Survey Assist\\Test Files\\Survey Data\\2020\\Job Tracker Digital System.xlsm'
2020-06-12 13:12:33,899:Survey Assist - v1.0:Started Application

2020-06-12 13:12:33,914:Survey Assist - v1.0:Job Tracker excel spreadsheet not found

[Errno 2] No such file or directory: 'C:\\Users\\rjwal_000\\PycharmProjects\\Survey Assist\\Test Files\\Survey Data\\2020\\Job Tracker Digital System.xlsm'
Traceback (most recent call last):
  File "C:\Users\rjwal_000\PycharmProjects\Survey Assist\job_tracker.py", line 19, in __init__
    self.workbook = load_workbook(self.job_tracker_filepath, read_only=True)
  File "C:\Python34\lib\site-packages\openpyxl\reader\excel.py", line 147, in load_workbook
    archive = _validate_archive(filename)
  File "C:\Python34\lib\site-packages\openpyxl\reader\excel.py", line 97, in _validate_archive
    archive = ZipFile(filename, 'r')
  File "C:\Python34\lib\zipfile.py", line 923, in __init__
    self.fp = io.open(file, modeDict[mode])
FileNotFoundError: [Errno 2] No such file or directory: 'C:\\Users\\rjwal_000\\PycharmProjects\\Survey Assist\\Test Files\\Survey Data\\2020\\Job Tracker Digital System.xlsm'
2020-06-12 13:12:36,910:Survey Assist - v1.0:Job Tracker excel spreadsheet not found

[Errno 2] No such file or directory: 'C:\\Users\\rjwal_000\\PycharmProjects\\Survey Assist\\Test Files\\Survey Data\\2020\\Job Tracker Digital System.xlsm'
Traceback (most recent call last):
  File "C:\Users\rjwal_000\PycharmProjects\Survey Assist\job_tracker.py", line 19, in __init__
    self.workbook = load_workbook(self.job_tracker_filepath, read_only=True)
  File "C:\Python34\lib\site-packages\openpyxl\reader\excel.py", line 147, in load_workbook
    archive = _validate_archive(filename)
  File "C:\Python34\lib\site-packages\openpyxl\reader\excel.py", line 97, in _validate_archive
    archive = ZipFile(filename, 'r')
  File "C:\Python34\lib\zipfile.py", line 923, in __init__
    self.fp = io.open(file, modeDict[mode])
FileNotFoundError: [Errno 2] No such file or directory: 'C:\\Users\\rjwal_000\\PycharmProjects\\Survey Assist\\Test Files\\Survey Data\\2020\\Job Tracker Digital System.xlsm'
2020-06-12 13:13:28,180:Survey Assist - v1.0:Started Application

2020-06-12 13:13:28,195:Survey Assist - v1.0:Job Tracker excel spreadsheet not found

[Errno 2] No such file or directory: 'C:\\Users\\rjwal_000\\PycharmProjects\\Survey Assist\\Test Files\\Survey Data\\2020\\Job Tracker Digital System.xlsm'
Traceback (most recent call last):
  File "C:\Users\rjwal_000\PycharmProjects\Survey Assist\job_tracker.py", line 19, in __init__
    self.workbook = load_workbook(self.job_tracker_filepath, read_only=True)
  File "C:\Python34\lib\site-packages\openpyxl\reader\excel.py", line 147, in load_workbook
    archive = _validate_archive(filename)
  File "C:\Python34\lib\site-packages\openpyxl\reader\excel.py", line 97, in _validate_archive
    archive = ZipFile(filename, 'r')
  File "C:\Python34\lib\zipfile.py", line 923, in __init__
    self.fp = io.open(file, modeDict[mode])
FileNotFoundError: [Errno 2] No such file or directory: 'C:\\Users\\rjwal_000\\PycharmProjects\\Survey Assist\\Test Files\\Survey Data\\2020\\Job Tracker Digital System.xlsm'
2020-06-12 13:13:30,707:Survey Assist - v1.0:Job Tracker excel spreadsheet not found

[Errno 2] No such file or directory: 'C:\\Users\\rjwal_000\\PycharmProjects\\Survey Assist\\Test Files\\Survey Data\\2020\\Job Tracker Digital System.xlsm'
Traceback (most recent call last):
  File "C:\Users\rjwal_000\PycharmProjects\Survey Assist\job_tracker.py", line 19, in __init__
    self.workbook = load_workbook(self.job_tracker_filepath, read_only=True)
  File "C:\Python34\lib\site-packages\openpyxl\reader\excel.py", line 147, in load_workbook
    archive = _validate_archive(filename)
  File "C:\Python34\lib\site-packages\openpyxl\reader\excel.py", line 97, in _validate_archive
    archive = ZipFile(filename, 'r')
  File "C:\Python34\lib\zipfile.py", line 923, in __init__
    self.fp = io.open(file, modeDict[mode])
FileNotFoundError: [Errno 2] No such file or directory: 'C:\\Users\\rjwal_000\\PycharmProjects\\Survey Assist\\Test Files\\Survey Data\\2020\\Job Tracker Digital System.xlsm'
2020-06-12 13:14:36,700:Survey Assist - v1.0:Started Application

2020-06-12 13:14:36,715:Survey Assist - v1.0:Job Tracker excel spreadsheet not found

[Errno 2] No such file or directory: 'C:\\Users\\rjwal_000\\PycharmProjects\\Survey Assist\\Test Files\\Survey Data\\2020\\Job Tracker Digital System.xlsm'
Traceback (most recent call last):
  File "C:\Users\rjwal_000\PycharmProjects\Survey Assist\job_tracker.py", line 18, in __init__
    self.workbook = load_workbook(self.job_tracker_filepath, read_only=True)
  File "C:\Python34\lib\site-packages\openpyxl\reader\excel.py", line 147, in load_workbook
    archive = _validate_archive(filename)
  File "C:\Python34\lib\site-packages\openpyxl\reader\excel.py", line 97, in _validate_archive
    archive = ZipFile(filename, 'r')
  File "C:\Python34\lib\zipfile.py", line 923, in __init__
    self.fp = io.open(file, modeDict[mode])
FileNotFoundError: [Errno 2] No such file or directory: 'C:\\Users\\rjwal_000\\PycharmProjects\\Survey Assist\\Test Files\\Survey Data\\2020\\Job Tracker Digital System.xlsm'
2020-06-12 13:14:42,956:Survey Assist - v1.0:Job Tracker excel spreadsheet not found

[Errno 2] No such file or directory: 'C:\\Users\\rjwal_000\\PycharmProjects\\Survey Assist\\Test Files\\Survey Data\\2020\\Job Tracker Digital System.xlsm'
Traceback (most recent call last):
  File "C:\Users\rjwal_000\PycharmProjects\Survey Assist\job_tracker.py", line 18, in __init__
    self.workbook = load_workbook(self.job_tracker_filepath, read_only=True)
  File "C:\Python34\lib\site-packages\openpyxl\reader\excel.py", line 147, in load_workbook
    archive = _validate_archive(filename)
  File "C:\Python34\lib\site-packages\openpyxl\reader\excel.py", line 97, in _validate_archive
    archive = ZipFile(filename, 'r')
  File "C:\Python34\lib\zipfile.py", line 923, in __init__
    self.fp = io.open(file, modeDict[mode])
FileNotFoundError: [Errno 2] No such file or directory: 'C:\\Users\\rjwal_000\\PycharmProjects\\Survey Assist\\Test Files\\Survey Data\\2020\\Job Tracker Digital System.xlsm'
2020-06-12 13:14:50,911:Survey Assist - v1.0:Started Application

2020-06-12 13:14:50,927:Survey Assist - v1.0:Job Tracker excel spreadsheet not found

[Errno 2] No such file or directory: 'C:\\Users\\rjwal_000\\PycharmProjects\\Survey Assist\\Test Files\\Survey Data\\2020\\Job Tracker Digital System.xlsm'
Traceback (most recent call last):
  File "C:\Users\rjwal_000\PycharmProjects\Survey Assist\job_tracker.py", line 18, in __init__
    self.workbook = load_workbook(self.job_tracker_filepath, read_only=True)
  File "C:\Python34\lib\site-packages\openpyxl\reader\excel.py", line 147, in load_workbook
    archive = _validate_archive(filename)
  File "C:\Python34\lib\site-packages\openpyxl\reader\excel.py", line 97, in _validate_archive
    archive = ZipFile(filename, 'r')
  File "C:\Python34\lib\zipfile.py", line 923, in __init__
    self.fp = io.open(file, modeDict[mode])
FileNotFoundError: [Errno 2] No such file or directory: 'C:\\Users\\rjwal_000\\PycharmProjects\\Survey Assist\\Test Files\\Survey Data\\2020\\Job Tracker Digital System.xlsm'
2020-06-12 13:14:52,033:Survey Assist - v1.0:Job Tracker excel spreadsheet not found

[Errno 2] No such file or directory: 'C:\\Users\\rjwal_000\\PycharmProjects\\Survey Assist\\Test Files\\Survey Data\\2020\\Job Tracker Digital System.xlsm'
Traceback (most recent call last):
  File "C:\Users\rjwal_000\PycharmProjects\Survey Assist\job_tracker.py", line 18, in __init__
    self.workbook = load_workbook(self.job_tracker_filepath, read_only=True)
  File "C:\Python34\lib\site-packages\openpyxl\reader\excel.py", line 147, in load_workbook
    archive = _validate_archive(filename)
  File "C:\Python34\lib\site-packages\openpyxl\reader\excel.py", line 97, in _validate_archive
    archive = ZipFile(filename, 'r')
  File "C:\Python34\lib\zipfile.py", line 923, in __init__
    self.fp = io.open(file, modeDict[mode])
FileNotFoundError: [Errno 2] No such file or directory: 'C:\\Users\\rjwal_000\\PycharmProjects\\Survey Assist\\Test Files\\Survey Data\\2020\\Job Tracker Digital System.xlsm'
2020-06-12 13:18:02,356:Survey Assist - v1.0:Started Application

2020-06-12 13:18:02,370:Survey Assist - v1.0:Job Tracker excel spreadsheet not found

[Errno 2] No such file or directory: 'C:\\Users\\rjwal_000\\PycharmProjects\\Survey Assist\\Test Files\\Survey Data\\2020\\Job Tracker Digital System.xlsm'
Traceback (most recent call last):
  File "C:\Users\rjwal_000\PycharmProjects\Survey Assist\job_tracker.py", line 18, in __init__
    self.workbook = load_workbook(self.job_tracker_filepath, read_only=True)
  File "C:\Python34\lib\site-packages\openpyxl\reader\excel.py", line 147, in load_workbook
    archive = _validate_archive(filename)
  File "C:\Python34\lib\site-packages\openpyxl\reader\excel.py", line 97, in _validate_archive
    archive = ZipFile(filename, 'r')
  File "C:\Python34\lib\zipfile.py", line 923, in __init__
    self.fp = io.open(file, modeDict[mode])
FileNotFoundError: [Errno 2] No such file or directory: 'C:\\Users\\rjwal_000\\PycharmProjects\\Survey Assist\\Test Files\\Survey Data\\2020\\Job Tracker Digital System.xlsm'
2020-06-12 13:18:06,152:Survey Assist - v1.0:Job Tracker excel spreadsheet not found

[Errno 2] No such file or directory: 'C:\\Users\\rjwal_000\\PycharmProjects\\Survey Assist\\Test Files\\Survey Data\\2020\\Job Tracker Digital System.xlsm'
Traceback (most recent call last):
  File "C:\Users\rjwal_000\PycharmProjects\Survey Assist\job_tracker.py", line 18, in __init__
    self.workbook = load_workbook(self.job_tracker_filepath, read_only=True)
  File "C:\Python34\lib\site-packages\openpyxl\reader\excel.py", line 147, in load_workbook
    archive = _validate_archive(filename)
  File "C:\Python34\lib\site-packages\openpyxl\reader\excel.py", line 97, in _validate_archive
    archive = ZipFile(filename, 'r')
  File "C:\Python34\lib\zipfile.py", line 923, in __init__
    self.fp = io.open(file, modeDict[mode])
FileNotFoundError: [Errno 2] No such file or directory: 'C:\\Users\\rjwal_000\\PycharmProjects\\Survey Assist\\Test Files\\Survey Data\\2020\\Job Tracker Digital System.xlsm'
2020-06-12 13:19:36,091:Survey Assist - v1.0:Started Application

2020-06-12 13:19:41,112:Survey Assist - v1.0:Error has occurred in JobTracker init().

insert_rows() got an unexpected keyword argument 'translate'
Traceback (most recent call last):
  File "C:/Users/rjwal_000/PycharmProjects/Survey Assist/main.py", line 2145, in save_job_to_excel
    actions_sheet.insert_rows(idx=11, translate=True)
TypeError: insert_rows() got an unexpected keyword argument 'translate'
2020-06-12 13:23:55,337:Survey Assist - v1.0:Started Application

2020-06-12 13:26:15,064:Survey Assist - v1.0:Started Application

2020-06-12 13:26:18,002:Survey Assist - v1.0:Job Tracker excel spreadsheet currently in use

[Errno 13] Permission denied: 'C:\\Users\\rjwal_000\\PycharmProjects\\Survey Assist\\Test Files\\Survey Data\\2020\\Job Tracker Digital System.xlsm'
Traceback (most recent call last):
  File "C:/Users/rjwal_000/PycharmProjects/Survey Assist/main.py", line 2153, in save_job_to_excel
    workbook.save(filename=self.job_tracker_filepath)
  File "C:\Python34\lib\site-packages\openpyxl\workbook\workbook.py", line 391, in save
    save_workbook(self, filename)
  File "C:\Python34\lib\site-packages\openpyxl\writer\excel.py", line 282, in save_workbook
    archive = ZipFile(filename, 'w', ZIP_DEFLATED, allowZip64=True)
  File "C:\Python34\lib\zipfile.py", line 923, in __init__
    self.fp = io.open(file, modeDict[mode])
PermissionError: [Errno 13] Permission denied: 'C:\\Users\\rjwal_000\\PycharmProjects\\Survey Assist\\Test Files\\Survey Data\\2020\\Job Tracker Digital System.xlsm'
2020-06-12 13:40:10,275:Survey Assist - v1.0:Started Application

2020-06-12 13:40:34,691:Survey Assist - v1.0:Started Application

2020-06-12 13:50:32,318:Survey Assist - v1.0:Started Application

2020-06-12 13:52:07,064:Survey Assist - v1.0:Started Application

2020-06-12 13:52:07,094:Survey Assist - v1.0:Error has occurred in JobTracker init().

'NoneType' object has no attribute 'strftime'
Traceback (most recent call last):
  File "C:\Users\rjwal_000\PycharmProjects\Survey Assist\job_tracker.py", line 20, in __init__
    self.create_list_of_job_tracker_jobs()
  File "C:\Users\rjwal_000\PycharmProjects\Survey Assist\job_tracker.py", line 42, in create_list_of_job_tracker_jobs
    survey_job = SurveyJob(row[0].value, row[1].value.strftime('%d/%m/%Y'), row[2].value, row[3].value, row[4].value)
AttributeError: 'NoneType' object has no attribute 'strftime'
2020-06-12 13:52:08,736:Survey Assist - v1.0:Error has occurred in JobTracker init().

'NoneType' object has no attribute 'strftime'
Traceback (most recent call last):
  File "C:\Users\rjwal_000\PycharmProjects\Survey Assist\job_tracker.py", line 20, in __init__
    self.create_list_of_job_tracker_jobs()
  File "C:\Users\rjwal_000\PycharmProjects\Survey Assist\job_tracker.py", line 42, in create_list_of_job_tracker_jobs
    survey_job = SurveyJob(row[0].value, row[1].value.strftime('%d/%m/%Y'), row[2].value, row[3].value, row[4].value)
AttributeError: 'NoneType' object has no attribute 'strftime'
2020-06-12 13:53:40,542:Survey Assist - v1.0:Started Application

2020-06-12 13:54:22,582:Survey Assist - v1.0:Started Application

2020-06-12 13:54:22,619:Survey Assist - v1.0:Error has occurred in JobTracker init().

'NoneType' object has no attribute 'strftime'
Traceback (most recent call last):
  File "C:\Users\rjwal_000\PycharmProjects\Survey Assist\job_tracker.py", line 20, in __init__
    self.create_list_of_job_tracker_jobs()
  File "C:\Users\rjwal_000\PycharmProjects\Survey Assist\job_tracker.py", line 43, in create_list_of_job_tracker_jobs
    survey_job = SurveyJob(row[0].value, row[1].value.strftime('%d/%m/%Y'), row[2].value, row[3].value, row[4].value)
AttributeError: 'NoneType' object has no attribute 'strftime'
2020-06-12 13:54:24,758:Survey Assist - v1.0:Error has occurred in JobTracker init().

'NoneType' object has no attribute 'strftime'
Traceback (most recent call last):
  File "C:\Users\rjwal_000\PycharmProjects\Survey Assist\job_tracker.py", line 20, in __init__
    self.create_list_of_job_tracker_jobs()
  File "C:\Users\rjwal_000\PycharmProjects\Survey Assist\job_tracker.py", line 43, in create_list_of_job_tracker_jobs
    survey_job = SurveyJob(row[0].value, row[1].value.strftime('%d/%m/%Y'), row[2].value, row[3].value, row[4].value)
AttributeError: 'NoneType' object has no attribute 'strftime'
2020-06-12 13:55:26,709:Survey Assist - v1.0:Started Application

2020-06-12 13:56:39,095:Survey Assist - v1.0:Started Application

2020-06-12 14:10:29,131:Survey Assist - v1.0:Started Application

2020-06-12 14:10:29,150:Survey Assist - v1.0:Job Tracker excel spreadsheet not found

[Errno 2] No such file or directory: 'C:\\Users\\rjwal_000\\PycharmProjects\\Survey Assist\\Test Files\\Survey Data\\2020\\Job Tracker Digital System.xlsm'
Traceback (most recent call last):
  File "C:\Users\rjwal_000\PycharmProjects\Survey Assist\job_tracker.py", line 18, in __init__
    self.workbook = load_workbook(self.job_tracker_filepath, read_only=True)
  File "C:\Python34\lib\site-packages\openpyxl\reader\excel.py", line 147, in load_workbook
    archive = _validate_archive(filename)
  File "C:\Python34\lib\site-packages\openpyxl\reader\excel.py", line 97, in _validate_archive
    archive = ZipFile(filename, 'r')
  File "C:\Python34\lib\zipfile.py", line 923, in __init__
    self.fp = io.open(file, modeDict[mode])
FileNotFoundError: [Errno 2] No such file or directory: 'C:\\Users\\rjwal_000\\PycharmProjects\\Survey Assist\\Test Files\\Survey Data\\2020\\Job Tracker Digital System.xlsm'
2020-06-12 14:10:30,500:Survey Assist - v1.0:Job Tracker excel spreadsheet not found

[Errno 2] No such file or directory: 'C:\\Users\\rjwal_000\\PycharmProjects\\Survey Assist\\Test Files\\Survey Data\\2020\\Job Tracker Digital System.xlsm'
Traceback (most recent call last):
  File "C:\Users\rjwal_000\PycharmProjects\Survey Assist\job_tracker.py", line 18, in __init__
    self.workbook = load_workbook(self.job_tracker_filepath, read_only=True)
  File "C:\Python34\lib\site-packages\openpyxl\reader\excel.py", line 147, in load_workbook
    archive = _validate_archive(filename)
  File "C:\Python34\lib\site-packages\openpyxl\reader\excel.py", line 97, in _validate_archive
    archive = ZipFile(filename, 'r')
  File "C:\Python34\lib\zipfile.py", line 923, in __init__
    self.fp = io.open(file, modeDict[mode])
FileNotFoundError: [Errno 2] No such file or directory: 'C:\\Users\\rjwal_000\\PycharmProjects\\Survey Assist\\Test Files\\Survey Data\\2020\\Job Tracker Digital System.xlsm'
2020-06-12 14:11:06,931:Survey Assist - v1.0:Started Application

2020-06-12 14:12:58,385:Survey Assist - v1.0:Started Application

2020-06-12 14:15:31,146:Survey Assist - v1.0:Started Application

2020-06-12 14:15:31,178:Survey Assist - v1.0:Error has occurred in JobTracker init().

'str' object has no attribute 'strftime'
Traceback (most recent call last):
  File "C:\Users\rjwal_000\PycharmProjects\Survey Assist\job_tracker.py", line 20, in __init__
    self.create_list_of_job_tracker_jobs()
  File "C:\Users\rjwal_000\PycharmProjects\Survey Assist\job_tracker.py", line 42, in create_list_of_job_tracker_jobs
    survey_job = SurveyJob(row[0].value, row[1].value.strftime('%d/%m/%Y'), row[2].value, row[3].value, row[4].value)
AttributeError: 'str' object has no attribute 'strftime'
2020-06-12 14:15:32,646:Survey Assist - v1.0:Error has occurred in JobTracker init().

'str' object has no attribute 'strftime'
Traceback (most recent call last):
  File "C:\Users\rjwal_000\PycharmProjects\Survey Assist\job_tracker.py", line 20, in __init__
    self.create_list_of_job_tracker_jobs()
  File "C:\Users\rjwal_000\PycharmProjects\Survey Assist\job_tracker.py", line 42, in create_list_of_job_tracker_jobs
    survey_job = SurveyJob(row[0].value, row[1].value.strftime('%d/%m/%Y'), row[2].value, row[3].value, row[4].value)
AttributeError: 'str' object has no attribute 'strftime'
2020-06-12 14:16:41,147:Survey Assist - v1.0:Started Application

2020-06-12 14:16:41,167:Survey Assist - v1.0:Job Tracker excel spreadsheet not found

[Errno 2] No such file or directory: 'C:\\Users\\rjwal_000\\PycharmProjects\\Survey Assist\\Test Files\\Survey Data\\2020\\Job Tracker Digital System.xlsm'
Traceback (most recent call last):
  File "C:\Users\rjwal_000\PycharmProjects\Survey Assist\job_tracker.py", line 18, in __init__
    self.workbook = load_workbook(self.job_tracker_filepath, read_only=True)
  File "C:\Python34\lib\site-packages\openpyxl\reader\excel.py", line 147, in load_workbook
    archive = _validate_archive(filename)
  File "C:\Python34\lib\site-packages\openpyxl\reader\excel.py", line 97, in _validate_archive
    archive = ZipFile(filename, 'r')
  File "C:\Python34\lib\zipfile.py", line 923, in __init__
    self.fp = io.open(file, modeDict[mode])
FileNotFoundError: [Errno 2] No such file or directory: 'C:\\Users\\rjwal_000\\PycharmProjects\\Survey Assist\\Test Files\\Survey Data\\2020\\Job Tracker Digital System.xlsm'
2020-06-12 14:16:42,863:Survey Assist - v1.0:Job Tracker excel spreadsheet not found

[Errno 2] No such file or directory: 'C:\\Users\\rjwal_000\\PycharmProjects\\Survey Assist\\Test Files\\Survey Data\\2020\\Job Tracker Digital System.xlsm'
Traceback (most recent call last):
  File "C:\Users\rjwal_000\PycharmProjects\Survey Assist\job_tracker.py", line 18, in __init__
    self.workbook = load_workbook(self.job_tracker_filepath, read_only=True)
  File "C:\Python34\lib\site-packages\openpyxl\reader\excel.py", line 147, in load_workbook
    archive = _validate_archive(filename)
  File "C:\Python34\lib\site-packages\openpyxl\reader\excel.py", line 97, in _validate_archive
    archive = ZipFile(filename, 'r')
  File "C:\Python34\lib\zipfile.py", line 923, in __init__
    self.fp = io.open(file, modeDict[mode])
FileNotFoundError: [Errno 2] No such file or directory: 'C:\\Users\\rjwal_000\\PycharmProjects\\Survey Assist\\Test Files\\Survey Data\\2020\\Job Tracker Digital System.xlsm'
2020-06-12 14:16:59,138:Survey Assist - v1.0:Started Application

2020-06-12 14:24:36,283:Survey Assist - v1.0:Started Application

2020-06-12 14:24:42,496:Survey Assist - v1.0:Error has occurred in JobTracker init().

Value must be one of {'formula', 'percentile', 'num', 'percent', 'max', 'min'}
Traceback (most recent call last):
  File "C:/Users/rjwal_000/PycharmProjects/Survey Assist/main.py", line 2169, in save_job_to_excel
    showValue = "None", minLength = 0, maxLength = 5)
  File "C:\Python34\lib\site-packages\openpyxl\formatting\rule.py", line 288, in DataBarRule
    start = FormatObject(start_type, start_value)
  File "C:\Python34\lib\site-packages\openpyxl\formatting\rule.py", line 59, in __init__
    self.type = type
  File "C:\Python34\lib\site-packages\openpyxl\descriptors\base.py", line 130, in __set__
    raise ValueError(self.__doc__)
ValueError: Value must be one of {'formula', 'percentile', 'num', 'percent', 'max', 'min'}
2020-06-12 14:25:15,166:Survey Assist - v1.0:Started Application

2020-06-12 14:25:20,812:Survey Assist - v1.0:Job Tracker excel spreadsheet currently in use

[Errno 13] Permission denied: 'C:\\Users\\rjwal_000\\PycharmProjects\\Survey Assist\\Test Files\\Survey Data\\2020\\Job Tracker Digital System.xlsm'
Traceback (most recent call last):
  File "C:/Users/rjwal_000/PycharmProjects/Survey Assist/main.py", line 2173, in save_job_to_excel
    workbook.save(filename=self.job_tracker_filepath)
  File "C:\Python34\lib\site-packages\openpyxl\workbook\workbook.py", line 391, in save
    save_workbook(self, filename)
  File "C:\Python34\lib\site-packages\openpyxl\writer\excel.py", line 282, in save_workbook
    archive = ZipFile(filename, 'w', ZIP_DEFLATED, allowZip64=True)
  File "C:\Python34\lib\zipfile.py", line 923, in __init__
    self.fp = io.open(file, modeDict[mode])
PermissionError: [Errno 13] Permission denied: 'C:\\Users\\rjwal_000\\PycharmProjects\\Survey Assist\\Test Files\\Survey Data\\2020\\Job Tracker Digital System.xlsm'
2020-06-12 14:33:08,499:Survey Assist - v1.0:Started Application

2020-06-12 14:33:08,531:Survey Assist - v1.0:Error has occurred in JobTracker init().

'str' object has no attribute 'strftime'
Traceback (most recent call last):
  File "C:\Users\rjwal_000\PycharmProjects\Survey Assist\job_tracker.py", line 20, in __init__
    self.create_list_of_job_tracker_jobs()
  File "C:\Users\rjwal_000\PycharmProjects\Survey Assist\job_tracker.py", line 42, in create_list_of_job_tracker_jobs
    survey_job = SurveyJob(row[0].value, row[1].value.strftime('%d/%m/%Y'), row[2].value, row[3].value, row[4].value)
AttributeError: 'str' object has no attribute 'strftime'
2020-06-12 14:33:10,270:Survey Assist - v1.0:Error has occurred in JobTracker init().

'str' object has no attribute 'strftime'
Traceback (most recent call last):
  File "C:\Users\rjwal_000\PycharmProjects\Survey Assist\job_tracker.py", line 20, in __init__
    self.create_list_of_job_tracker_jobs()
  File "C:\Users\rjwal_000\PycharmProjects\Survey Assist\job_tracker.py", line 42, in create_list_of_job_tracker_jobs
    survey_job = SurveyJob(row[0].value, row[1].value.strftime('%d/%m/%Y'), row[2].value, row[3].value, row[4].value)
AttributeError: 'str' object has no attribute 'strftime'
2020-06-12 14:34:08,922:Survey Assist - v1.0:Started Application

2020-06-12 14:34:40,538:Survey Assist - v1.0:Started Application

2020-06-12 14:34:40,567:Survey Assist - v1.0:Error has occurred in JobTracker init().

'str' object has no attribute 'strftime'
Traceback (most recent call last):
  File "C:\Users\rjwal_000\PycharmProjects\Survey Assist\job_tracker.py", line 20, in __init__
    self.create_list_of_job_tracker_jobs()
  File "C:\Users\rjwal_000\PycharmProjects\Survey Assist\job_tracker.py", line 42, in create_list_of_job_tracker_jobs
    survey_job = SurveyJob(row[0].value, row[1].value.strftime('%d/%m/%Y'), row[2].value, row[3].value, row[4].value)
AttributeError: 'str' object has no attribute 'strftime'
2020-06-12 14:34:42,085:Survey Assist - v1.0:Error has occurred in JobTracker init().

'str' object has no attribute 'strftime'
Traceback (most recent call last):
  File "C:\Users\rjwal_000\PycharmProjects\Survey Assist\job_tracker.py", line 20, in __init__
    self.create_list_of_job_tracker_jobs()
  File "C:\Users\rjwal_000\PycharmProjects\Survey Assist\job_tracker.py", line 42, in create_list_of_job_tracker_jobs
    survey_job = SurveyJob(row[0].value, row[1].value.strftime('%d/%m/%Y'), row[2].value, row[3].value, row[4].value)
AttributeError: 'str' object has no attribute 'strftime'
2020-06-12 14:35:51,767:Survey Assist - v1.0:Started Application

2020-06-12 14:35:51,798:Survey Assist - v1.0:Error has occurred in JobTracker init().

'str' object has no attribute 'strftime'
Traceback (most recent call last):
  File "C:\Users\rjwal_000\PycharmProjects\Survey Assist\job_tracker.py", line 20, in __init__
    self.create_list_of_job_tracker_jobs()
  File "C:\Users\rjwal_000\PycharmProjects\Survey Assist\job_tracker.py", line 42, in create_list_of_job_tracker_jobs
    survey_job = SurveyJob(row[0].value, row[1].value.strftime('%d/%m/%Y'), row[2].value, row[3].value, row[4].value)
AttributeError: 'str' object has no attribute 'strftime'
2020-06-12 14:35:53,088:Survey Assist - v1.0:Error has occurred in JobTracker init().

'str' object has no attribute 'strftime'
Traceback (most recent call last):
  File "C:\Users\rjwal_000\PycharmProjects\Survey Assist\job_tracker.py", line 20, in __init__
    self.create_list_of_job_tracker_jobs()
  File "C:\Users\rjwal_000\PycharmProjects\Survey Assist\job_tracker.py", line 42, in create_list_of_job_tracker_jobs
    survey_job = SurveyJob(row[0].value, row[1].value.strftime('%d/%m/%Y'), row[2].value, row[3].value, row[4].value)
AttributeError: 'str' object has no attribute 'strftime'
2020-06-12 14:36:59,142:Survey Assist - v1.0:Started Application

2020-06-12 14:36:59,171:Survey Assist - v1.0:Error has occurred in JobTracker init().

'str' object is not callable
Traceback (most recent call last):
  File "C:\Users\rjwal_000\PycharmProjects\Survey Assist\job_tracker.py", line 20, in __init__
    self.create_list_of_job_tracker_jobs()
  File "C:\Users\rjwal_000\PycharmProjects\Survey Assist\job_tracker.py", line 43, in create_list_of_job_tracker_jobs
    survey_job = SurveyJob(row[0].value, survey_date('%d/%m/%Y'), row[2].value, row[3].value, row[4].value)
TypeError: 'str' object is not callable
2020-06-12 14:37:00,210:Survey Assist - v1.0:Error has occurred in JobTracker init().

'str' object is not callable
Traceback (most recent call last):
  File "C:\Users\rjwal_000\PycharmProjects\Survey Assist\job_tracker.py", line 20, in __init__
    self.create_list_of_job_tracker_jobs()
  File "C:\Users\rjwal_000\PycharmProjects\Survey Assist\job_tracker.py", line 43, in create_list_of_job_tracker_jobs
    survey_job = SurveyJob(row[0].value, survey_date('%d/%m/%Y'), row[2].value, row[3].value, row[4].value)
TypeError: 'str' object is not callable
2020-06-12 14:37:09,179:Survey Assist - v1.0:Started Application

2020-06-12 14:37:31,528:Survey Assist - v1.0:Error has occurred in JobTracker init().

'str' object is not callable
Traceback (most recent call last):
  File "C:\Users\rjwal_000\PycharmProjects\Survey Assist\job_tracker.py", line 20, in __init__
    self.create_list_of_job_tracker_jobs()
  File "C:\Users\rjwal_000\PycharmProjects\Survey Assist\job_tracker.py", line 43, in create_list_of_job_tracker_jobs
    survey_job = SurveyJob(row[0].value, survey_date('%d/%m/%Y'), row[2].value, row[3].value, row[4].value)
TypeError: 'str' object is not callable
2020-06-12 14:38:53,758:Survey Assist - v1.0:Started Application

2020-06-12 14:39:26,705:Survey Assist - v1.0:Started Application

2020-06-12 14:44:56,101:Survey Assist - v1.0:Started Application

2020-06-12 14:49:22,845:Survey Assist - v1.0:Started Application

2020-06-12 14:50:00,455:Survey Assist - v1.0:Started Application

2020-06-12 15:28:55,268:Survey Assist - v1.0:Started Application

2020-06-12 15:29:54,497:Survey Assist - v1.0:Started Application

2020-06-12 15:30:19,295:Survey Assist - v1.0:Started Application

2020-06-12 16:17:59,246:Survey Assist - v1.0:Started Application

2020-06-12 16:31:21,057:Survey Assist - v1.0:Started Application

2020-06-12 16:31:28,568:Survey Assist - v1.0:Error has occurred in JobTracker init().

Can't convert 'int' object to str implicitly
Traceback (most recent call last):
  File "C:/Users/rjwal_000/PycharmProjects/Survey Assist/main.py", line 2162, in save_job_to_excel
    actions_sheet[percentage_complete_cell] = '=SUM(D' + row + ':H' + row +')'
TypeError: Can't convert 'int' object to str implicitly
2020-06-12 16:31:50,480:Survey Assist - v1.0:Started Application

2020-06-12 16:33:48,579:Survey Assist - v1.0:Started Application

2020-06-12 16:36:09,944:Survey Assist - v1.0:Started Application

2020-06-12 16:37:04,470:Survey Assist - v1.0:Started Application

2020-06-12 16:39:34,267:Survey Assist - v1.0:Started Application

2020-06-12 16:41:35,319:Survey Assist - v1.0:Started Application

2020-06-14 15:52:47,086:Survey Assist - v1.0:Started Application

2020-06-14 15:53:17,588:Survey Assist - v1.0:Started Application

2020-06-14 15:55:30,372:Survey Assist - v1.0:Started Application

2020-06-14 15:56:39,789:Survey Assist - v1.0:Started Application

2020-06-14 15:59:01,013:Survey Assist - v1.0:Started Application

2020-06-14 15:59:40,995:Survey Assist - v1.0:Started Application

2020-06-14 15:59:55,998:Survey Assist - v1.0:Started Application

2020-06-14 16:00:35,546:Survey Assist - v1.0:Job Tracker excel spreadsheet currently in use

[Errno 13] Permission denied: 'C:\\Users\\rjwal_000\\PycharmProjects\\Survey Assist\\Test Files\\Survey Data\\2020\\Job Tracker Digital System.xlsm'
Traceback (most recent call last):
  File "C:/Users/rjwal_000/PycharmProjects/Survey Assist/main.py", line 2186, in save_job_to_excel
    workbook.save(filename=self.job_tracker_filepath)
  File "C:\Python34\lib\site-packages\openpyxl\workbook\workbook.py", line 391, in save
    save_workbook(self, filename)
  File "C:\Python34\lib\site-packages\openpyxl\writer\excel.py", line 282, in save_workbook
    archive = ZipFile(filename, 'w', ZIP_DEFLATED, allowZip64=True)
  File "C:\Python34\lib\zipfile.py", line 923, in __init__
    self.fp = io.open(file, modeDict[mode])
PermissionError: [Errno 13] Permission denied: 'C:\\Users\\rjwal_000\\PycharmProjects\\Survey Assist\\Test Files\\Survey Data\\2020\\Job Tracker Digital System.xlsm'
2020-06-14 16:02:59,087:Survey Assist - v1.0:Job Tracker excel spreadsheet currently in use

[Errno 13] Permission denied: 'C:\\Users\\rjwal_000\\PycharmProjects\\Survey Assist\\Test Files\\Survey Data\\2020\\Job Tracker Digital System.xlsm'
Traceback (most recent call last):
  File "C:/Users/rjwal_000/PycharmProjects/Survey Assist/main.py", line 2186, in save_job_to_excel
    workbook.save(filename=self.job_tracker_filepath)
  File "C:\Python34\lib\site-packages\openpyxl\workbook\workbook.py", line 391, in save
    save_workbook(self, filename)
  File "C:\Python34\lib\site-packages\openpyxl\writer\excel.py", line 282, in save_workbook
    archive = ZipFile(filename, 'w', ZIP_DEFLATED, allowZip64=True)
  File "C:\Python34\lib\zipfile.py", line 923, in __init__
    self.fp = io.open(file, modeDict[mode])
PermissionError: [Errno 13] Permission denied: 'C:\\Users\\rjwal_000\\PycharmProjects\\Survey Assist\\Test Files\\Survey Data\\2020\\Job Tracker Digital System.xlsm'
2020-06-14 16:04:51,025:Survey Assist - v1.0:Started Application

2020-06-14 16:05:53,253:Survey Assist - v1.0:Started Application

2020-06-14 16:09:30,124:Survey Assist - v1.0:Started Application

2020-06-14 16:15:37,754:Survey Assist - v1.0:Started Application

2020-06-14 16:15:37,827:Survey Assist - v1.0:Error has occurred in JobTracker init().

'datetime.datetime' object has no attribute 'split'
Traceback (most recent call last):
  File "C:\Users\rjwal_000\PycharmProjects\Survey Assist\job_tracker.py", line 20, in __init__
    self.create_list_of_job_tracker_jobs()
  File "C:\Users\rjwal_000\PycharmProjects\Survey Assist\job_tracker.py", line 44, in create_list_of_job_tracker_jobs
    survey_job = SurveyJob(row[0].value, survey_date, row[2].value, row[3].value, row[4].value)
  File "C:\Users\rjwal_000\PycharmProjects\Survey Assist\job_tracker.py", line 68, in __init__
    self.survey_date = survey_date.split()[0]   #we only want the date not the timestamp
AttributeError: 'datetime.datetime' object has no attribute 'split'
2020-06-14 16:15:39,525:Survey Assist - v1.0:Error has occurred in JobTracker init().

'datetime.datetime' object has no attribute 'split'
Traceback (most recent call last):
  File "C:\Users\rjwal_000\PycharmProjects\Survey Assist\job_tracker.py", line 20, in __init__
    self.create_list_of_job_tracker_jobs()
  File "C:\Users\rjwal_000\PycharmProjects\Survey Assist\job_tracker.py", line 44, in create_list_of_job_tracker_jobs
    survey_job = SurveyJob(row[0].value, survey_date, row[2].value, row[3].value, row[4].value)
  File "C:\Users\rjwal_000\PycharmProjects\Survey Assist\job_tracker.py", line 68, in __init__
    self.survey_date = survey_date.split()[0]   #we only want the date not the timestamp
AttributeError: 'datetime.datetime' object has no attribute 'split'
2020-06-14 16:17:00,568:Survey Assist - v1.0:Started Application

2020-06-14 16:17:12,531:Survey Assist - v1.0:Error has occurred in JobTracker init().

'str' object has no attribute 'strftime'
Traceback (most recent call last):
  File "C:\Users\rjwal_000\PycharmProjects\Survey Assist\job_tracker.py", line 20, in __init__
    self.create_list_of_job_tracker_jobs()
  File "C:\Users\rjwal_000\PycharmProjects\Survey Assist\job_tracker.py", line 44, in create_list_of_job_tracker_jobs
    survey_job = SurveyJob(row[0].value, survey_date, row[2].value, row[3].value, row[4].value)
  File "C:\Users\rjwal_000\PycharmProjects\Survey Assist\job_tracker.py", line 68, in __init__
    self.survey_date = survey_date.strftime('%d/%m/%Y')
AttributeError: 'str' object has no attribute 'strftime'
2020-06-14 16:17:21,300:Survey Assist - v1.0:Error has occurred in JobTracker init().

'str' object has no attribute 'strftime'
Traceback (most recent call last):
  File "C:\Users\rjwal_000\PycharmProjects\Survey Assist\job_tracker.py", line 20, in __init__
    self.create_list_of_job_tracker_jobs()
  File "C:\Users\rjwal_000\PycharmProjects\Survey Assist\job_tracker.py", line 44, in create_list_of_job_tracker_jobs
    survey_job = SurveyJob(row[0].value, survey_date, row[2].value, row[3].value, row[4].value)
  File "C:\Users\rjwal_000\PycharmProjects\Survey Assist\job_tracker.py", line 68, in __init__
    self.survey_date = survey_date.strftime('%d/%m/%Y')
AttributeError: 'str' object has no attribute 'strftime'
2020-06-14 16:18:08,390:Survey Assist - v1.0:Started Application

2020-06-14 16:19:37,123:Survey Assist - v1.0:Started Application

2020-06-14 16:25:13,907:Survey Assist - v1.0:Started Application

2020-06-14 16:25:20,265:Survey Assist - v1.0:Error has occurred in JobTracker init().

'Cell' object has no attribute 'date_format'
Traceback (most recent call last):
  File "C:/Users/rjwal_000/PycharmProjects/Survey Assist/main.py", line 2165, in save_job_to_excel
    actions_sheet["B11"].date_format
AttributeError: 'Cell' object has no attribute 'date_format'
2020-06-14 16:26:57,052:Survey Assist - v1.0:Started Application

2020-06-14 16:27:03,059:Survey Assist - v1.0:Error has occurred in JobTracker init().

an integer is required (got type str)
Traceback (most recent call last):
  File "C:/Users/rjwal_000/PycharmProjects/Survey Assist/main.py", line 2164, in save_job_to_excel
    actions_sheet["B11"] = datetime.datetime(self.jt_date_btn['text'])
TypeError: an integer is required (got type str)
2020-06-14 16:29:08,493:Survey Assist - v1.0:Started Application

2020-06-14 16:29:12,030:Survey Assist - v1.0:Error has occurred in JobTracker init().

an integer is required (got type str)
Traceback (most recent call last):
  File "C:/Users/rjwal_000/PycharmProjects/Survey Assist/main.py", line 2167, in save_job_to_excel
    actions_sheet["B11"] = datetime.datetime(job_day, job_month, job_year)
TypeError: an integer is required (got type str)
2020-06-14 16:29:36,426:Survey Assist - v1.0:Started Application

2020-06-14 16:29:39,059:Survey Assist - v1.0:Error has occurred in JobTracker init().

day is out of range for month
Traceback (most recent call last):
  File "C:/Users/rjwal_000/PycharmProjects/Survey Assist/main.py", line 2167, in save_job_to_excel
    actions_sheet["B11"] = datetime.datetime(job_day, job_month, job_year)
ValueError: day is out of range for month
2020-06-14 16:30:04,959:Survey Assist - v1.0:Started Application

2020-06-14 16:33:08,476:Survey Assist - v1.0:Started Application

2020-06-14 16:36:19,175:Survey Assist - v1.0:Started Application

2020-06-14 16:36:22,815:Survey Assist - v1.0:Error has occurred in JobTracker init().

name 'GradientFill' is not defined
Traceback (most recent call last):
  File "C:/Users/rjwal_000/PycharmProjects/Survey Assist/main.py", line 2186, in save_job_to_excel
    actions_sheet[percentage_complete_cell] = GradientFill(stop=("4875f0", "4875f0"))
NameError: name 'GradientFill' is not defined
2020-06-14 16:37:10,438:Survey Assist - v1.0:Started Application

2020-06-14 16:37:28,058:Survey Assist - v1.0:Error has occurred in JobTracker init().

Cannot convert <openpyxl.styles.fills.GradientFill object>
Parameters:
top=0.0, right=0.0, bottom=0.0, degree=0.0, type='linear', left=0.0, stop=[<openpyxl.styles.fills.Stop object>
Parameters:
position=0.0, color=<openpyxl.styles.colors.Color object>
Parameters:
auto=None, theme=None, tint=0.0, rgb='004875f0', indexed=None, type='rgb', <openpyxl.styles.fills.Stop object>
Parameters:
position=1.0, color=<openpyxl.styles.colors.Color object>
Parameters:
auto=None, theme=None, tint=0.0, rgb='004875f0', indexed=None, type='rgb'] to Excel
Traceback (most recent call last):
  File "C:/Users/rjwal_000/PycharmProjects/Survey Assist/main.py", line 2187, in save_job_to_excel
    actions_sheet[percentage_complete_cell] = GradientFill(stop=("4875f0", "4875f0"))
  File "C:\Python34\lib\site-packages\openpyxl\worksheet\worksheet.py", line 369, in __setitem__
    self[key].value = value
  File "C:\Python34\lib\site-packages\openpyxl\cell\cell.py", line 294, in value
    self._bind_value(value)
  File "C:\Python34\lib\site-packages\openpyxl\cell\cell.py", line 207, in _bind_value
    raise ValueError("Cannot convert {0!r} to Excel".format(value))
ValueError: Cannot convert <openpyxl.styles.fills.GradientFill object>
Parameters:
top=0.0, right=0.0, bottom=0.0, degree=0.0, type='linear', left=0.0, stop=[<openpyxl.styles.fills.Stop object>
Parameters:
position=0.0, color=<openpyxl.styles.colors.Color object>
Parameters:
auto=None, theme=None, tint=0.0, rgb='004875f0', indexed=None, type='rgb', <openpyxl.styles.fills.Stop object>
Parameters:
position=1.0, color=<openpyxl.styles.colors.Color object>
Parameters:
auto=None, theme=None, tint=0.0, rgb='004875f0', indexed=None, type='rgb'] to Excel
2020-06-14 16:37:53,432:Survey Assist - v1.0:Started Application

2020-06-14 16:41:37,607:Survey Assist - v1.0:Started Application

2020-06-14 16:41:41,042:Survey Assist - v1.0:Error has occurred in JobTracker init().

DataBarRule() got an unexpected keyword argument 'dxf'
Traceback (most recent call last):
  File "C:/Users/rjwal_000/PycharmProjects/Survey Assist/main.py", line 2194, in save_job_to_excel
    showValue=False, minLength=0, maxLength=100, dxf=dxf)
TypeError: DataBarRule() got an unexpected keyword argument 'dxf'
2020-06-14 16:42:08,624:Survey Assist - v1.0:Started Application

2020-06-14 16:48:15,341:Survey Assist - v1.0:Started Application

2020-06-14 16:52:16,578:Survey Assist - v1.0:Started Application

2020-06-14 16:54:19,454:Survey Assist - v1.0:Started Application

2020-06-14 16:54:54,685:Survey Assist - v1.0:Started Application

2020-06-14 16:55:27,673:Survey Assist - v1.0:Started Application

2020-06-14 16:55:46,445:Survey Assist - v1.0:Started Application

2020-06-14 16:56:14,252:Survey Assist - v1.0:Started Application

2020-06-14 16:56:19,456:Survey Assist - v1.0:Started Application

2020-06-14 16:58:13,969:Survey Assist - v1.0:Started Application

2020-06-14 16:59:34,111:Survey Assist - v1.0:Started Application

2020-06-14 19:47:57,454:Survey Assist - v1.0:Started Application

2020-06-14 19:51:29,670:Survey Assist - v1.0:Started Application

2020-06-14 19:51:49,735:Survey Assist - v1.0:Started Application

2020-06-14 19:55:37,325:Survey Assist - v1.0:Started Application

2020-06-14 19:56:07,871:Survey Assist - v1.0:Started Application

2020-06-14 19:58:02,251:Survey Assist - v1.0:Started Application

2020-06-14 19:59:55,340:Survey Assist - v1.0:Started Application

2020-06-14 20:00:00,263:Survey Assist - v1.0:Started Application

2020-06-14 20:00:48,175:Survey Assist - v1.0:Started Application

2020-06-14 20:01:43,897:Survey Assist - v1.0:Error has occurred in JobTracker init().

'str' object has no attribute 'strftime'
Traceback (most recent call last):
  File "C:\Users\rjwal_000\PycharmProjects\Survey Assist\job_tracker.py", line 20, in __init__
    self.create_list_of_job_tracker_jobs()
  File "C:\Users\rjwal_000\PycharmProjects\Survey Assist\job_tracker.py", line 44, in create_list_of_job_tracker_jobs
    survey_job = SurveyJob(row[0].value, survey_date, row[2].value, row[3].value, row[4].value)
  File "C:\Users\rjwal_000\PycharmProjects\Survey Assist\job_tracker.py", line 68, in __init__
    self.survey_date = survey_date.strftime('%d/%m/%Y')
AttributeError: 'str' object has no attribute 'strftime'
2020-06-14 20:01:47,346:Survey Assist - v1.0:Error has occurred in JobTracker init().

'str' object has no attribute 'strftime'
Traceback (most recent call last):
  File "C:\Users\rjwal_000\PycharmProjects\Survey Assist\job_tracker.py", line 20, in __init__
    self.create_list_of_job_tracker_jobs()
  File "C:\Users\rjwal_000\PycharmProjects\Survey Assist\job_tracker.py", line 44, in create_list_of_job_tracker_jobs
    survey_job = SurveyJob(row[0].value, survey_date, row[2].value, row[3].value, row[4].value)
  File "C:\Users\rjwal_000\PycharmProjects\Survey Assist\job_tracker.py", line 68, in __init__
    self.survey_date = survey_date.strftime('%d/%m/%Y')
AttributeError: 'str' object has no attribute 'strftime'
2020-06-14 20:04:05,356:Survey Assist - v1.0:Started Application

2020-06-14 20:05:38,509:Survey Assist - v1.0:Started Application

2020-06-14 20:17:45,041:Survey Assist - v1.0:Started Application

2020-06-14 20:17:52,226:Survey Assist - v1.0:Error has occurred in JobTracker init().

'module' object has no attribute 'strptime'
Traceback (most recent call last):
  File "C:/Users/rjwal_000/PycharmProjects/Survey Assist/main.py", line 2174, in save_job_to_excel
    actions_sheet["B11"] = datetime.strptime(date_string, "%d/%m/%Y")
AttributeError: 'module' object has no attribute 'strptime'
2020-06-14 20:20:59,344:Survey Assist - v1.0:Started Application

2020-06-14 20:21:02,943:Survey Assist - v1.0:Error has occurred in JobTracker init().

'module' object has no attribute 'strptime'
Traceback (most recent call last):
  File "C:/Users/rjwal_000/PycharmProjects/Survey Assist/main.py", line 2174, in save_job_to_excel
    actions_sheet["B11"] = datetime.strptime(date_string, "%d/%m/%Y")
AttributeError: 'module' object has no attribute 'strptime'
2020-06-14 20:22:06,508:Survey Assist - v1.0:Started Application

2020-06-14 20:24:57,823:Survey Assist - v1.0:Error has occurred in JobTracker init().

'module' object has no attribute 'strptime'
Traceback (most recent call last):
  File "C:/Users/rjwal_000/PycharmProjects/Survey Assist/main.py", line 2174, in save_job_to_excel
    actions_sheet["B11"] = datetime.strptime(date_string, "%d/%m/%Y")
AttributeError: 'module' object has no attribute 'strptime'
2020-06-14 20:27:08,062:Survey Assist - v1.0:Started Application

2020-06-14 20:30:40,487:Survey Assist - v1.0:Started Application

2020-06-14 20:30:45,942:Survey Assist - v1.0:Job Tracker excel spreadsheet currently in use

[Errno 13] Permission denied: 'C:\\Users\\rjwal_000\\PycharmProjects\\Survey Assist\\Test Files\\Survey Data\\2020\\Job Tracker Digital System.xlsm'
Traceback (most recent call last):
  File "C:/Users/rjwal_000/PycharmProjects/Survey Assist/main.py", line 2226, in save_job_to_excel
    workbook.save(filename=self.job_tracker_filepath)
  File "C:\Python34\lib\site-packages\openpyxl\workbook\workbook.py", line 391, in save
    save_workbook(self, filename)
  File "C:\Python34\lib\site-packages\openpyxl\writer\excel.py", line 282, in save_workbook
    archive = ZipFile(filename, 'w', ZIP_DEFLATED, allowZip64=True)
  File "C:\Python34\lib\zipfile.py", line 923, in __init__
    self.fp = io.open(file, modeDict[mode])
PermissionError: [Errno 13] Permission denied: 'C:\\Users\\rjwal_000\\PycharmProjects\\Survey Assist\\Test Files\\Survey Data\\2020\\Job Tracker Digital System.xlsm'
2020-06-14 20:31:54,755:Survey Assist - v1.0:Started Application

2020-06-14 20:31:59,526:Survey Assist - v1.0:Error has occurred in JobTracker init().

'str' object has no attribute 'strftime'
Traceback (most recent call last):
  File "C:\Users\rjwal_000\PycharmProjects\Survey Assist\job_tracker.py", line 20, in __init__
    self.create_list_of_job_tracker_jobs()
  File "C:\Users\rjwal_000\PycharmProjects\Survey Assist\job_tracker.py", line 44, in create_list_of_job_tracker_jobs
    survey_job = SurveyJob(row[0].value, survey_date, row[2].value, row[3].value, row[4].value)
  File "C:\Users\rjwal_000\PycharmProjects\Survey Assist\job_tracker.py", line 68, in __init__
    self.survey_date = survey_date.strftime('%d/%m/%Y')
AttributeError: 'str' object has no attribute 'strftime'
2020-06-14 20:32:00,601:Survey Assist - v1.0:Error has occurred in JobTracker init().

'str' object has no attribute 'strftime'
Traceback (most recent call last):
  File "C:\Users\rjwal_000\PycharmProjects\Survey Assist\job_tracker.py", line 20, in __init__
    self.create_list_of_job_tracker_jobs()
  File "C:\Users\rjwal_000\PycharmProjects\Survey Assist\job_tracker.py", line 44, in create_list_of_job_tracker_jobs
    survey_job = SurveyJob(row[0].value, survey_date, row[2].value, row[3].value, row[4].value)
  File "C:\Users\rjwal_000\PycharmProjects\Survey Assist\job_tracker.py", line 68, in __init__
    self.survey_date = survey_date.strftime('%d/%m/%Y')
AttributeError: 'str' object has no attribute 'strftime'
2020-06-14 20:33:04,222:Survey Assist - v1.0:Started Application

2020-06-14 20:33:04,266:Survey Assist - v1.0:Error has occurred in JobTracker init().

'str' object has no attribute 'strftime'
Traceback (most recent call last):
  File "C:\Users\rjwal_000\PycharmProjects\Survey Assist\job_tracker.py", line 20, in __init__
    self.create_list_of_job_tracker_jobs()
  File "C:\Users\rjwal_000\PycharmProjects\Survey Assist\job_tracker.py", line 44, in create_list_of_job_tracker_jobs
    survey_job = SurveyJob(row[0].value, survey_date, row[2].value, row[3].value, row[4].value)
  File "C:\Users\rjwal_000\PycharmProjects\Survey Assist\job_tracker.py", line 68, in __init__
    self.survey_date = survey_date.strftime('%d/%m/%Y')
AttributeError: 'str' object has no attribute 'strftime'
2020-06-14 20:33:06,152:Survey Assist - v1.0:Error has occurred in JobTracker init().

'str' object has no attribute 'strftime'
Traceback (most recent call last):
  File "C:\Users\rjwal_000\PycharmProjects\Survey Assist\job_tracker.py", line 20, in __init__
    self.create_list_of_job_tracker_jobs()
  File "C:\Users\rjwal_000\PycharmProjects\Survey Assist\job_tracker.py", line 44, in create_list_of_job_tracker_jobs
    survey_job = SurveyJob(row[0].value, survey_date, row[2].value, row[3].value, row[4].value)
  File "C:\Users\rjwal_000\PycharmProjects\Survey Assist\job_tracker.py", line 68, in __init__
    self.survey_date = survey_date.strftime('%d/%m/%Y')
AttributeError: 'str' object has no attribute 'strftime'
2020-06-14 20:37:28,358:Survey Assist - v1.0:Started Application

2020-06-14 20:37:28,392:Survey Assist - v1.0:Error has occurred in JobTracker init().

'str' object has no attribute 'strftime'
Traceback (most recent call last):
  File "C:\Users\rjwal_000\PycharmProjects\Survey Assist\job_tracker.py", line 20, in __init__
    self.create_list_of_job_tracker_jobs()
  File "C:\Users\rjwal_000\PycharmProjects\Survey Assist\job_tracker.py", line 44, in create_list_of_job_tracker_jobs
    survey_job = SurveyJob(row[0].value, survey_date, row[2].value, row[3].value, row[4].value)
  File "C:\Users\rjwal_000\PycharmProjects\Survey Assist\job_tracker.py", line 68, in __init__
    self.survey_date = survey_date.strftime('%d/%m/%Y')
AttributeError: 'str' object has no attribute 'strftime'
2020-06-14 20:37:30,531:Survey Assist - v1.0:Error has occurred in JobTracker init().

'str' object has no attribute 'strftime'
Traceback (most recent call last):
  File "C:\Users\rjwal_000\PycharmProjects\Survey Assist\job_tracker.py", line 20, in __init__
    self.create_list_of_job_tracker_jobs()
  File "C:\Users\rjwal_000\PycharmProjects\Survey Assist\job_tracker.py", line 44, in create_list_of_job_tracker_jobs
    survey_job = SurveyJob(row[0].value, survey_date, row[2].value, row[3].value, row[4].value)
  File "C:\Users\rjwal_000\PycharmProjects\Survey Assist\job_tracker.py", line 68, in __init__
    self.survey_date = survey_date.strftime('%d/%m/%Y')
AttributeError: 'str' object has no attribute 'strftime'
2020-06-14 20:37:49,388:Survey Assist - v1.0:Started Application

2020-06-15 16:34:00,688:Survey Assist - v1.0:Started Application

2020-06-15 16:34:41,313:Survey Assist - v1.0:Started Application

2020-06-16 19:27:11,333:Survey Assist - v1.0:Started Application

2020-06-16 19:27:11,342:Survey Assist - v1.0:Started Application

2020-06-16 19:27:22,022:Survey Assist - v1.0:Started Application

2020-06-18 09:40:57,360:Survey Assist - v1.0:Started Application

2020-06-18 09:41:42,220:Survey Assist - v1.0:Error has occurred in JobTracker init().

'str' object has no attribute 'strftime'
Traceback (most recent call last):
  File "C:\Users\rjwal_000\PycharmProjects\Survey Assist\job_tracker.py", line 20, in __init__
    self.create_list_of_job_tracker_jobs()
  File "C:\Users\rjwal_000\PycharmProjects\Survey Assist\job_tracker.py", line 44, in create_list_of_job_tracker_jobs
    survey_job = SurveyJob(row[0].value, survey_date, row[2].value, row[3].value, row[4].value)
  File "C:\Users\rjwal_000\PycharmProjects\Survey Assist\job_tracker.py", line 68, in __init__
    self.survey_date = survey_date.strftime('%d/%m/%Y')
AttributeError: 'str' object has no attribute 'strftime'
2020-06-18 09:41:47,080:Survey Assist - v1.0:Error has occurred in JobTracker init().

'str' object has no attribute 'strftime'
Traceback (most recent call last):
  File "C:\Users\rjwal_000\PycharmProjects\Survey Assist\job_tracker.py", line 20, in __init__
    self.create_list_of_job_tracker_jobs()
  File "C:\Users\rjwal_000\PycharmProjects\Survey Assist\job_tracker.py", line 44, in create_list_of_job_tracker_jobs
    survey_job = SurveyJob(row[0].value, survey_date, row[2].value, row[3].value, row[4].value)
  File "C:\Users\rjwal_000\PycharmProjects\Survey Assist\job_tracker.py", line 68, in __init__
    self.survey_date = survey_date.strftime('%d/%m/%Y')
AttributeError: 'str' object has no attribute 'strftime'
2020-06-18 09:44:09,393:Survey Assist - v1.0:Started Application

2020-06-18 09:44:09,436:Survey Assist - v1.0:Error has occurred in JobTracker init().

'str' object has no attribute 'strftime'
Traceback (most recent call last):
  File "C:\Users\rjwal_000\PycharmProjects\Survey Assist\job_tracker.py", line 20, in __init__
    self.create_list_of_job_tracker_jobs()
  File "C:\Users\rjwal_000\PycharmProjects\Survey Assist\job_tracker.py", line 44, in create_list_of_job_tracker_jobs
    survey_job = SurveyJob(row[0].value, survey_date, row[2].value, row[3].value, row[4].value)
  File "C:\Users\rjwal_000\PycharmProjects\Survey Assist\job_tracker.py", line 68, in __init__
    self.survey_date = survey_date.strftime('%d/%m/%Y')
AttributeError: 'str' object has no attribute 'strftime'
2020-06-18 09:44:11,521:Survey Assist - v1.0:Error has occurred in JobTracker init().

'str' object has no attribute 'strftime'
Traceback (most recent call last):
  File "C:\Users\rjwal_000\PycharmProjects\Survey Assist\job_tracker.py", line 20, in __init__
    self.create_list_of_job_tracker_jobs()
  File "C:\Users\rjwal_000\PycharmProjects\Survey Assist\job_tracker.py", line 44, in create_list_of_job_tracker_jobs
    survey_job = SurveyJob(row[0].value, survey_date, row[2].value, row[3].value, row[4].value)
  File "C:\Users\rjwal_000\PycharmProjects\Survey Assist\job_tracker.py", line 68, in __init__
    self.survey_date = survey_date.strftime('%d/%m/%Y')
AttributeError: 'str' object has no attribute 'strftime'
2020-06-18 09:46:36,407:Survey Assist - v1.0:Started Application

2020-06-18 09:46:36,452:Survey Assist - v1.0:Error has occurred in JobTracker init().

'str' object has no attribute 'strftime'
Traceback (most recent call last):
  File "C:\Users\rjwal_000\PycharmProjects\Survey Assist\job_tracker.py", line 20, in __init__
    self.create_list_of_job_tracker_jobs()
  File "C:\Users\rjwal_000\PycharmProjects\Survey Assist\job_tracker.py", line 44, in create_list_of_job_tracker_jobs
    survey_job = SurveyJob(row[0].value, survey_date, row[2].value, row[3].value, row[4].value)
  File "C:\Users\rjwal_000\PycharmProjects\Survey Assist\job_tracker.py", line 68, in __init__
    self.survey_date = survey_date.strftime('%d/%m/%Y')
AttributeError: 'str' object has no attribute 'strftime'
2020-06-18 09:47:19,541:Survey Assist - v1.0:Started Application

2020-06-18 09:47:19,576:Survey Assist - v1.0:Error has occurred in JobTracker init().

'str' object has no attribute 'strftime'
Traceback (most recent call last):
  File "C:\Users\rjwal_000\PycharmProjects\Survey Assist\job_tracker.py", line 20, in __init__
    self.create_list_of_job_tracker_jobs()
  File "C:\Users\rjwal_000\PycharmProjects\Survey Assist\job_tracker.py", line 44, in create_list_of_job_tracker_jobs
    survey_job = SurveyJob(row[0].value, survey_date, row[2].value, row[3].value, row[4].value)
  File "C:\Users\rjwal_000\PycharmProjects\Survey Assist\job_tracker.py", line 68, in __init__
    self.survey_date = survey_date.strftime('%d/%m/%Y')
AttributeError: 'str' object has no attribute 'strftime'
2020-06-18 09:47:20,679:Survey Assist - v1.0:Error has occurred in JobTracker init().

'str' object has no attribute 'strftime'
Traceback (most recent call last):
  File "C:\Users\rjwal_000\PycharmProjects\Survey Assist\job_tracker.py", line 20, in __init__
    self.create_list_of_job_tracker_jobs()
  File "C:\Users\rjwal_000\PycharmProjects\Survey Assist\job_tracker.py", line 44, in create_list_of_job_tracker_jobs
    survey_job = SurveyJob(row[0].value, survey_date, row[2].value, row[3].value, row[4].value)
  File "C:\Users\rjwal_000\PycharmProjects\Survey Assist\job_tracker.py", line 68, in __init__
    self.survey_date = survey_date.strftime('%d/%m/%Y')
AttributeError: 'str' object has no attribute 'strftime'
2020-06-18 09:48:32,341:Survey Assist - v1.0:Started Application

2020-06-18 09:48:41,694:Survey Assist - v1.0:Error has occurred in JobTracker init().

'str' object has no attribute 'strftime'
Traceback (most recent call last):
  File "C:\Users\rjwal_000\PycharmProjects\Survey Assist\job_tracker.py", line 20, in __init__
    self.create_list_of_job_tracker_jobs()
  File "C:\Users\rjwal_000\PycharmProjects\Survey Assist\job_tracker.py", line 44, in create_list_of_job_tracker_jobs
    survey_job = SurveyJob(row[0].value, survey_date, row[2].value, row[3].value, row[4].value)
  File "C:\Users\rjwal_000\PycharmProjects\Survey Assist\job_tracker.py", line 68, in __init__
    self.survey_date = survey_date.strftime('%d/%m/%Y')
AttributeError: 'str' object has no attribute 'strftime'
2020-06-18 09:48:43,712:Survey Assist - v1.0:Error has occurred in JobTracker init().

'str' object has no attribute 'strftime'
Traceback (most recent call last):
  File "C:\Users\rjwal_000\PycharmProjects\Survey Assist\job_tracker.py", line 20, in __init__
    self.create_list_of_job_tracker_jobs()
  File "C:\Users\rjwal_000\PycharmProjects\Survey Assist\job_tracker.py", line 44, in create_list_of_job_tracker_jobs
    survey_job = SurveyJob(row[0].value, survey_date, row[2].value, row[3].value, row[4].value)
  File "C:\Users\rjwal_000\PycharmProjects\Survey Assist\job_tracker.py", line 68, in __init__
    self.survey_date = survey_date.strftime('%d/%m/%Y')
AttributeError: 'str' object has no attribute 'strftime'
2020-06-18 09:51:40,592:Survey Assist - v1.0:Started Application

2020-06-18 09:51:40,624:Survey Assist - v1.0:Error has occurred in create_list_of_job_tracker_jobs.

'str' object has no attribute 'strftime'
Traceback (most recent call last):
  File "C:\Users\rjwal_000\PycharmProjects\Survey Assist\job_tracker.py", line 46, in create_list_of_job_tracker_jobs
    survey_job = SurveyJob(row[0].value, survey_date, row[2].value, row[3].value, row[4].value)
  File "C:\Users\rjwal_000\PycharmProjects\Survey Assist\job_tracker.py", line 76, in __init__
    self.survey_date = survey_date.strftime('%d/%m/%Y')
AttributeError: 'str' object has no attribute 'strftime'
2020-06-18 09:52:24,772:Survey Assist - v1.0:Started Application

2020-06-18 09:52:24,805:Survey Assist - v1.0:Error has occurred in create_list_of_job_tracker_jobs.

'str' object has no attribute 'strftime'
Traceback (most recent call last):
  File "C:\Users\rjwal_000\PycharmProjects\Survey Assist\job_tracker.py", line 46, in create_list_of_job_tracker_jobs
    survey_job = SurveyJob(row[0].value, survey_date, row[2].value, row[3].value, row[4].value)
  File "C:\Users\rjwal_000\PycharmProjects\Survey Assist\job_tracker.py", line 77, in __init__
    self.survey_date = survey_date.strftime('%d/%m/%Y')
AttributeError: 'str' object has no attribute 'strftime'
2020-06-18 09:52:38,343:Survey Assist - v1.0:Started Application

2020-06-18 09:52:38,375:Survey Assist - v1.0:Error has occurred in create_list_of_job_tracker_jobs.

'str' object has no attribute 'strftime'
Traceback (most recent call last):
  File "C:\Users\rjwal_000\PycharmProjects\Survey Assist\job_tracker.py", line 46, in create_list_of_job_tracker_jobs
    survey_job = SurveyJob(row[0].value, survey_date, row[2].value, row[3].value, row[4].value)
  File "C:\Users\rjwal_000\PycharmProjects\Survey Assist\job_tracker.py", line 77, in __init__
    self.survey_date = survey_date.strftime('%d/%m/%Y')
AttributeError: 'str' object has no attribute 'strftime'
2020-06-18 09:53:15,822:Survey Assist - v1.0:Started Application

2020-06-18 09:53:15,854:Survey Assist - v1.0:Error has occurred in create_list_of_job_tracker_jobs.

'str' object has no attribute 'strftime'
Traceback (most recent call last):
  File "C:\Users\rjwal_000\PycharmProjects\Survey Assist\job_tracker.py", line 46, in create_list_of_job_tracker_jobs
    survey_job = SurveyJob(row[0].value, survey_date, row[2].value, row[3].value, row[4].value)
  File "C:\Users\rjwal_000\PycharmProjects\Survey Assist\job_tracker.py", line 78, in __init__
    self.survey_date = survey_date.strftime('%d/%m/%Y')
AttributeError: 'str' object has no attribute 'strftime'
2020-06-18 09:56:51,421:Survey Assist - v1.0:Started Application

2020-06-18 09:56:51,468:Survey Assist - v1.0:Error has occurred in create_list_of_job_tracker_jobs.

'str' object has no attribute 'strftime'
Traceback (most recent call last):
  File "C:\Users\rjwal_000\PycharmProjects\Survey Assist\job_tracker.py", line 46, in create_list_of_job_tracker_jobs
    survey_job = SurveyJob(row[0].value, survey_date, row[2].value, row[3].value, row[4].value)
  File "C:\Users\rjwal_000\PycharmProjects\Survey Assist\job_tracker.py", line 78, in __init__
    self.survey_date = survey_date.strftime('%d/%m/%Y')
AttributeError: 'str' object has no attribute 'strftime'
2020-06-18 09:57:29,104:Survey Assist - v1.0:Started Application

2020-06-18 09:57:29,145:Survey Assist - v1.0:Error has occurred in create_list_of_job_tracker_jobs.

'str' object has no attribute 'strftime'
Traceback (most recent call last):
  File "C:\Users\rjwal_000\PycharmProjects\Survey Assist\job_tracker.py", line 46, in create_list_of_job_tracker_jobs
    survey_job = SurveyJob(row[0].value, survey_date, row[2].value, row[3].value, row[4].value)
  File "C:\Users\rjwal_000\PycharmProjects\Survey Assist\job_tracker.py", line 78, in __init__
    self.survey_date = survey_date.strftime('%d/%m/%Y')
AttributeError: 'str' object has no attribute 'strftime'
2020-06-18 09:58:41,524:Survey Assist - v1.0:Started Application

2020-06-18 09:58:41,555:Survey Assist - v1.0:Error has occurred in create_list_of_job_tracker_jobs.

'str' object has no attribute 'strftime'
Traceback (most recent call last):
  File "C:\Users\rjwal_000\PycharmProjects\Survey Assist\job_tracker.py", line 46, in create_list_of_job_tracker_jobs
    survey_job = SurveyJob(row[0].value, survey_date, row[2].value, row[3].value, row[4].value)
  File "C:\Users\rjwal_000\PycharmProjects\Survey Assist\job_tracker.py", line 78, in __init__
    self.survey_date = survey_date.strftime('%d/%m/%Y')
AttributeError: 'str' object has no attribute 'strftime'
2020-06-18 09:59:47,194:Survey Assist - v1.0:Started Application

2020-06-18 10:01:12,070:Survey Assist - v1.0:Started Application

2020-06-18 10:01:12,116:Survey Assist - v1.0:Error has occurred in create_list_of_job_tracker_jobs.

'str' object has no attribute 'strftime'
Traceback (most recent call last):
  File "C:\Users\rjwal_000\PycharmProjects\Survey Assist\job_tracker.py", line 46, in create_list_of_job_tracker_jobs
    survey_job = SurveyJob(row[0].value, survey_date, row[2].value, row[3].value, row[4].value)
  File "C:\Users\rjwal_000\PycharmProjects\Survey Assist\job_tracker.py", line 78, in __init__
    self.survey_date = survey_date.strftime('%d/%m/%Y')
AttributeError: 'str' object has no attribute 'strftime'
2020-06-18 10:03:04,184:Survey Assist - v1.0:Started Application

2020-06-18 10:03:04,219:Survey Assist - v1.0:Error has occurred in create_list_of_job_tracker_jobs.

'str' object has no attribute 'strftime'
Traceback (most recent call last):
  File "C:\Users\rjwal_000\PycharmProjects\Survey Assist\job_tracker.py", line 46, in create_list_of_job_tracker_jobs
    survey_job = SurveyJob(row[0].value, survey_date, row[2].value, row[3].value, row[4].value)
  File "C:\Users\rjwal_000\PycharmProjects\Survey Assist\job_tracker.py", line 78, in __init__
    self.survey_date = survey_date.strftime('%d/%m/%Y')
AttributeError: 'str' object has no attribute 'strftime'
2020-06-18 10:03:57,938:Survey Assist - v1.0:Started Application

2020-06-18 10:03:57,996:Survey Assist - v1.0:Error has occurred in create_list_of_job_tracker_jobs.

'str' object has no attribute 'strftime'
Traceback (most recent call last):
  File "C:\Users\rjwal_000\PycharmProjects\Survey Assist\job_tracker.py", line 46, in create_list_of_job_tracker_jobs
    survey_job = SurveyJob(row[0].value, survey_date, row[2].value, row[3].value, row[4].value)
  File "C:\Users\rjwal_000\PycharmProjects\Survey Assist\job_tracker.py", line 78, in __init__
    self.survey_date = survey_date.strftime('%d/%m/%Y')
AttributeError: 'str' object has no attribute 'strftime'
2020-06-18 10:04:21,359:Survey Assist - v1.0:Started Application

2020-06-18 10:04:21,397:Survey Assist - v1.0:Error has occurred in create_list_of_job_tracker_jobs.

'str' object has no attribute 'strftime'
Traceback (most recent call last):
  File "C:\Users\rjwal_000\PycharmProjects\Survey Assist\job_tracker.py", line 46, in create_list_of_job_tracker_jobs
    survey_job = SurveyJob(row[0].value, survey_date, row[2].value, row[3].value, row[4].value)
  File "C:\Users\rjwal_000\PycharmProjects\Survey Assist\job_tracker.py", line 78, in __init__
    self.survey_date = survey_date.strftime('%d/%m/%Y')
AttributeError: 'str' object has no attribute 'strftime'
2020-06-18 10:10:26,354:Survey Assist - v1.0:Started Application

2020-06-18 10:10:26,388:Survey Assist - v1.0:Error has occurred in create_list_of_job_tracker_jobs.

'str' object has no attribute 'strftime'
Traceback (most recent call last):
  File "C:\Users\rjwal_000\PycharmProjects\Survey Assist\job_tracker.py", line 46, in create_list_of_job_tracker_jobs
    survey_job = SurveyJob(row[0].value, survey_date, row[2].value, row[3].value, row[4].value)
  File "C:\Users\rjwal_000\PycharmProjects\Survey Assist\job_tracker.py", line 78, in __init__
    self.survey_date = survey_date.strftime('%d/%m/%Y')
AttributeError: 'str' object has no attribute 'strftime'
2020-06-18 10:11:01,743:Survey Assist - v1.0:Started Application

2020-06-18 10:11:07,402:Survey Assist - v1.0:Job Tracker excel spreadsheet currently in use

[Errno 13] Permission denied: 'C:\\Users\\rjwal_000\\PycharmProjects\\Survey Assist\\Test Files\\Survey Data\\2020\\Job Tracker Digital System.xlsm'
Traceback (most recent call last):
  File "C:/Users/rjwal_000/PycharmProjects/Survey Assist/main.py", line 2240, in save_job_to_excel
    workbook.save(filename=self.job_tracker_filepath)
  File "C:\Python34\lib\site-packages\openpyxl\workbook\workbook.py", line 391, in save
    save_workbook(self, filename)
  File "C:\Python34\lib\site-packages\openpyxl\writer\excel.py", line 282, in save_workbook
    archive = ZipFile(filename, 'w', ZIP_DEFLATED, allowZip64=True)
  File "C:\Python34\lib\zipfile.py", line 923, in __init__
    self.fp = io.open(file, modeDict[mode])
PermissionError: [Errno 13] Permission denied: 'C:\\Users\\rjwal_000\\PycharmProjects\\Survey Assist\\Test Files\\Survey Data\\2020\\Job Tracker Digital System.xlsm'
2020-06-18 10:11:14,168:Survey Assist - v1.0:Error has occurred in create_list_of_job_tracker_jobs.

'str' object has no attribute 'strftime'
Traceback (most recent call last):
  File "C:\Users\rjwal_000\PycharmProjects\Survey Assist\job_tracker.py", line 46, in create_list_of_job_tracker_jobs
    survey_job = SurveyJob(row[0].value, survey_date, row[2].value, row[3].value, row[4].value)
  File "C:\Users\rjwal_000\PycharmProjects\Survey Assist\job_tracker.py", line 78, in __init__
    self.survey_date = survey_date.strftime('%d/%m/%Y')
AttributeError: 'str' object has no attribute 'strftime'
2020-06-18 10:11:15,808:Survey Assist - v1.0:Error has occurred in create_list_of_job_tracker_jobs.

'str' object has no attribute 'strftime'
Traceback (most recent call last):
  File "C:\Users\rjwal_000\PycharmProjects\Survey Assist\job_tracker.py", line 46, in create_list_of_job_tracker_jobs
    survey_job = SurveyJob(row[0].value, survey_date, row[2].value, row[3].value, row[4].value)
  File "C:\Users\rjwal_000\PycharmProjects\Survey Assist\job_tracker.py", line 78, in __init__
    self.survey_date = survey_date.strftime('%d/%m/%Y')
AttributeError: 'str' object has no attribute 'strftime'
2020-06-18 10:12:38,238:Survey Assist - v1.0:Started Application

2020-06-18 10:13:39,140:Survey Assist - v1.0:Started Application

2020-06-18 10:13:39,177:Survey Assist - v1.0:Error has occurred in JobTracker init().

'str' object has no attribute 'strftime'
Traceback (most recent call last):
  File "C:\Users\rjwal_000\PycharmProjects\Survey Assist\job_tracker.py", line 20, in __init__
    self.create_list_of_job_tracker_jobs()
  File "C:\Users\rjwal_000\PycharmProjects\Survey Assist\job_tracker.py", line 44, in create_list_of_job_tracker_jobs
    survey_job = SurveyJob(row[0].value, survey_date, row[2].value, row[3].value, row[4].value)
  File "C:\Users\rjwal_000\PycharmProjects\Survey Assist\job_tracker.py", line 68, in __init__
    self.survey_date = survey_date.strftime('%d/%m/%Y')
AttributeError: 'str' object has no attribute 'strftime'
2020-06-18 10:16:06,384:Survey Assist - v1.0:Started Application

2020-06-18 10:16:35,723:Survey Assist - v1.0:Error has occurred in JobTracker init().

Style date_style exists already
Traceback (most recent call last):
  File "C:/Users/rjwal_000/PycharmProjects/Survey Assist/main.py", line 2174, in save_job_to_excel
    workbook.add_named_style(date_style)
  File "C:\Python34\lib\site-packages\openpyxl\workbook\workbook.py", line 327, in add_named_style
    self._named_styles.append(style)
  File "C:\Python34\lib\site-packages\openpyxl\styles\named_styles.py", line 194, in append
    raise ValueError("""Style {0} exists already""".format(style.name))
ValueError: Style date_style exists already
2020-06-18 10:19:08,930:Survey Assist - v1.0:Started Application

2020-06-18 10:19:16,499:Survey Assist - v1.0:Error has occurred in JobTracker init().

'str' object has no attribute 'strftime'
Traceback (most recent call last):
  File "C:\Users\rjwal_000\PycharmProjects\Survey Assist\job_tracker.py", line 20, in __init__
    self.create_list_of_job_tracker_jobs()
  File "C:\Users\rjwal_000\PycharmProjects\Survey Assist\job_tracker.py", line 44, in create_list_of_job_tracker_jobs
    survey_job = SurveyJob(row[0].value, survey_date, row[2].value, row[3].value, row[4].value)
  File "C:\Users\rjwal_000\PycharmProjects\Survey Assist\job_tracker.py", line 68, in __init__
    self.survey_date = survey_date.strftime('%d/%m/%Y')
AttributeError: 'str' object has no attribute 'strftime'
2020-06-18 10:19:17,678:Survey Assist - v1.0:Error has occurred in JobTracker init().

'str' object has no attribute 'strftime'
Traceback (most recent call last):
  File "C:\Users\rjwal_000\PycharmProjects\Survey Assist\job_tracker.py", line 20, in __init__
    self.create_list_of_job_tracker_jobs()
  File "C:\Users\rjwal_000\PycharmProjects\Survey Assist\job_tracker.py", line 44, in create_list_of_job_tracker_jobs
    survey_job = SurveyJob(row[0].value, survey_date, row[2].value, row[3].value, row[4].value)
  File "C:\Users\rjwal_000\PycharmProjects\Survey Assist\job_tracker.py", line 68, in __init__
    self.survey_date = survey_date.strftime('%d/%m/%Y')
AttributeError: 'str' object has no attribute 'strftime'
2020-06-18 10:19:32,282:Survey Assist - v1.0:Started Application

2020-06-18 10:19:32,350:Survey Assist - v1.0:Error has occurred in JobTracker init().

'str' object has no attribute 'strftime'
Traceback (most recent call last):
  File "C:\Users\rjwal_000\PycharmProjects\Survey Assist\job_tracker.py", line 20, in __init__
    self.create_list_of_job_tracker_jobs()
  File "C:\Users\rjwal_000\PycharmProjects\Survey Assist\job_tracker.py", line 44, in create_list_of_job_tracker_jobs
    survey_job = SurveyJob(row[0].value, survey_date, row[2].value, row[3].value, row[4].value)
  File "C:\Users\rjwal_000\PycharmProjects\Survey Assist\job_tracker.py", line 68, in __init__
    self.survey_date = survey_date.strftime('%d/%m/%Y')
AttributeError: 'str' object has no attribute 'strftime'
2020-06-18 10:20:00,427:Survey Assist - v1.0:Started Application

2020-06-18 10:21:09,351:Survey Assist - v1.0:Error has occurred in JobTracker init().

'str' object has no attribute 'strftime'
Traceback (most recent call last):
  File "C:\Users\rjwal_000\PycharmProjects\Survey Assist\job_tracker.py", line 20, in __init__
    self.create_list_of_job_tracker_jobs()
  File "C:\Users\rjwal_000\PycharmProjects\Survey Assist\job_tracker.py", line 44, in create_list_of_job_tracker_jobs
    survey_job = SurveyJob(row[0].value, survey_date, row[2].value, row[3].value, row[4].value)
  File "C:\Users\rjwal_000\PycharmProjects\Survey Assist\job_tracker.py", line 68, in __init__
    self.survey_date = survey_date.strftime('%d/%m/%Y')
AttributeError: 'str' object has no attribute 'strftime'
2020-06-18 10:22:37,142:Survey Assist - v1.0:Error has occurred in JobTracker init().

'str' object has no attribute 'strftime'
Traceback (most recent call last):
  File "C:\Users\rjwal_000\PycharmProjects\Survey Assist\job_tracker.py", line 20, in __init__
    self.create_list_of_job_tracker_jobs()
  File "C:\Users\rjwal_000\PycharmProjects\Survey Assist\job_tracker.py", line 44, in create_list_of_job_tracker_jobs
    survey_job = SurveyJob(row[0].value, survey_date, row[2].value, row[3].value, row[4].value)
  File "C:\Users\rjwal_000\PycharmProjects\Survey Assist\job_tracker.py", line 68, in __init__
    self.survey_date = survey_date.strftime('%d/%m/%Y')
AttributeError: 'str' object has no attribute 'strftime'
2020-06-18 10:25:42,447:Survey Assist - v1.0:Started Application

2020-06-18 10:26:30,655:Survey Assist - v1.0:Started Application

2020-06-18 10:26:30,689:Survey Assist - v1.0:Error has occurred in JobTracker init().

'str' object has no attribute 'strftime'
Traceback (most recent call last):
  File "C:\Users\rjwal_000\PycharmProjects\Survey Assist\job_tracker.py", line 20, in __init__
    self.create_list_of_job_tracker_jobs()
  File "C:\Users\rjwal_000\PycharmProjects\Survey Assist\job_tracker.py", line 44, in create_list_of_job_tracker_jobs
    survey_job = SurveyJob(row[0].value, survey_date, row[2].value, row[3].value, row[4].value)
  File "C:\Users\rjwal_000\PycharmProjects\Survey Assist\job_tracker.py", line 68, in __init__
    self.survey_date = survey_date.strftime('%d/%m/%Y')
AttributeError: 'str' object has no attribute 'strftime'
2020-06-18 10:26:49,251:Survey Assist - v1.0:Started Application

2020-06-18 10:26:54,074:Survey Assist - v1.0:Job Tracker excel spreadsheet currently in use

[Errno 13] Permission denied: 'C:\\Users\\rjwal_000\\PycharmProjects\\Survey Assist\\Test Files\\Survey Data\\2020\\Job Tracker Digital System.xlsm'
Traceback (most recent call last):
  File "C:/Users/rjwal_000/PycharmProjects/Survey Assist/main.py", line 2240, in save_job_to_excel
    workbook.save(filename=self.job_tracker_filepath)
  File "C:\Python34\lib\site-packages\openpyxl\workbook\workbook.py", line 391, in save
    save_workbook(self, filename)
  File "C:\Python34\lib\site-packages\openpyxl\writer\excel.py", line 282, in save_workbook
    archive = ZipFile(filename, 'w', ZIP_DEFLATED, allowZip64=True)
  File "C:\Python34\lib\zipfile.py", line 923, in __init__
    self.fp = io.open(file, modeDict[mode])
PermissionError: [Errno 13] Permission denied: 'C:\\Users\\rjwal_000\\PycharmProjects\\Survey Assist\\Test Files\\Survey Data\\2020\\Job Tracker Digital System.xlsm'
2020-06-18 10:27:00,522:Survey Assist - v1.0:Error has occurred in JobTracker init().

'str' object has no attribute 'strftime'
Traceback (most recent call last):
  File "C:\Users\rjwal_000\PycharmProjects\Survey Assist\job_tracker.py", line 20, in __init__
    self.create_list_of_job_tracker_jobs()
  File "C:\Users\rjwal_000\PycharmProjects\Survey Assist\job_tracker.py", line 44, in create_list_of_job_tracker_jobs
    survey_job = SurveyJob(row[0].value, survey_date, row[2].value, row[3].value, row[4].value)
  File "C:\Users\rjwal_000\PycharmProjects\Survey Assist\job_tracker.py", line 68, in __init__
    self.survey_date = survey_date.strftime('%d/%m/%Y')
AttributeError: 'str' object has no attribute 'strftime'
2020-06-18 10:29:57,479:Survey Assist - v1.0:Started Application

2020-06-18 10:29:57,512:Survey Assist - v1.0:Error has occurred in JobTracker init().

'str' object has no attribute 'strftime'
Traceback (most recent call last):
  File "C:\Users\rjwal_000\PycharmProjects\Survey Assist\job_tracker.py", line 20, in __init__
    self.create_list_of_job_tracker_jobs()
  File "C:\Users\rjwal_000\PycharmProjects\Survey Assist\job_tracker.py", line 44, in create_list_of_job_tracker_jobs
    survey_job = SurveyJob(row[0].value, survey_date, row[2].value, row[3].value, row[4].value)
  File "C:\Users\rjwal_000\PycharmProjects\Survey Assist\job_tracker.py", line 68, in __init__
    self.survey_date = survey_date.strftime('%d/%m/%Y')
AttributeError: 'str' object has no attribute 'strftime'
2020-06-18 10:30:06,439:Survey Assist - v1.0:Started Application

2020-06-18 10:30:06,473:Survey Assist - v1.0:Error has occurred in JobTracker init().

'str' object has no attribute 'strftime'
Traceback (most recent call last):
  File "C:\Users\rjwal_000\PycharmProjects\Survey Assist\job_tracker.py", line 20, in __init__
    self.create_list_of_job_tracker_jobs()
  File "C:\Users\rjwal_000\PycharmProjects\Survey Assist\job_tracker.py", line 44, in create_list_of_job_tracker_jobs
    survey_job = SurveyJob(row[0].value, survey_date, row[2].value, row[3].value, row[4].value)
  File "C:\Users\rjwal_000\PycharmProjects\Survey Assist\job_tracker.py", line 68, in __init__
    self.survey_date = survey_date.strftime('%d/%m/%Y')
AttributeError: 'str' object has no attribute 'strftime'
2020-06-18 10:31:23,073:Survey Assist - v1.0:Started Application

2020-06-18 10:31:23,107:Survey Assist - v1.0:Error has occurred in JobTracker init().

'str' object has no attribute 'strftime'
Traceback (most recent call last):
  File "C:\Users\rjwal_000\PycharmProjects\Survey Assist\job_tracker.py", line 20, in __init__
    self.create_list_of_job_tracker_jobs()
  File "C:\Users\rjwal_000\PycharmProjects\Survey Assist\job_tracker.py", line 44, in create_list_of_job_tracker_jobs
    survey_job = SurveyJob(row[0].value, survey_date, row[2].value, row[3].value, row[4].value)
  File "C:\Users\rjwal_000\PycharmProjects\Survey Assist\job_tracker.py", line 68, in __init__
    self.survey_date = survey_date.strftime('%d/%m/%Y')
AttributeError: 'str' object has no attribute 'strftime'
2020-06-18 10:33:08,325:Survey Assist - v1.0:Started Application

2020-06-18 10:33:08,356:Survey Assist - v1.0:Error has occurred in JobTracker init().

'str' object has no attribute 'strftime'
Traceback (most recent call last):
  File "C:\Users\rjwal_000\PycharmProjects\Survey Assist\job_tracker.py", line 20, in __init__
    self.create_list_of_job_tracker_jobs()
  File "C:\Users\rjwal_000\PycharmProjects\Survey Assist\job_tracker.py", line 44, in create_list_of_job_tracker_jobs
    survey_job = SurveyJob(row[0].value, survey_date, row[2].value, row[3].value, row[4].value)
  File "C:\Users\rjwal_000\PycharmProjects\Survey Assist\job_tracker.py", line 68, in __init__
    self.survey_date = survey_date.strftime('%d/%m/%Y')
AttributeError: 'str' object has no attribute 'strftime'
2020-06-18 10:37:15,782:Survey Assist - v1.0:Started Application

2020-06-18 10:37:15,816:Survey Assist - v1.0:Error has occurred in JobTracker init().

'str' object has no attribute 'strftime'
Traceback (most recent call last):
  File "C:\Users\rjwal_000\PycharmProjects\Survey Assist\job_tracker.py", line 20, in __init__
    self.create_list_of_job_tracker_jobs()
  File "C:\Users\rjwal_000\PycharmProjects\Survey Assist\job_tracker.py", line 44, in create_list_of_job_tracker_jobs
    survey_job = SurveyJob(row[0].value, survey_date, row[2].value, row[3].value, row[4].value)
  File "C:\Users\rjwal_000\PycharmProjects\Survey Assist\job_tracker.py", line 68, in __init__
    self.survey_date = survey_date.strftime('%d/%m/%Y')
AttributeError: 'str' object has no attribute 'strftime'
2020-06-18 10:41:11,522:Survey Assist - v1.0:Started Application

2020-06-18 10:41:11,558:Survey Assist - v1.0:Error has occurred in JobTracker init().

'str' object has no attribute 'strftime'
Traceback (most recent call last):
  File "C:\Users\rjwal_000\PycharmProjects\Survey Assist\job_tracker.py", line 20, in __init__
    self.create_list_of_job_tracker_jobs()
  File "C:\Users\rjwal_000\PycharmProjects\Survey Assist\job_tracker.py", line 44, in create_list_of_job_tracker_jobs
    survey_job = SurveyJob(row[0].value, survey_date, row[2].value, row[3].value, row[4].value)
  File "C:\Users\rjwal_000\PycharmProjects\Survey Assist\job_tracker.py", line 68, in __init__
    self.survey_date = survey_date.strftime('%d/%m/%Y')
AttributeError: 'str' object has no attribute 'strftime'
2020-06-18 10:42:30,932:Survey Assist - v1.0:Started Application

2020-06-18 10:42:37,957:Survey Assist - v1.0:Job Tracker excel spreadsheet currently in use

[Errno 13] Permission denied: 'C:\\Users\\rjwal_000\\PycharmProjects\\Survey Assist\\Test Files\\Survey Data\\2020\\Job Tracker Digital System.xlsm'
Traceback (most recent call last):
  File "C:/Users/rjwal_000/PycharmProjects/Survey Assist/main.py", line 2242, in save_job_to_excel
    workbook.save(filename=self.job_tracker_filepath)
  File "C:\Python34\lib\site-packages\openpyxl\workbook\workbook.py", line 391, in save
    save_workbook(self, filename)
  File "C:\Python34\lib\site-packages\openpyxl\writer\excel.py", line 282, in save_workbook
    archive = ZipFile(filename, 'w', ZIP_DEFLATED, allowZip64=True)
  File "C:\Python34\lib\zipfile.py", line 923, in __init__
    self.fp = io.open(file, modeDict[mode])
PermissionError: [Errno 13] Permission denied: 'C:\\Users\\rjwal_000\\PycharmProjects\\Survey Assist\\Test Files\\Survey Data\\2020\\Job Tracker Digital System.xlsm'
2020-06-18 10:42:43,632:Survey Assist - v1.0:Error has occurred in JobTracker init().

'str' object has no attribute 'strftime'
Traceback (most recent call last):
  File "C:\Users\rjwal_000\PycharmProjects\Survey Assist\job_tracker.py", line 20, in __init__
    self.create_list_of_job_tracker_jobs()
  File "C:\Users\rjwal_000\PycharmProjects\Survey Assist\job_tracker.py", line 44, in create_list_of_job_tracker_jobs
    survey_job = SurveyJob(row[0].value, survey_date, row[2].value, row[3].value, row[4].value)
  File "C:\Users\rjwal_000\PycharmProjects\Survey Assist\job_tracker.py", line 68, in __init__
    self.survey_date = survey_date.strftime('%d/%m/%Y')
AttributeError: 'str' object has no attribute 'strftime'
2020-06-18 10:42:45,258:Survey Assist - v1.0:Error has occurred in JobTracker init().

No Job Names Found
Traceback (most recent call last):
  File "C:/Users/rjwal_000/PycharmProjects/Survey Assist/main.py", line 2247, in save_job_to_excel
    self.jt_job_name_combo['values'] = self.get_combobox_values()
  File "C:/Users/rjwal_000/PycharmProjects/Survey Assist/main.py", line 2130, in get_combobox_values
    raise Exception("No Job Names Found")
Exception: No Job Names Found
2020-06-18 10:44:39,324:Survey Assist - v1.0:Started Application

2020-06-18 10:44:54,302:Survey Assist - v1.0:Started Application

2020-06-18 10:45:00,599:Survey Assist - v1.0:Job Tracker excel spreadsheet currently in use

[Errno 13] Permission denied: 'C:\\Users\\rjwal_000\\PycharmProjects\\Survey Assist\\Test Files\\Survey Data\\2020\\Job Tracker Digital System.xlsm'
Traceback (most recent call last):
  File "C:/Users/rjwal_000/PycharmProjects/Survey Assist/main.py", line 2242, in save_job_to_excel
    workbook.save(filename=self.job_tracker_filepath)
  File "C:\Python34\lib\site-packages\openpyxl\workbook\workbook.py", line 391, in save
    save_workbook(self, filename)
  File "C:\Python34\lib\site-packages\openpyxl\writer\excel.py", line 282, in save_workbook
    archive = ZipFile(filename, 'w', ZIP_DEFLATED, allowZip64=True)
  File "C:\Python34\lib\zipfile.py", line 923, in __init__
    self.fp = io.open(file, modeDict[mode])
PermissionError: [Errno 13] Permission denied: 'C:\\Users\\rjwal_000\\PycharmProjects\\Survey Assist\\Test Files\\Survey Data\\2020\\Job Tracker Digital System.xlsm'
2020-06-18 10:45:05,681:Survey Assist - v1.0:Error has occurred in JobTracker init().

'str' object has no attribute 'strftime'
Traceback (most recent call last):
  File "C:/Users/rjwal_000/PycharmProjects/Survey Assist/main.py", line 2246, in save_job_to_excel
    self.job_tracker = JobTracker(self.job_tracker_filepath, logger)
  File "C:\Users\rjwal_000\PycharmProjects\Survey Assist\job_tracker.py", line 20, in __init__
    self.create_list_of_job_tracker_jobs()
  File "C:\Users\rjwal_000\PycharmProjects\Survey Assist\job_tracker.py", line 44, in create_list_of_job_tracker_jobs
    survey_job = SurveyJob(row[0].value, survey_date, row[2].value, row[3].value, row[4].value)
  File "C:\Users\rjwal_000\PycharmProjects\Survey Assist\job_tracker.py", line 68, in __init__
    self.survey_date = survey_date.strftime('%d/%m/%Y')
AttributeError: 'str' object has no attribute 'strftime'
2020-06-18 10:45:15,245:Survey Assist - v1.0:Error has occurred in JobTracker init().

Style date_style_rw exists already
Traceback (most recent call last):
  File "C:/Users/rjwal_000/PycharmProjects/Survey Assist/main.py", line 2176, in save_job_to_excel
    workbook.add_named_style(date_style)
  File "C:\Python34\lib\site-packages\openpyxl\workbook\workbook.py", line 327, in add_named_style
    self._named_styles.append(style)
  File "C:\Python34\lib\site-packages\openpyxl\styles\named_styles.py", line 194, in append
    raise ValueError("""Style {0} exists already""".format(style.name))
ValueError: Style date_style_rw exists already
2020-06-18 10:46:05,820:Survey Assist - v1.0:Started Application

2020-06-18 10:46:44,511:Survey Assist - v1.0:Started Application

2020-06-18 10:46:50,567:Survey Assist - v1.0:Error has occurred in JobTracker init().

'str' object has no attribute 'strftime'
Traceback (most recent call last):
  File "C:/Users/rjwal_000/PycharmProjects/Survey Assist/main.py", line 2243, in save_job_to_excel
    self.job_tracker = JobTracker(self.job_tracker_filepath, logger)
  File "C:\Users\rjwal_000\PycharmProjects\Survey Assist\job_tracker.py", line 20, in __init__
    self.create_list_of_job_tracker_jobs()
  File "C:\Users\rjwal_000\PycharmProjects\Survey Assist\job_tracker.py", line 44, in create_list_of_job_tracker_jobs
    survey_job = SurveyJob(row[0].value, survey_date, row[2].value, row[3].value, row[4].value)
  File "C:\Users\rjwal_000\PycharmProjects\Survey Assist\job_tracker.py", line 68, in __init__
    self.survey_date = survey_date.strftime('%d/%m/%Y')
AttributeError: 'str' object has no attribute 'strftime'
2020-06-18 10:47:27,915:Survey Assist - v1.0:Error has occurred in JobTracker init().

'str' object has no attribute 'strftime'
Traceback (most recent call last):
  File "C:/Users/rjwal_000/PycharmProjects/Survey Assist/main.py", line 2243, in save_job_to_excel
    self.job_tracker = JobTracker(self.job_tracker_filepath, logger)
  File "C:\Users\rjwal_000\PycharmProjects\Survey Assist\job_tracker.py", line 20, in __init__
    self.create_list_of_job_tracker_jobs()
  File "C:\Users\rjwal_000\PycharmProjects\Survey Assist\job_tracker.py", line 44, in create_list_of_job_tracker_jobs
    survey_job = SurveyJob(row[0].value, survey_date, row[2].value, row[3].value, row[4].value)
  File "C:\Users\rjwal_000\PycharmProjects\Survey Assist\job_tracker.py", line 68, in __init__
    self.survey_date = survey_date.strftime('%d/%m/%Y')
AttributeError: 'str' object has no attribute 'strftime'
2020-06-18 10:50:07,141:Survey Assist - v1.0:Started Application

2020-06-18 10:50:26,106:Survey Assist - v1.0:Started Application

2020-06-18 10:50:40,622:Survey Assist - v1.0:Error has occurred in JobTracker init().

'str' object has no attribute 'strftime'
Traceback (most recent call last):
  File "C:/Users/rjwal_000/PycharmProjects/Survey Assist/main.py", line 2243, in save_job_to_excel
    self.job_tracker = JobTracker(self.job_tracker_filepath, logger)
  File "C:\Users\rjwal_000\PycharmProjects\Survey Assist\job_tracker.py", line 20, in __init__
    self.create_list_of_job_tracker_jobs()
  File "C:\Users\rjwal_000\PycharmProjects\Survey Assist\job_tracker.py", line 44, in create_list_of_job_tracker_jobs
    survey_job = SurveyJob(row[0].value, survey_date, row[2].value, row[3].value, row[4].value)
  File "C:\Users\rjwal_000\PycharmProjects\Survey Assist\job_tracker.py", line 68, in __init__
    self.survey_date = survey_date.strftime('%d/%m/%Y')
AttributeError: 'str' object has no attribute 'strftime'
2020-06-18 10:50:51,345:Survey Assist - v1.0:OPENING UP A GSI FILE: C:/Users/rjwal_000/PycharmProjects/Survey Assist/Test Files/Survey Data/2020/MONITORING/A9 ARTC/200515/ARTC_903_MON_V2_TS60_150520_EDITED_Sorted.gsi
2020-06-18 10:51:04,277:Survey Assist - v1.0:Started Application

2020-06-18 10:57:50,290:Survey Assist - v1.0:Started Application

2020-06-18 10:58:14,385:Survey Assist - v1.0:Started Application

2020-06-18 10:58:48,463:Survey Assist - v1.0:Started Application

2020-06-18 10:58:54,825:Survey Assist - v1.0:Error has occurred in JobTracker init().

type object 'Color' has no attribute 'RED'
Traceback (most recent call last):
  File "C:/Users/rjwal_000/PycharmProjects/Survey Assist/main.py", line 2191, in save_job_to_excel
    actions_sheet["C11"].font = Font(color = Color.RED)
AttributeError: type object 'Color' has no attribute 'RED'
2020-06-18 10:59:53,184:Survey Assist - v1.0:Started Application

2020-06-18 10:59:57,952:Survey Assist - v1.0:Error has occurred in JobTracker init().

Colors must be aRGB hex values
Traceback (most recent call last):
  File "C:/Users/rjwal_000/PycharmProjects/Survey Assist/main.py", line 2191, in save_job_to_excel
    actions_sheet["C11"].font = Font(color = '#ff0000')
  File "C:\Python34\lib\site-packages\openpyxl\styles\fonts.py", line 92, in __init__
    self.color = color
  File "C:\Python34\lib\site-packages\openpyxl\styles\colors.py", line 135, in __set__
    value = Color(rgb=value)
  File "C:\Python34\lib\site-packages\openpyxl\styles\colors.py", line 95, in __init__
    self.rgb = rgb
  File "C:\Python34\lib\site-packages\openpyxl\styles\colors.py", line 63, in __set__
    raise ValueError("Colors must be aRGB hex values")
ValueError: Colors must be aRGB hex values
2020-06-18 11:00:32,412:Survey Assist - v1.0:Started Application

2020-06-18 11:00:36,167:Survey Assist - v1.0:Error has occurred in JobTracker init().

'str' object has no attribute 'strftime'
Traceback (most recent call last):
  File "C:/Users/rjwal_000/PycharmProjects/Survey Assist/main.py", line 2244, in save_job_to_excel
    self.job_tracker = JobTracker(self.job_tracker_filepath, logger)
  File "C:\Users\rjwal_000\PycharmProjects\Survey Assist\job_tracker.py", line 20, in __init__
    self.create_list_of_job_tracker_jobs()
  File "C:\Users\rjwal_000\PycharmProjects\Survey Assist\job_tracker.py", line 44, in create_list_of_job_tracker_jobs
    survey_job = SurveyJob(row[0].value, survey_date, row[2].value, row[3].value, row[4].value)
  File "C:\Users\rjwal_000\PycharmProjects\Survey Assist\job_tracker.py", line 68, in __init__
    self.survey_date = survey_date.strftime('%d/%m/%Y')
AttributeError: 'str' object has no attribute 'strftime'
2020-06-18 11:05:43,834:Survey Assist - v1.0:Started Application

2020-06-18 11:05:56,801:Survey Assist - v1.0:Started Application

2020-06-18 11:07:50,640:Survey Assist - v1.0:Started Application

2020-06-18 11:07:50,672:Survey Assist - v1.0:Error has occurred creating Job Tracker object.

isinstance() arg 2 must be a type or tuple of types
Traceback (most recent call last):
  File "C:/Users/rjwal_000/PycharmProjects/Survey Assist/main.py", line 4253, in __init__
    self.job_tracker_bar = JobTrackerBar(self.main_window, self.menu_bar.user_config.user_initials)
  File "C:/Users/rjwal_000/PycharmProjects/Survey Assist/main.py", line 2044, in __init__
    self.job_tracker = JobTracker(self.job_tracker_filepath, logger)
  File "C:\Users\rjwal_000\PycharmProjects\Survey Assist\job_tracker.py", line 20, in __init__
    self.create_list_of_job_tracker_jobs()
  File "C:\Users\rjwal_000\PycharmProjects\Survey Assist\job_tracker.py", line 43, in create_list_of_job_tracker_jobs
    survey_job = SurveyJob(row[0].value, row[0].value, row[2].value, row[3].value, row[4].value)
  File "C:\Users\rjwal_000\PycharmProjects\Survey Assist\job_tracker.py", line 69, in __init__
    if isinstance(survey_date, datetime):
TypeError: isinstance() arg 2 must be a type or tuple of types
2020-06-18 11:11:07,965:Survey Assist - v1.0:Started Application

2020-06-18 11:12:01,232:Survey Assist - v1.0:Started Application

2020-06-18 11:13:51,763:Survey Assist - v1.0:Started Application

2020-06-18 11:14:19,675:Survey Assist - v1.0:Started Application

2020-06-18 13:21:04,110:Survey Assist - v1.0:Started Application

2020-06-18 13:21:10,927:Survey Assist - v1.0:Error has occurred in JobTracker init().

'str' object has no attribute 'alignment'
Traceback (most recent call last):
  File "C:/Users/rjwal_000/PycharmProjects/Survey Assist/main.py", line 2186, in save_job_to_excel
    self.update_job_date(actions_sheet["B11"], date_string)
  File "C:/Users/rjwal_000/PycharmProjects/Survey Assist/main.py", line 2281, in update_job_date
    cell.alignment = Alignment(horizontal='center')
AttributeError: 'str' object has no attribute 'alignment'
2020-06-18 13:23:37,239:Survey Assist - v1.0:Started Application

2020-06-18 13:24:02,951:Survey Assist - v1.0:Job Tracker excel spreadsheet currently in use

[Errno 13] Permission denied: 'C:\\Users\\rjwal_000\\PycharmProjects\\Survey Assist\\Test Files\\Survey Data\\2020\\Job Tracker Digital System.xlsm'
Traceback (most recent call last):
  File "C:/Users/rjwal_000/PycharmProjects/Survey Assist/main.py", line 2241, in save_job_to_excel
    workbook.save(filename=self.job_tracker_filepath)
  File "C:\Python34\lib\site-packages\openpyxl\workbook\workbook.py", line 391, in save
    save_workbook(self, filename)
  File "C:\Python34\lib\site-packages\openpyxl\writer\excel.py", line 282, in save_workbook
    archive = ZipFile(filename, 'w', ZIP_DEFLATED, allowZip64=True)
  File "C:\Python34\lib\zipfile.py", line 923, in __init__
    self.fp = io.open(file, modeDict[mode])
PermissionError: [Errno 13] Permission denied: 'C:\\Users\\rjwal_000\\PycharmProjects\\Survey Assist\\Test Files\\Survey Data\\2020\\Job Tracker Digital System.xlsm'
2020-06-18 13:26:36,133:Survey Assist - v1.0:Started Application

2020-06-18 13:26:42,036:Survey Assist - v1.0:Job Tracker excel spreadsheet currently in use

[Errno 13] Permission denied: 'C:\\Users\\rjwal_000\\PycharmProjects\\Survey Assist\\Test Files\\Survey Data\\2020\\Job Tracker Digital System.xlsm'
Traceback (most recent call last):
  File "C:/Users/rjwal_000/PycharmProjects/Survey Assist/main.py", line 2241, in save_job_to_excel
    workbook.save(filename=self.job_tracker_filepath)
  File "C:\Python34\lib\site-packages\openpyxl\workbook\workbook.py", line 391, in save
    save_workbook(self, filename)
  File "C:\Python34\lib\site-packages\openpyxl\writer\excel.py", line 282, in save_workbook
    archive = ZipFile(filename, 'w', ZIP_DEFLATED, allowZip64=True)
  File "C:\Python34\lib\zipfile.py", line 923, in __init__
    self.fp = io.open(file, modeDict[mode])
PermissionError: [Errno 13] Permission denied: 'C:\\Users\\rjwal_000\\PycharmProjects\\Survey Assist\\Test Files\\Survey Data\\2020\\Job Tracker Digital System.xlsm'
2020-06-18 13:27:30,881:Survey Assist - v1.0:Started Application

2020-06-18 13:32:11,146:Survey Assist - v1.0:Started Application

2020-06-18 13:38:34,944:Survey Assist - v1.0:Started Application

2020-06-18 13:38:41,717:Survey Assist - v1.0:Job Tracker excel spreadsheet currently in use

[Errno 13] Permission denied: 'C:\\Users\\rjwal_000\\PycharmProjects\\Survey Assist\\Test Files\\Survey Data\\2020\\Job Tracker Digital System.xlsm'
Traceback (most recent call last):
  File "C:/Users/rjwal_000/PycharmProjects/Survey Assist/main.py", line 2241, in save_job_to_excel
    workbook.save(filename=self.job_tracker_filepath)
  File "C:\Python34\lib\site-packages\openpyxl\workbook\workbook.py", line 391, in save
    save_workbook(self, filename)
  File "C:\Python34\lib\site-packages\openpyxl\writer\excel.py", line 282, in save_workbook
    archive = ZipFile(filename, 'w', ZIP_DEFLATED, allowZip64=True)
  File "C:\Python34\lib\zipfile.py", line 923, in __init__
    self.fp = io.open(file, modeDict[mode])
PermissionError: [Errno 13] Permission denied: 'C:\\Users\\rjwal_000\\PycharmProjects\\Survey Assist\\Test Files\\Survey Data\\2020\\Job Tracker Digital System.xlsm'
2020-06-18 13:42:31,354:Survey Assist - v1.0:Started Application

2020-06-18 13:55:55,926:Survey Assist - v1.0:Started Application

2020-06-18 13:58:32,837:Survey Assist - v1.0:Started Application

2020-06-18 13:58:40,338:Survey Assist - v1.0:Job Tracker excel spreadsheet currently in use

[Errno 13] Permission denied: 'C:\\Users\\rjwal_000\\PycharmProjects\\Survey Assist\\Test Files\\Survey Data\\2020\\Job Tracker Digital System.xlsm'
Traceback (most recent call last):
  File "C:/Users/rjwal_000/PycharmProjects/Survey Assist/main.py", line 2241, in save_job_to_excel
    workbook.save(filename=self.job_tracker_filepath)
  File "C:\Python34\lib\site-packages\openpyxl\workbook\workbook.py", line 391, in save
    save_workbook(self, filename)
  File "C:\Python34\lib\site-packages\openpyxl\writer\excel.py", line 282, in save_workbook
    archive = ZipFile(filename, 'w', ZIP_DEFLATED, allowZip64=True)
  File "C:\Python34\lib\zipfile.py", line 923, in __init__
    self.fp = io.open(file, modeDict[mode])
PermissionError: [Errno 13] Permission denied: 'C:\\Users\\rjwal_000\\PycharmProjects\\Survey Assist\\Test Files\\Survey Data\\2020\\Job Tracker Digital System.xlsm'
2020-06-18 14:01:45,552:Survey Assist - v1.0:Started Application

2020-06-18 14:09:32,730:Survey Assist - v1.0:Started Application

2020-06-18 14:11:16,606:Survey Assist - v1.0:Started Application

2020-06-18 14:12:32,160:Survey Assist - v1.0:Started Application

2020-06-18 14:12:40,482:Survey Assist - v1.0:Job Tracker excel spreadsheet currently in use

[Errno 13] Permission denied: 'C:\\Users\\rjwal_000\\PycharmProjects\\Survey Assist\\Test Files\\Survey Data\\2020\\Job Tracker Digital System.xlsm'
Traceback (most recent call last):
  File "C:/Users/rjwal_000/PycharmProjects/Survey Assist/main.py", line 2241, in save_job_to_excel
    workbook.save(filename=self.job_tracker_filepath)
  File "C:\Users\rjwal_000\AppData\Local\Programs\Python\Python38-32\lib\site-packages\openpyxl\workbook\workbook.py", line 392, in save
    save_workbook(self, filename)
  File "C:\Users\rjwal_000\AppData\Local\Programs\Python\Python38-32\lib\site-packages\openpyxl\writer\excel.py", line 291, in save_workbook
    archive = ZipFile(filename, 'w', ZIP_DEFLATED, allowZip64=True)
  File "C:\Users\rjwal_000\AppData\Local\Programs\Python\Python38-32\lib\zipfile.py", line 1250, in __init__
    self.fp = io.open(file, filemode)
PermissionError: [Errno 13] Permission denied: 'C:\\Users\\rjwal_000\\PycharmProjects\\Survey Assist\\Test Files\\Survey Data\\2020\\Job Tracker Digital System.xlsm'
2020-06-18 14:25:25,499:Survey Assist - v1.0:Started Application

2020-06-18 14:26:22,826:Survey Assist - v1.0:Started Application

2020-06-18 14:27:19,287:Survey Assist - v1.0:Started Application

2020-06-18 14:30:17,864:Survey Assist - v1.0:Started Application

2020-06-18 14:32:27,034:Survey Assist - v1.0:Started Application

2020-06-18 14:33:38,189:Survey Assist - v1.0:Started Application

2020-06-18 14:33:43,886:Survey Assist - v1.0:Error has occurred in JobTracker init().

Value must be one of {'min', 'formula', 'percentile', 'num', 'max', 'percent'}
Traceback (most recent call last):
  File "C:/Users/rjwal_000/PycharmProjects/Survey Assist/main.py", line 2200, in save_job_to_excel
    self.update_conditional_formatting(actions_sheet)
  File "C:/Users/rjwal_000/PycharmProjects/Survey Assist/main.py", line 2276, in update_conditional_formatting
    rule = DataBarRule(start_type='Percent', start_value=0, end_type='percentile', end_value=100, color="FF638EC6",
  File "C:\Users\rjwal_000\AppData\Local\Programs\Python\Python38-32\lib\site-packages\openpyxl\formatting\rule.py", line 285, in DataBarRule
    start = FormatObject(start_type, start_value)
  File "C:\Users\rjwal_000\AppData\Local\Programs\Python\Python38-32\lib\site-packages\openpyxl\formatting\rule.py", line 56, in __init__
    self.type = type
  File "C:\Users\rjwal_000\AppData\Local\Programs\Python\Python38-32\lib\site-packages\openpyxl\descriptors\base.py", line 128, in __set__
    raise ValueError(self.__doc__)
ValueError: Value must be one of {'min', 'formula', 'percentile', 'num', 'max', 'percent'}
2020-06-18 14:34:17,123:Survey Assist - v1.0:Started Application

2020-06-18 14:35:12,705:Survey Assist - v1.0:Started Application

2020-06-18 14:36:57,630:Survey Assist - v1.0:Started Application

2020-06-18 14:39:57,087:Survey Assist - v1.0:Started Application

2020-06-18 14:41:36,340:Survey Assist - v1.0:Started Application

2020-06-18 14:42:11,619:Survey Assist - v1.0:Started Application

2020-06-18 14:42:18,262:Survey Assist - v1.0:Started Application

2020-06-18 14:46:25,542:Survey Assist - v1.0:Started Application

2020-06-18 14:47:02,966:Survey Assist - v1.0:Started Application

2020-06-18 14:47:05,972:Survey Assist - v1.0:Error has occurred in JobTracker init().

'module' object is not callable
Traceback (most recent call last):
  File "C:/Users/rjwal_000/PycharmProjects/Survey Assist/main.py", line 2179, in save_job_to_excel
    actions_sheet["J11"]._style = copy(actions_sheet["J11"]._style)
TypeError: 'module' object is not callable
2020-06-18 14:50:35,366:Survey Assist - v1.0:Started Application

2020-06-18 15:14:14,360:Survey Assist - v1.0:Started Application

2020-06-18 15:14:20,263:Survey Assist - v1.0:Error has occurred in JobTracker init().

expected <class 'openpyxl.worksheet.cell_range.MultiCellRange'>
Traceback (most recent call last):
  File "C:\Python34\lib\site-packages\openpyxl\descriptors\base.py", line 57, in _convert
    value = expected_type(value)
  File "C:\Python34\lib\site-packages\openpyxl\worksheet\cell_range.py", line 381, in __init__
    ranges = [CellRange(r) for r in ranges.split()]
  File "C:\Python34\lib\site-packages\openpyxl\worksheet\cell_range.py", line 381, in <listcomp>
    ranges = [CellRange(r) for r in ranges.split()]
  File "C:\Python34\lib\site-packages\openpyxl\worksheet\cell_range.py", line 68, in __init__
    raise ValueError(fmt.format(min_row=min_row, max_row=max_row))
ValueError: 10 must be greater than 11

During handling of the above exception, another exception occurred:

Traceback (most recent call last):
  File "C:/Users/rjwal_000/PycharmProjects/Survey Assist/main.py", line 2200, in save_job_to_excel
    self.update_conditional_formatting(actions_sheet)
  File "C:/Users/rjwal_000/PycharmProjects/Survey Assist/main.py", line 2278, in update_conditional_formatting
    actions_sheet.conditional_formatting.add('J11:J10', rule)
  File "C:\Python34\lib\site-packages\openpyxl\formatting\formatting.py", line 75, in add
    cf = ConditionalFormatting(range_string)
  File "C:\Python34\lib\site-packages\openpyxl\formatting\formatting.py", line 33, in __init__
    self.sqref = sqref
  File "C:\Python34\lib\site-packages\openpyxl\descriptors\base.py", line 69, in __set__
    value = _convert(self.expected_type, value)
  File "C:\Python34\lib\site-packages\openpyxl\descriptors\base.py", line 59, in _convert
    raise TypeError('expected ' + str(expected_type))
TypeError: expected <class 'openpyxl.worksheet.cell_range.MultiCellRange'>
2020-06-18 15:14:38,747:Survey Assist - v1.0:Started Application

2020-06-18 15:15:47,576:Survey Assist - v1.0:Started Application

2020-06-18 16:12:10,575:Survey Assist - v1.0:Started Application

2020-06-18 16:12:18,016:Survey Assist - v1.0:Error has occurred in JobTracker init().

expected <class 'openpyxl.worksheet.cell_range.MultiCellRange'>
Traceback (most recent call last):
  File "C:\Python34\lib\site-packages\openpyxl\descriptors\base.py", line 57, in _convert
    value = expected_type(value)
  File "C:\Python34\lib\site-packages\openpyxl\worksheet\cell_range.py", line 381, in __init__
    ranges = [CellRange(r) for r in ranges.split()]
  File "C:\Python34\lib\site-packages\openpyxl\worksheet\cell_range.py", line 381, in <listcomp>
    ranges = [CellRange(r) for r in ranges.split()]
  File "C:\Python34\lib\site-packages\openpyxl\worksheet\cell_range.py", line 55, in __init__
    min_col, min_row, max_col, max_row = range_boundaries(range_string)
  File "C:\Python34\lib\site-packages\openpyxl\utils\cell.py", line 137, in range_boundaries
    raise ValueError(msg)
ValueError: J11:J32' is not a valid coordinate or range

During handling of the above exception, another exception occurred:

Traceback (most recent call last):
  File "C:/Users/rjwal_000/PycharmProjects/Survey Assist/main.py", line 2200, in save_job_to_excel
    self.update_conditional_formatting(actions_sheet)
  File "C:/Users/rjwal_000/PycharmProjects/Survey Assist/main.py", line 2278, in update_conditional_formatting
    actions_sheet.conditional_formatting.add('J11:J' + str((11+len(self.job_tracker.get_job_names()))) + '\'', rule)
  File "C:\Python34\lib\site-packages\openpyxl\formatting\formatting.py", line 75, in add
    cf = ConditionalFormatting(range_string)
  File "C:\Python34\lib\site-packages\openpyxl\formatting\formatting.py", line 33, in __init__
    self.sqref = sqref
  File "C:\Python34\lib\site-packages\openpyxl\descriptors\base.py", line 69, in __set__
    value = _convert(self.expected_type, value)
  File "C:\Python34\lib\site-packages\openpyxl\descriptors\base.py", line 59, in _convert
    raise TypeError('expected ' + str(expected_type))
TypeError: expected <class 'openpyxl.worksheet.cell_range.MultiCellRange'>
2020-06-18 16:13:32,734:Survey Assist - v1.0:Started Application

2020-06-18 16:14:03,139:Survey Assist - v1.0:Error has occurred in JobTracker init().

expected <class 'openpyxl.worksheet.cell_range.MultiCellRange'>
Traceback (most recent call last):
  File "C:\Python34\lib\site-packages\openpyxl\descriptors\base.py", line 57, in _convert
    value = expected_type(value)
  File "C:\Python34\lib\site-packages\openpyxl\worksheet\cell_range.py", line 381, in __init__
    ranges = [CellRange(r) for r in ranges.split()]
  File "C:\Python34\lib\site-packages\openpyxl\worksheet\cell_range.py", line 381, in <listcomp>
    ranges = [CellRange(r) for r in ranges.split()]
  File "C:\Python34\lib\site-packages\openpyxl\worksheet\cell_range.py", line 55, in __init__
    min_col, min_row, max_col, max_row = range_boundaries(range_string)
  File "C:\Python34\lib\site-packages\openpyxl\utils\cell.py", line 137, in range_boundaries
    raise ValueError(msg)
ValueError: J11:J32' is not a valid coordinate or range

During handling of the above exception, another exception occurred:

Traceback (most recent call last):
  File "C:/Users/rjwal_000/PycharmProjects/Survey Assist/main.py", line 2200, in save_job_to_excel
    self.update_conditional_formatting(actions_sheet)
  File "C:/Users/rjwal_000/PycharmProjects/Survey Assist/main.py", line 2279, in update_conditional_formatting
    actions_sheet.conditional_formatting.add('J11:J' + range_cell + '\'', rule)
  File "C:\Python34\lib\site-packages\openpyxl\formatting\formatting.py", line 75, in add
    cf = ConditionalFormatting(range_string)
  File "C:\Python34\lib\site-packages\openpyxl\formatting\formatting.py", line 33, in __init__
    self.sqref = sqref
  File "C:\Python34\lib\site-packages\openpyxl\descriptors\base.py", line 69, in __set__
    value = _convert(self.expected_type, value)
  File "C:\Python34\lib\site-packages\openpyxl\descriptors\base.py", line 59, in _convert
    raise TypeError('expected ' + str(expected_type))
TypeError: expected <class 'openpyxl.worksheet.cell_range.MultiCellRange'>
2020-06-18 16:15:47,034:Survey Assist - v1.0:Started Application

2020-06-18 16:16:57,280:Survey Assist - v1.0:Started Application

2020-06-18 16:17:02,022:Survey Assist - v1.0:Error has occurred in JobTracker init().

expected <class 'openpyxl.worksheet.cell_range.MultiCellRange'>
Traceback (most recent call last):
  File "C:\Python34\lib\site-packages\openpyxl\descriptors\base.py", line 57, in _convert
    value = expected_type(value)
  File "C:\Python34\lib\site-packages\openpyxl\worksheet\cell_range.py", line 381, in __init__
    ranges = [CellRange(r) for r in ranges.split()]
  File "C:\Python34\lib\site-packages\openpyxl\worksheet\cell_range.py", line 381, in <listcomp>
    ranges = [CellRange(r) for r in ranges.split()]
  File "C:\Python34\lib\site-packages\openpyxl\worksheet\cell_range.py", line 55, in __init__
    min_col, min_row, max_col, max_row = range_boundaries(range_string)
  File "C:\Python34\lib\site-packages\openpyxl\utils\cell.py", line 137, in range_boundaries
    raise ValueError(msg)
ValueError: J11:J32' is not a valid coordinate or range

During handling of the above exception, another exception occurred:

Traceback (most recent call last):
  File "C:/Users/rjwal_000/PycharmProjects/Survey Assist/main.py", line 2200, in save_job_to_excel
    self.update_conditional_formatting(actions_sheet)
  File "C:/Users/rjwal_000/PycharmProjects/Survey Assist/main.py", line 2280, in update_conditional_formatting
    actions_sheet.conditional_formatting.add(cell_range, rule)
  File "C:\Python34\lib\site-packages\openpyxl\formatting\formatting.py", line 75, in add
    cf = ConditionalFormatting(range_string)
  File "C:\Python34\lib\site-packages\openpyxl\formatting\formatting.py", line 33, in __init__
    self.sqref = sqref
  File "C:\Python34\lib\site-packages\openpyxl\descriptors\base.py", line 69, in __set__
    value = _convert(self.expected_type, value)
  File "C:\Python34\lib\site-packages\openpyxl\descriptors\base.py", line 59, in _convert
    raise TypeError('expected ' + str(expected_type))
TypeError: expected <class 'openpyxl.worksheet.cell_range.MultiCellRange'>
2020-06-18 16:17:26,707:Survey Assist - v1.0:Started Application

2020-06-18 16:18:22,683:Survey Assist - v1.0:Started Application

2020-06-18 16:19:00,654:Survey Assist - v1.0:Started Application

2020-06-18 16:21:09,668:Survey Assist - v1.0:Started Application

2020-06-18 16:23:42,080:Survey Assist - v1.0:Started Application

2020-06-18 16:25:11,846:Survey Assist - v1.0:Job Tracker excel spreadsheet currently in use

[Errno 13] Permission denied: 'C:\\Users\\rjwal_000\\PycharmProjects\\Survey Assist\\Test Files\\Survey Data\\2020\\Job Tracker Digital System.xlsm'
Traceback (most recent call last):
  File "C:/Users/rjwal_000/PycharmProjects/Survey Assist/main.py", line 2217, in save_job_to_excel
    workbook.save(filename=self.job_tracker_filepath)
  File "C:\Python34\lib\site-packages\openpyxl\workbook\workbook.py", line 391, in save
    save_workbook(self, filename)
  File "C:\Python34\lib\site-packages\openpyxl\writer\excel.py", line 282, in save_workbook
    archive = ZipFile(filename, 'w', ZIP_DEFLATED, allowZip64=True)
  File "C:\Python34\lib\zipfile.py", line 923, in __init__
    self.fp = io.open(file, modeDict[mode])
PermissionError: [Errno 13] Permission denied: 'C:\\Users\\rjwal_000\\PycharmProjects\\Survey Assist\\Test Files\\Survey Data\\2020\\Job Tracker Digital System.xlsm'
2020-06-18 16:28:34,733:Survey Assist - v1.0:Started Application

2020-06-18 16:29:42,849:Survey Assist - v1.0:Started Application

2020-06-18 16:33:16,647:Survey Assist - v1.0:Started Application

2020-06-18 16:34:16,623:Survey Assist - v1.0:Started Application

2020-06-18 16:34:58,787:Survey Assist - v1.0:Started Application

2020-06-18 16:35:18,080:Survey Assist - v1.0:Started Application

2020-06-18 16:37:32,343:Survey Assist - v1.0:Started Application

2020-06-18 16:38:01,831:Survey Assist - v1.0:Started Application

2020-06-18 16:41:18,501:Survey Assist - v1.0:Started Application

2020-06-18 16:41:29,937:Survey Assist - v1.0:Started Application

2020-06-18 16:41:58,633:Survey Assist - v1.0:Started Application

2020-06-18 16:44:15,283:Survey Assist - v1.0:Started Application

2020-06-18 16:44:37,669:Survey Assist - v1.0:Started Application

2020-06-18 16:44:42,218:Survey Assist - v1.0:Started Application

2020-06-18 16:45:13,000:Survey Assist - v1.0:Started Application

2020-06-18 16:46:14,377:Survey Assist - v1.0:Started Application

2020-06-18 16:47:50,615:Survey Assist - v1.0:Started Application

2020-06-18 16:49:05,804:Survey Assist - v1.0:Started Application

2020-06-18 16:49:22,443:Survey Assist - v1.0:Started Application

2020-06-18 16:50:01,155:Survey Assist - v1.0:Started Application

2020-06-18 16:51:50,727:Survey Assist - v1.0:Started Application

2020-06-18 16:52:52,845:Survey Assist - v1.0:Started Application

2020-06-18 16:53:13,296:Survey Assist - v1.0:Job Tracker excel spreadsheet currently in use

[Errno 13] Permission denied: 'C:\\Users\\rjwal_000\\PycharmProjects\\Survey Assist\\Test Files\\Survey Data\\2020\\Job Tracker Digital System.xlsm'
Traceback (most recent call last):
  File "C:/Users/rjwal_000/PycharmProjects/Survey Assist/main.py", line 2221, in save_job_to_excel
    workbook.save(filename=self.job_tracker_filepath)
  File "C:\Python34\lib\site-packages\openpyxl\workbook\workbook.py", line 391, in save
    save_workbook(self, filename)
  File "C:\Python34\lib\site-packages\openpyxl\writer\excel.py", line 282, in save_workbook
    archive = ZipFile(filename, 'w', ZIP_DEFLATED, allowZip64=True)
  File "C:\Python34\lib\zipfile.py", line 923, in __init__
    self.fp = io.open(file, modeDict[mode])
PermissionError: [Errno 13] Permission denied: 'C:\\Users\\rjwal_000\\PycharmProjects\\Survey Assist\\Test Files\\Survey Data\\2020\\Job Tracker Digital System.xlsm'
2020-06-18 16:55:53,350:Survey Assist - v1.0:Started Application

2020-06-18 17:00:00,551:Survey Assist - v1.0:Started Application

2020-06-18 17:05:06,161:Survey Assist - v1.0:Started Application

2020-06-18 17:05:54,047:Survey Assist - v1.0:Started Application

2020-06-18 18:28:59,688:Survey Assist - v1.0:Started Application

2020-06-18 18:55:51,910:Survey Assist - v1.0:Started Application

2020-06-18 18:55:51,970:Survey Assist - v1.0:Error has occurred creating Job Tracker object.

No Job Names Found
Traceback (most recent call last):
  File "C:/Users/rjwal_000/PycharmProjects/Survey Assist/main.py", line 4258, in __init__
    self.job_tracker_bar = JobTrackerBar(self.main_window, self.menu_bar.user_config.user_initials)
  File "C:/Users/rjwal_000/PycharmProjects/Survey Assist/main.py", line 2075, in __init__
    self.jt_job_name_combo['values'] = self.get_combobox_values()
  File "C:/Users/rjwal_000/PycharmProjects/Survey Assist/main.py", line 2131, in get_combobox_values
    raise Exception("No Job Names Found")
Exception: No Job Names Found
2020-06-18 18:57:35,306:Survey Assist - v1.0:Started Application

2020-06-18 18:57:35,356:Survey Assist - v1.0:Error has occurred creating Job Tracker object.

No Job Names Found
Traceback (most recent call last):
  File "C:/Users/rjwal_000/PycharmProjects/Survey Assist/main.py", line 4258, in __init__
    self.job_tracker_bar = JobTrackerBar(self.main_window, self.menu_bar.user_config.user_initials)
  File "C:/Users/rjwal_000/PycharmProjects/Survey Assist/main.py", line 2075, in __init__
    self.jt_job_name_combo['values'] = self.get_combobox_values()
  File "C:/Users/rjwal_000/PycharmProjects/Survey Assist/main.py", line 2131, in get_combobox_values
    raise Exception("No Job Names Found")
Exception: No Job Names Found
2020-06-18 19:01:21,673:Survey Assist - v1.0:Started Application

2020-06-18 19:01:25,417:Survey Assist - v1.0:Job Tracker excel spreadsheet currently in use

[Errno 13] Permission denied: 'C:\\Users\\rjwal_000\\PycharmProjects\\Survey Assist\\Test Files\\Survey Data\\2020\\Job Tracker Digital System.xlsm'
Traceback (most recent call last):
  File "C:/Users/rjwal_000/PycharmProjects/Survey Assist/main.py", line 2220, in save_job_to_excel
    workbook.save(filename=self.job_tracker_filepath)
  File "C:\Python34\lib\site-packages\openpyxl\workbook\workbook.py", line 391, in save
    save_workbook(self, filename)
  File "C:\Python34\lib\site-packages\openpyxl\writer\excel.py", line 282, in save_workbook
    archive = ZipFile(filename, 'w', ZIP_DEFLATED, allowZip64=True)
  File "C:\Python34\lib\zipfile.py", line 923, in __init__
    self.fp = io.open(file, modeDict[mode])
PermissionError: [Errno 13] Permission denied: 'C:\\Users\\rjwal_000\\PycharmProjects\\Survey Assist\\Test Files\\Survey Data\\2020\\Job Tracker Digital System.xlsm'
2020-06-18 19:03:40,538:Survey Assist - v1.0:Started Application

2020-06-18 19:04:13,652:Survey Assist - v1.0:Started Application

2020-06-18 19:06:09,749:Survey Assist - v1.0:Started Application

2020-06-18 20:06:47,050:Survey Assist - v1.0:Started Application

2020-06-18 20:08:56,525:Survey Assist - v1.0:Started Application

2020-06-18 20:16:43,194:Survey Assist - v1.0:Started Application

2020-06-18 20:17:01,482:Survey Assist - v1.0:Started Application

