2020-05-22 15:01:49,518:Survey Assist - v1.0:Started Application

2020-05-22 15:01:53,879:Survey Assist - v1.0:OPENING UP A GSI FILE: C:/Users/Richard/Downloads/890MR 150520.GSI
2020-05-22 15:04:34,728:Survey Assist - v1.0:Started Application

2020-05-22 15:04:39,409:Survey Assist - v1.0:OPENING UP A GSI FILE: C:/Users/Richard/Downloads/890MR 150520.GSI
2020-05-22 15:04:52,040:Survey Assist - v1.0:An unexpected error has occurred

update_station_height()

5
Traceback (most recent call last):
  File "C:/Users/Richard/PycharmProjects/Survey Assist/main.py", line 2607, in change_station_height
    self.subsequent_station_setups[line_number].add(formatted_line['Point_ID'])
KeyError: 5
2020-05-22 15:07:35,580:Survey Assist - v1.0:Started Application

2020-05-22 15:07:39,159:Survey Assist - v1.0:OPENING UP A GSI FILE: C:/Users/Richard/Downloads/890MR 150520.GSI
2020-05-22 15:07:54,311:Survey Assist - v1.0:An unexpected error has occurred

update_station_height()

descriptor 'get' for 'dict' objects doesn't apply to 'str' object
Traceback (most recent call last):
  File "C:/Users/Richard/PycharmProjects/Survey Assist/main.py", line 2650, in change_station_height
    prev_averaged_coordinates = new_stn_coordinates.get(point_id) # retrieve previous average coordinates if they exist
TypeError: descriptor 'get' for 'dict' objects doesn't apply to 'str' object
2020-05-22 15:11:51,381:Survey Assist - v1.0:An unexpected error has occurred

update_station_height()

descriptor 'get' for 'dict' objects doesn't apply to 'str' object
Traceback (most recent call last):
  File "C:/Users/Richard/PycharmProjects/Survey Assist/main.py", line 2650, in change_station_height
    prev_averaged_coordinates = new_stn_coordinates.get(point_id) # retrieve previous average coordinates if they exist
TypeError: descriptor 'get' for 'dict' objects doesn't apply to 'str' object
2020-05-22 15:15:39,686:Survey Assist - v1.0:Started Application

2020-05-22 15:15:44,206:Survey Assist - v1.0:OPENING UP A GSI FILE: C:/Users/Richard/Downloads/890MR 150520.GSI
2020-05-22 15:16:30,552:Survey Assist - v1.0:An unexpected error has occurred

update_station_height()

'STN04'
Traceback (most recent call last):
  File "C:/Users/Richard/PycharmProjects/Survey Assist/main.py", line 2659, in change_station_height
    new_stn_elevation = new_stn_coordinates[station][2]
KeyError: 'STN04'
2020-05-22 15:18:34,381:Survey Assist - v1.0:Started Application

2020-05-22 15:18:40,348:Survey Assist - v1.0:OPENING UP A GSI FILE: C:/Users/Richard/Downloads/890MR 150520.GSI
2020-05-22 15:41:57,180:Survey Assist - v1.0:Started Application

2020-05-22 15:42:01,409:Survey Assist - v1.0:OPENING UP A GSI FILE: C:/Users/Richard/Downloads/890MR 150520.GSI
2020-05-22 16:20:01,240:Survey Assist - v1.0:Started Application

2020-05-22 16:20:06,128:Survey Assist - v1.0:OPENING UP A GSI FILE: C:/Users/Richard/Downloads/890MR 150520.GSI
2020-05-22 16:21:05,489:Survey Assist - v1.0:An unexpected error has occurred

update_station_height()

'STN04'
Traceback (most recent call last):
  File "C:/Users/Richard/PycharmProjects/Survey Assist/main.py", line 2660, in change_station_height
    stn_coordinates = self.new_stn_coordinates[station]
KeyError: 'STN04'
2020-05-22 16:25:37,819:Survey Assist - v1.0:Started Application

2020-05-22 16:25:43,455:Survey Assist - v1.0:OPENING UP A GSI FILE: C:/Users/Richard/Downloads/890MR 150520.GSI
2020-05-22 16:27:19,875:Survey Assist - v1.0:Started Application

2020-05-22 16:27:25,659:Survey Assist - v1.0:OPENING UP A GSI FILE: C:/Users/Richard/Downloads/890MR 150520.GSI
2020-05-22 16:29:13,391:Survey Assist - v1.0:Started Application

2020-05-22 16:29:18,207:Survey Assist - v1.0:OPENING UP A GSI FILE: C:/Users/Richard/Downloads/890MR 150520.GSI
2020-05-22 16:29:25,135:Survey Assist - v1.0:An unexpected error has occurred

update_station_height()

'NoneType' object has no attribute 'group'
Traceback (most recent call last):
  File "C:/Users/Richard/PycharmProjects/Survey Assist/main.py", line 2663, in change_station_height
    gsi.update_station_elevation(line_number, new_stn_elevation)
  File "C:\Users\Richard\PycharmProjects\Survey Assist\GSI.py", line 134, in update_station_elevation
    org_field_value = match.group()
AttributeError: 'NoneType' object has no attribute 'group'
2020-05-22 16:30:04,125:Survey Assist - v1.0:Started Application

2020-05-22 16:30:08,018:Survey Assist - v1.0:OPENING UP A GSI FILE: C:/Users/Richard/Downloads/890MR 150520.GSI
2020-05-22 16:32:31,578:Survey Assist - v1.0:An unexpected error has occurred

update_station_height()

'STN04'
Traceback (most recent call last):
  File "C:/Users/Richard/PycharmProjects/Survey Assist/main.py", line 2660, in change_station_height
    stn_coordinates = self.new_stn_coordinates[station]
KeyError: 'STN04'
2020-05-22 16:34:29,411:Survey Assist - v1.0:Started Application

2020-05-22 16:34:37,393:Survey Assist - v1.0:OPENING UP A GSI FILE: C:/Users/Richard/Downloads/890MR 150520.GSI
2020-05-22 16:35:10,412:Survey Assist - v1.0:An unexpected error has occurred

update_station_height()

'STN04'
Traceback (most recent call last):
  File "C:/Users/Richard/PycharmProjects/Survey Assist/main.py", line 2660, in change_station_height
    stn_coordinates = self.new_stn_coordinates[station]
KeyError: 'STN04'
2020-05-22 16:57:07,381:Survey Assist - v1.0:Started Application

2020-05-22 16:57:12,550:Survey Assist - v1.0:OPENING UP A GSI FILE: C:/Users/Richard/Downloads/890MR 150520.GSI
2020-05-22 16:57:37,049:Survey Assist - v1.0:OPENING UP A GSI FILE: C:/Users/Richard/Downloads/890MR 150520.GSI
2020-05-22 16:58:18,067:Survey Assist - v1.0:OPENING UP A GSI FILE: C:/Users/Richard/Downloads/890MR 150520.GSI
2020-05-22 16:59:37,226:Survey Assist - v1.0:Started Application

2020-05-22 16:59:41,893:Survey Assist - v1.0:OPENING UP A GSI FILE: C:/Users/Richard/Downloads/890MR 150520.GSI
2020-05-22 17:02:46,475:Survey Assist - v1.0:Started Application

2020-05-22 17:02:51,003:Survey Assist - v1.0:OPENING UP A GSI FILE: C:/Users/Richard/Downloads/890MR 150520.GSI
2020-05-22 17:06:58,269:Survey Assist - v1.0:OPENING UP A GSI FILE: C:/Users/Richard/Downloads/890MR 150520.GSI
2020-05-22 17:10:24,191:Survey Assist - v1.0:OPENING UP A GSI FILE: C:/Users/Richard/PycharmProjects/Survey Assist/Test Files/GSI Files/HCCL 030719.GSI
2020-05-22 17:12:34,657:Survey Assist - v1.0:Started Application

2020-05-22 17:12:41,785:Survey Assist - v1.0:OPENING UP A GSI FILE: C:/Users/Richard/Downloads/890MR 150520.GSI
2020-05-22 17:12:49,053:Survey Assist - v1.0:An unexpected error has occurred

update_station_height()

'NoneType' object has no attribute 'group'
Traceback (most recent call last):
  File "C:/Users/Richard/PycharmProjects/Survey Assist/main.py", line 2664, in change_station_height
    gsi.update_station_elevation(line_number-1, new_stn_elevation)
  File "C:\Users\Richard\PycharmProjects\Survey Assist\GSI.py", line 134, in update_station_elevation
    org_field_value = match.group()
AttributeError: 'NoneType' object has no attribute 'group'
2020-05-22 17:14:25,197:Survey Assist - v1.0:Started Application

2020-05-22 17:14:29,284:Survey Assist - v1.0:OPENING UP A GSI FILE: C:/Users/Richard/Downloads/890MR 150520.GSI
2020-05-22 17:16:18,005:Survey Assist - v1.0:Started Application

2020-05-22 17:16:38,748:Survey Assist - v1.0:Started Application

2020-05-22 17:16:43,612:Survey Assist - v1.0:OPENING UP A GSI FILE: C:/Users/Richard/Downloads/890MR 150520.GSI
2020-05-22 17:17:31,976:Survey Assist - v1.0:Started Application

2020-05-22 17:17:35,222:Survey Assist - v1.0:OPENING UP A GSI FILE: C:/Users/Richard/Downloads/890MR 150520.GSI
2020-05-22 17:23:53,631:Survey Assist - v1.0:Started Application

2020-05-22 17:23:58,628:Survey Assist - v1.0:OPENING UP A GSI FILE: C:/Users/Richard/Downloads/890MR 150520.GSI
2020-05-22 17:25:51,706:Survey Assist - v1.0:OPENING UP A GSI FILE: C:/Users/Richard/Downloads/890MR 150520.GSI
2020-05-22 17:27:18,332:Survey Assist - v1.0:OPENING UP A GSI FILE: C:/Users/Richard/Downloads/890MR 150520.GSI
2020-05-22 17:31:20,827:Survey Assist - v1.0:Started Application

2020-05-22 17:31:24,956:Survey Assist - v1.0:OPENING UP A GSI FILE: C:/Users/Richard/Downloads/890MR 150520.GSI
2020-05-22 17:31:32,513:Survey Assist - v1.0:An unexpected error has occurred

update_station_height()

could not convert string to float: 
Traceback (most recent call last):
  File "C:/Users/Richard/PycharmProjects/Survey Assist/main.py", line 2681, in change_station_height
    float(point_stn_elevation)])
ValueError: could not convert string to float: 
2020-05-22 17:32:37,308:Survey Assist - v1.0:Started Application

2020-05-22 17:32:40,456:Survey Assist - v1.0:OPENING UP A GSI FILE: C:/Users/Richard/Downloads/890MR 150520.GSI
2020-05-22 17:34:14,146:Survey Assist - v1.0:Started Application

2020-05-22 17:34:32,195:Survey Assist - v1.0:Started Application

2020-05-22 17:34:36,487:Survey Assist - v1.0:OPENING UP A GSI FILE: C:/Users/Richard/Downloads/890MR 150520.GSI
2020-05-22 17:36:45,513:Survey Assist - v1.0:Started Application

2020-05-22 17:36:49,206:Survey Assist - v1.0:OPENING UP A GSI FILE: C:/Users/Richard/Downloads/890MR 150520.GSI
2020-05-22 17:36:58,798:Survey Assist - v1.0:An unexpected error has occurred

update_station_height()

[<class 'decimal.ConversionSyntax'>]
Traceback (most recent call last):
  File "C:/Users/Richard/PycharmProjects/Survey Assist/main.py", line 2675, in change_station_height
    point_stn_elevation = str(decimalize_value(point_stn_elevation, self.precision))
  File "C:\Users\Richard\PycharmProjects\Survey Assist\utilities.py", line 28, in decimalize_value
    return Decimal(in_value).quantize(Decimal('1.000'))
decimal.InvalidOperation: [<class 'decimal.ConversionSyntax'>]
2020-05-22 17:37:59,343:Survey Assist - v1.0:Started Application

2020-05-22 17:38:02,971:Survey Assist - v1.0:OPENING UP A GSI FILE: C:/Users/Richard/Downloads/890MR 150520.GSI
2020-05-22 17:38:09,095:Survey Assist - v1.0:An unexpected error has occurred

update_station_height()

could not convert string to float: 
Traceback (most recent call last):
  File "C:/Users/Richard/PycharmProjects/Survey Assist/main.py", line 2675, in change_station_height
    point_stn_elevation = str(decimalize_value(float(point_stn_elevation), self.precision))
ValueError: could not convert string to float: 
2020-05-22 17:39:13,379:Survey Assist - v1.0:Started Application

2020-05-22 17:39:19,191:Survey Assist - v1.0:OPENING UP A GSI FILE: C:/Users/Richard/Downloads/890MR 150520.GSI
2020-05-22 17:39:26,684:Survey Assist - v1.0:An unexpected error has occurred

update_station_height()

could not convert string to float: 
Traceback (most recent call last):
  File "C:/Users/Richard/PycharmProjects/Survey Assist/main.py", line 2685, in change_station_height
    self.new_stn_coordinates[point_id] = [float(point_easting), float(point_northing), float(point_stn_elevation)]
ValueError: could not convert string to float: 
2020-05-22 17:40:14,739:Survey Assist - v1.0:Started Application

2020-05-22 17:40:18,737:Survey Assist - v1.0:OPENING UP A GSI FILE: C:/Users/Richard/Downloads/890MR 150520.GSI
2020-05-22 17:41:52,389:Survey Assist - v1.0:Started Application

2020-05-22 17:41:56,205:Survey Assist - v1.0:OPENING UP A GSI FILE: C:/Users/Richard/Downloads/890MR 150520.GSI
2020-05-22 17:43:47,207:Survey Assist - v1.0:Started Application

2020-05-22 17:43:53,034:Survey Assist - v1.0:OPENING UP A GSI FILE: C:/Users/Richard/Downloads/890MR 150520.GSI
2020-05-23 08:52:20,507:Survey Assist - v1.0:Started Application

2020-05-23 08:52:25,954:Survey Assist - v1.0:OPENING UP A GSI FILE: C:/Users/Richard/Downloads/890MR 150520.GSI
2020-05-23 08:53:48,016:Survey Assist - v1.0:OPENING UP A GSI FILE: C:/Users/Richard/Downloads/890MR 150520.GSI
2020-05-23 08:55:18,766:Survey Assist - v1.0:Started Application

2020-05-23 08:55:22,797:Survey Assist - v1.0:OPENING UP A GSI FILE: C:/Users/Richard/Downloads/890MR 150520.GSI
2020-05-23 09:03:09,861:Survey Assist - v1.0:Started Application

2020-05-23 09:03:13,407:Survey Assist - v1.0:OPENING UP A GSI FILE: C:/Users/Richard/Downloads/890MR 150520.GSI
2020-05-23 09:03:20,824:Survey Assist - v1.0:An unexpected error has occurred

update_station_height()

name 'update_all_shot_elevations_from_station' is not defined
Traceback (most recent call last):
  File "C:/Users/Richard/PycharmProjects/Survey Assist/main.py", line 2668, in change_station_height
    updated_coordintates_dict = update_all_shot_elevations_from_station(line_number, station, float(stn_height_diff))
NameError: name 'update_all_shot_elevations_from_station' is not defined
2020-05-23 09:03:53,555:Survey Assist - v1.0:Started Application

2020-05-23 09:04:48,313:Survey Assist - v1.0:OPENING UP A GSI FILE: C:/Users/Richard/Downloads/890MR 150520.GSI
2020-05-23 09:04:54,728:Survey Assist - v1.0:An unexpected error has occurred

update_station_height()

could not convert string to float: 
Traceback (most recent call last):
  File "C:/Users/Richard/PycharmProjects/Survey Assist/main.py", line 2668, in change_station_height
    updated_coordintates_dict = self.update_all_shot_elevations_from_station(line_number, station, float(stn_height_diff))
  File "C:/Users/Richard/PycharmProjects/Survey Assist/main.py", line 2723, in update_all_shot_elevations_from_station
    point_easting = float(formatted_line['Easting'])
ValueError: could not convert string to float: 
2020-05-23 09:06:21,055:Survey Assist - v1.0:Started Application

2020-05-23 09:06:25,891:Survey Assist - v1.0:OPENING UP A GSI FILE: C:/Users/Richard/Downloads/890MR 150520.GSI
2020-05-23 09:06:33,126:Survey Assist - v1.0:An unexpected error has occurred

update_station_height()

'float' object has no attribute 'replace'
Traceback (most recent call last):
  File "C:/Users/Richard/PycharmProjects/Survey Assist/main.py", line 2668, in change_station_height
    updated_coordintates_dict = self.update_all_shot_elevations_from_station(line_number, station, float(stn_height_diff))
  File "C:/Users/Richard/PycharmProjects/Survey Assist/main.py", line 2731, in update_all_shot_elevations_from_station
    gsi.update_elevation(formatted_line_number, new_point_elevation)
  File "C:\Users\Richard\PycharmProjects\Survey Assist\GSI.py", line 293, in update_elevation
    new_elevation = new_elevation.replace(".", "")
AttributeError: 'float' object has no attribute 'replace'
2020-05-23 09:07:54,700:Survey Assist - v1.0:Started Application

2020-05-23 09:07:58,969:Survey Assist - v1.0:OPENING UP A GSI FILE: C:/Users/Richard/Downloads/890MR 150520.GSI
2020-05-23 09:08:06,917:Survey Assist - v1.0:An unexpected error has occurred

update_station_height()

can only concatenate str (not "float") to str
Traceback (most recent call last):
  File "C:/Users/Richard/PycharmProjects/Survey Assist/main.py", line 2668, in change_station_height
    updated_coordintates_dict = self.update_all_shot_elevations_from_station(line_number, station, float(stn_height_diff))
  File "C:/Users/Richard/PycharmProjects/Survey Assist/main.py", line 2730, in update_all_shot_elevations_from_station
    new_point_elevation = old_point_elevation + elevation_diff
TypeError: can only concatenate str (not "float") to str
2020-05-23 09:10:12,893:Survey Assist - v1.0:Started Application

2020-05-23 09:10:16,484:Survey Assist - v1.0:OPENING UP A GSI FILE: C:/Users/Richard/Downloads/890MR 150520.GSI
2020-05-23 09:10:23,091:Survey Assist - v1.0:An unexpected error has occurred

update_station_height()

name 'self' is not defined
Traceback (most recent call last):
  File "C:/Users/Richard/PycharmProjects/Survey Assist/main.py", line 2668, in change_station_height
    updated_coordintates_dict = self.update_all_shot_elevations_from_station(line_number, station, float(stn_height_diff))
  File "C:/Users/Richard/PycharmProjects/Survey Assist/main.py", line 2731, in update_all_shot_elevations_from_station
    new_point_elevation = str(decimalize_value(new_point_elevation, self.precision))
NameError: name 'self' is not defined
2020-05-23 09:10:50,221:Survey Assist - v1.0:Started Application

2020-05-23 09:10:53,875:Survey Assist - v1.0:OPENING UP A GSI FILE: C:/Users/Richard/Downloads/890MR 150520.GSI
2020-05-23 09:21:44,656:Survey Assist - v1.0:OPENING UP A GSI FILE: C:/Users/Richard/PycharmProjects/Survey Assist/Test Files/GSI Files/HCCL 030719.GSI
2020-05-23 09:23:18,375:Survey Assist - v1.0:An unexpected error has occurred

update_station_height()

'F'
Traceback (most recent call last):
  File "C:/Users/Richard/PycharmProjects/Survey Assist/main.py", line 2662, in change_station_height
    stn_coordinates = self.new_stn_coordinates[station]
KeyError: 'F'
2020-05-23 09:25:01,000:Survey Assist - v1.0:Started Application

2020-05-23 09:25:07,203:Survey Assist - v1.0:OPENING UP A GSI FILE: C:/Users/Richard/PycharmProjects/Survey Assist/Test Files/GSI Files/HCCL 030719.GSI
2020-05-23 09:29:51,787:Survey Assist - v1.0:Started Application

2020-05-23 09:29:56,765:Survey Assist - v1.0:OPENING UP A GSI FILE: C:/Users/Richard/PycharmProjects/Survey Assist/Test Files/GSI Files/HCCL 030719.GSI
2020-05-23 09:30:24,642:Survey Assist - v1.0:OPENING UP A GSI FILE: C:/Users/Richard/PycharmProjects/Survey Assist/Test Files/GSI Files/HCCL 030719.GSI
2020-05-23 09:31:24,985:Survey Assist - v1.0:OPENING UP A GSI FILE: C:/Users/Richard/PycharmProjects/Survey Assist/Test Files/GSI Files/HCCL 030719.GSI
2020-05-23 09:33:09,453:Survey Assist - v1.0:OPENING UP A GSI FILE: C:/Users/Richard/PycharmProjects/Survey Assist/Test Files/GSI Files/2D Survey MR050819.GSI
2020-05-23 09:33:33,516:Survey Assist - v1.0:OPENING UP A GSI FILE: C:/Users/Richard/PycharmProjects/Survey Assist/Test Files/GSI Files/2D Survey MR050819.GSI
2020-05-23 09:34:03,274:Survey Assist - v1.0:Started Application

2020-05-23 09:34:27,985:Survey Assist - v1.0:OPENING UP A GSI FILE: C:/Users/Richard/Downloads/MR140519.GSI
2020-05-23 09:34:43,220:Survey Assist - v1.0:An unexpected error has occurred

update_station_height()

could not convert string to float: 
Traceback (most recent call last):
  File "C:/Users/Richard/PycharmProjects/Survey Assist/main.py", line 2637, in change_station_height
    old_point_elevation = float(formatted_line['Elevation'])
ValueError: could not convert string to float: 
2020-05-23 09:39:46,743:Survey Assist - v1.0:Started Application

2020-05-23 09:39:51,297:Survey Assist - v1.0:OPENING UP A GSI FILE: C:/Users/Richard/Downloads/MR140519.GSI
2020-05-23 09:40:13,906:Survey Assist - v1.0:OPENING UP A GSI FILE: C:/Users/Richard/Downloads/MR140519.GSI
2020-05-23 09:44:12,836:Survey Assist - v1.0:Started Application

2020-05-23 09:44:16,703:Survey Assist - v1.0:OPENING UP A GSI FILE: C:/Users/Richard/Downloads/MR140519.GSI
2020-05-23 09:45:29,751:Survey Assist - v1.0:OPENING UP A GSI FILE: C:/Users/Richard/Downloads/TEST Target Height Test.GSI
2020-05-23 09:46:11,766:Survey Assist - v1.0:OPENING UP A GSI FILE: C:/Users/Richard/Downloads/TEST Target Height Test.GSI
2020-05-23 09:47:03,094:Survey Assist - v1.0:OPENING UP A GSI FILE: C:/Users/Richard/PycharmProjects/Survey Assist/Test Files/GSI Files/HCCL 030719.GSI
2020-05-23 09:47:53,329:Survey Assist - v1.0:OPENING UP A GSI FILE: C:/Users/Richard/PycharmProjects/Survey Assist/Test Files/GSI Files/ARTC_903_MS60 230320.GSI
2020-05-23 09:49:06,907:Survey Assist - v1.0:OPENING UP A GSI FILE: C:/Users/Richard/Downloads/ARTC_903_MON_V2_TS15_200420_combine.GSI
2020-05-23 09:49:38,633:Survey Assist - v1.0:An unexpected error has occurred

update_station_height()

'NoneType' object has no attribute 'group'
Traceback (most recent call last):
  File "C:/Users/Richard/PycharmProjects/Survey Assist/main.py", line 2671, in change_station_height
    gsi.update_station_elevation(line_number, new_stn_elevation)
  File "C:\Users\Richard\PycharmProjects\Survey Assist\GSI.py", line 134, in update_station_elevation
    org_field_value = match.group()
AttributeError: 'NoneType' object has no attribute 'group'
2020-05-23 09:51:18,079:Survey Assist - v1.0:OPENING UP A GSI FILE: C:/Users/Richard/PycharmProjects/Survey Assist/Test Files/GSI Files/ARTC_903_compnet 240220.GSI
2020-05-23 09:51:25,063:Survey Assist - v1.0:OPENING UP A GSI FILE: C:/Users/Richard/PycharmProjects/Survey Assist/Test Files/GSI Files/ARTC_903_compnet 240220_PCUpdated.gsi
2020-05-23 09:51:36,562:Survey Assist - v1.0:OPENING UP A GSI FILE: C:/Users/Richard/PycharmProjects/Survey Assist/Test Files/GSI Files/ARTC_903_compnet 240220.GSI
2020-05-23 09:51:52,066:Survey Assist - v1.0:An unexpected error has occurred

update_station_height()

'STN05'
Traceback (most recent call last):
  File "C:/Users/Richard/PycharmProjects/Survey Assist/main.py", line 2668, in change_station_height
    stn_coordinates = self.new_stn_coordinates[station]
KeyError: 'STN05'
2020-05-23 09:57:02,503:Survey Assist - v1.0:An unexpected error has occurred

update_station_height()

'STN11'
Traceback (most recent call last):
  File "C:/Users/Richard/PycharmProjects/Survey Assist/main.py", line 2668, in change_station_height
    stn_coordinates = self.new_stn_coordinates[station]
KeyError: 'STN11'
2020-05-23 09:59:08,101:Survey Assist - v1.0:Started Application

2020-05-23 10:02:03,062:Survey Assist - v1.0:Started Application

2020-05-23 10:02:10,501:Survey Assist - v1.0:OPENING UP A GSI FILE: C:/Users/Richard/PycharmProjects/Survey Assist/Test Files/GSI Files/HCCL 030719.GSI
2020-05-23 10:02:20,746:Survey Assist - v1.0:An unexpected error has occurred

update_station_height()

'NoneType' object is not subscriptable
Traceback (most recent call last):
  File "C:/Users/Richard/PycharmProjects/Survey Assist/main.py", line 2668, in change_station_height
    new_stn_elevation = stn_coordinates[2]
TypeError: 'NoneType' object is not subscriptable
2020-05-23 10:04:48,794:Survey Assist - v1.0:Started Application

2020-05-23 10:04:52,351:Survey Assist - v1.0:OPENING UP A GSI FILE: C:/Users/Richard/PycharmProjects/Survey Assist/Test Files/GSI Files/HCCL 030719.GSI
2020-05-23 10:05:57,151:Survey Assist - v1.0:An unexpected error has occurred

update_station_height()

'NoneType' object is not subscriptable
Traceback (most recent call last):
  File "C:/Users/Richard/PycharmProjects/Survey Assist/main.py", line 2668, in change_station_height
    new_stn_elevation = stn_coordinates[2]
TypeError: 'NoneType' object is not subscriptable
2020-05-23 10:07:23,377:Survey Assist - v1.0:Started Application

2020-05-23 10:07:44,582:Survey Assist - v1.0:OPENING UP A GSI FILE: C:/Users/Richard/PycharmProjects/Survey Assist/Test Files/GSI Files/HCCL 030719.GSI
2020-05-23 10:07:58,983:Survey Assist - v1.0:OPENING UP A GSI FILE: C:/Users/Richard/PycharmProjects/Survey Assist/Test Files/GSI Files/HCCL 030719.GSI
2020-05-23 10:08:15,235:Survey Assist - v1.0:OPENING UP A GSI FILE: C:/Users/Richard/PycharmProjects/Survey Assist/Test Files/GSI Files/ARTC_903_compnet 240220.GSI
2020-05-23 10:08:24,951:Survey Assist - v1.0:OPENING UP A GSI FILE: C:/Users/Richard/Downloads/ARTC_903_MON_V2_TS15_200420_combine.GSI
2020-05-23 10:08:48,451:Survey Assist - v1.0:OPENING UP A GSI FILE: C:/Users/Richard/PycharmProjects/Survey Assist/Test Files/GSI Files/ARTC_903_compnet 240220_PCUpdated.gsi
2020-05-23 10:10:10,782:Survey Assist - v1.0:OPENING UP A GSI FILE: C:/Users/Richard/PycharmProjects/Survey Assist/Test Files/GSI Files/ARTC_903_compnet 240220.GSI
2020-05-23 10:11:38,566:Survey Assist - v1.0:Started Application

2020-05-23 10:11:59,750:Survey Assist - v1.0:OPENING UP A GSI FILE: C:/Users/Richard/Downloads/890MR 150520.GSI
2020-05-23 10:12:35,765:Survey Assist - v1.0:OPENING UP A GSI FILE: C:/Users/Richard/Downloads/Raumer fix 150520.gsi
2020-05-23 10:14:36,651:Survey Assist - v1.0:OPENING UP A GSI FILE: C:/Users/Richard/Downloads/890MR 150520.GSI
2020-05-23 10:23:33,267:Survey Assist - v1.0:OPENING UP A GSI FILE: C:/Users/Richard/Downloads/890MR 150520.GSI
2020-05-23 10:26:00,876:Survey Assist - v1.0:OPENING UP A GSI FILE: C:/Users/Richard/Downloads/890MR 150520_EDITED.GSI
2020-05-23 10:35:47,036:Survey Assist - v1.0:An unexpected error has occurred

update_station_height()

'NoneType' object has no attribute 'group'
Traceback (most recent call last):
  File "C:/Users/Richard/PycharmProjects/Survey Assist/main.py", line 2670, in change_station_height
    new_stn_elevation = stn_coordinates[2]
  File "C:\Users\Richard\PycharmProjects\Survey Assist\GSI.py", line 134, in update_station_elevation
    org_field_value = match.group()
AttributeError: 'NoneType' object has no attribute 'group'
2020-05-23 10:36:20,035:Survey Assist - v1.0:Started Application

2020-05-23 10:36:26,735:Survey Assist - v1.0:OPENING UP A GSI FILE: C:/Users/Richard/Downloads/890MR 150520_EDITED_TgtUpdated_STNUpdated.gsi
2020-05-23 10:38:44,598:Survey Assist - v1.0:An unexpected error has occurred

update_station_height()

'NoneType' object has no attribute 'group'
Traceback (most recent call last):
  File "C:/Users/Richard/PycharmProjects/Survey Assist/main.py", line 2672, in change_station_height
    gsi.update_station_elevation(line_number, new_stn_elevation)
  File "C:\Users\Richard\PycharmProjects\Survey Assist\GSI.py", line 134, in update_station_elevation
    org_field_value = match.group()
AttributeError: 'NoneType' object has no attribute 'group'
2020-05-23 10:39:50,266:Survey Assist - v1.0:OPENING UP A GSI FILE: C:/Users/Richard/Downloads/MR140519.GSI
2020-05-23 10:39:55,735:Survey Assist - v1.0:OPENING UP A GSI FILE: C:/Users/Richard/Downloads/890MR 150520.GSI
2020-05-23 10:40:12,853:Survey Assist - v1.0:Started Application

2020-05-23 10:40:17,015:Survey Assist - v1.0:OPENING UP A GSI FILE: C:/Users/Richard/Downloads/890MR 150520.GSI
2020-05-23 10:40:27,894:Survey Assist - v1.0:An unexpected error has occurred

update_station_height()

'NoneType' object has no attribute 'group'
Traceback (most recent call last):
  File "C:/Users/Richard/PycharmProjects/Survey Assist/main.py", line 2672, in change_station_height
    gsi.update_station_elevation(line_number, new_stn_elevation)
  File "C:\Users\Richard\PycharmProjects\Survey Assist\GSI.py", line 134, in update_station_elevation
    org_field_value = match.group()
AttributeError: 'NoneType' object has no attribute 'group'
2020-05-23 10:40:39,433:Survey Assist - v1.0:Started Application

2020-05-23 10:40:46,515:Survey Assist - v1.0:OPENING UP A GSI FILE: C:/Users/Richard/Downloads/890MR 150520.GSI
2020-05-23 10:44:45,099:Survey Assist - v1.0:Started Application

2020-05-23 10:44:51,923:Survey Assist - v1.0:OPENING UP A GSI FILE: C:/Users/Richard/Downloads/890MR 150520.GSI
2020-05-23 10:45:00,772:Survey Assist - v1.0:An unexpected error has occurred

update_station_height()

'NoneType' object has no attribute 'group'
Traceback (most recent call last):
  File "C:/Users/Richard/PycharmProjects/Survey Assist/main.py", line 2672, in change_station_height
    gsi.update_station_elevation(line_number, new_stn_elevation)
  File "C:\Users\Richard\PycharmProjects\Survey Assist\GSI.py", line 134, in update_station_elevation
    org_field_value = match.group()
AttributeError: 'NoneType' object has no attribute 'group'
2020-05-23 10:46:44,666:Survey Assist - v1.0:Started Application

2020-05-23 10:46:49,688:Survey Assist - v1.0:OPENING UP A GSI FILE: C:/Users/Richard/Downloads/890MR 150520.GSI
2020-05-23 10:47:09,960:Survey Assist - v1.0:An unexpected error has occurred

update_station_height()

'NoneType' object has no attribute 'group'
Traceback (most recent call last):
  File "C:/Users/Richard/PycharmProjects/Survey Assist/main.py", line 2673, in change_station_height
    gsi.update_station_elevation(line_number, new_stn_elevation)
  File "C:\Users\Richard\PycharmProjects\Survey Assist\GSI.py", line 134, in update_station_elevation
    org_field_value = match.group()
AttributeError: 'NoneType' object has no attribute 'group'
